Workbook

Sheet Dashboard
B2: HIDDEN COST TRACKER | H2: TODAY
B3: What your debts, installments and subscriptions really cost you. | H3: =Settings!$C$9
B5: MONTHLY INCOME | D5: COMMITTED EACH MONTH | F5: SHARE OF INCOME COMMITTED | H5: LEFT OVER EACH MONTH
B6: =$C$40 | D6: =$C$44 | F6: =IF($C$40>0,$C$44/$C$40,0) | H6: =$C$45
B7: take-home · change it in Settings | D7: =TEXT(($C$41+$C$42),"$#,##0")&" debts + "&TEXT($C$43,"$#,##0")&" subscriptions" | F7: ="of every $1 you earn, "&TEXT(IF($C$40>0,$C$44/$C$40,0)*100,"0")&"¢ is already spoken for" | H7: after debts & subscriptions
B9: HIGHEST REAL APR | D9: INTEREST STILL TO PAY | F9: FREE TRIALS ENDING SOON | H9: YEARLY SAVINGS IF YOU CANCEL
B10: =IF(COUNT('Debts & Installments'!$J$6:$J$25)=0,"",MAX('Debts & Installments'!$J$6:$J$25)) | D10: =SUM('Debts & Installments'!$N$6:$N$25) | F10: =COUNTIF(Subscriptions!$R$6:$R$35,"Cancel soon?") | H10: =SUMIFS(Subscriptions!$M$6:$M$35,Subscriptions!$I$6:$I$35,"Yes")
B11: =IF(COUNT('Debts & Installments'!$J$6:$J$25)=0,"add a debt to see it",'Chart Data'!$B$24&" · "&COUNTIF('Debts & Installments'!$R$6:$R$25,"HIGH")&" flagged HIGH") | D11: =COUNT('Debts & Installments'!$J$6:$J$25)&" debts · debt-free "&IF(COUNT('Debts & Installments'!$O$6:$O$25)=0,"-",TEXT(MAX('Debts & Installments'!$O$6:$O$25),"mmm yyyy")) | F11: =IF(COUNT(Subscriptions!$U$6:$U$35)=0,"no open free trials","first cancel-by: "&TEXT(Settings!$C$9+INT(SMALL(Subscriptions!$U$6:$U$35,1)),"mmm d")) | H11: =COUNTIF(Subscriptions!$I$6:$I$35,"Yes")&" subscriptions ticked Cancel it?"
B13: COMING UP · NEXT CHARGES | F13: WHERE EACH MONTH'S INCOME GOES
B14: SUBSCRIPTION | C14: AMOUNT | D14: DATE | E14: DUE IN
B15: =IFERROR(INDEX(Subscriptions!$B$6:$B$35,MATCH(SMALL(Subscriptions!$S$6:$S$35,1),Subscriptions!$S$6:$S$35,0)),"") | C15: =IFERROR(INDEX(Subscriptions!$D$6:$D$35,MATCH(SMALL(Subscriptions!$S$6:$S$35,1),Subscriptions!$S$6:$S$35,0)),"") | D15: =IFERROR(INDEX(Subscriptions!$N$6:$N$35,MATCH(SMALL(Subscriptions!$S$6:$S$35,1),Subscriptions!$S$6:$S$35,0)),"") | E15: =IFERROR(INDEX(Subscriptions!$O$6:$O$35,MATCH(SMALL(Subscriptions!$S$6:$S$35,1),Subscriptions!$S$6:$S$35,0)),"")
B16: =IFERROR(INDEX(Subscriptions!$B$6:$B$35,MATCH(SMALL(Subscriptions!$S$6:$S$35,2),Subscriptions!$S$6:$S$35,0)),"") | C16: =IFERROR(INDEX(Subscriptions!$D$6:$D$35,MATCH(SMALL(Subscriptions!$S$6:$S$35,2),Subscriptions!$S$6:$S$35,0)),"") | D16: =IFERROR(INDEX(Subscriptions!$N$6:$N$35,MATCH(SMALL(Subscriptions!$S$6:$S$35,2),Subscriptions!$S$6:$S$35,0)),"") | E16: =IFERROR(INDEX(Subscriptions!$O$6:$O$35,MATCH(SMALL(Subscriptions!$S$6:$S$35,2),Subscriptions!$S$6:$S$35,0)),"")
B17: =IFERROR(INDEX(Subscriptions!$B$6:$B$35,MATCH(SMALL(Subscriptions!$S$6:$S$35,3),Subscriptions!$S$6:$S$35,0)),"") | C17: =IFERROR(INDEX(Subscriptions!$D$6:$D$35,MATCH(SMALL(Subscriptions!$S$6:$S$35,3),Subscriptions!$S$6:$S$35,0)),"") | D17: =IFERROR(INDEX(Subscriptions!$N$6:$N$35,MATCH(SMALL(Subscriptions!$S$6:$S$35,3),Subscriptions!$S$6:$S$35,0)),"") | E17: =IFERROR(INDEX(Subscriptions!$O$6:$O$35,MATCH(SMALL(Subscriptions!$S$6:$S$35,3),Subscriptions!$S$6:$S$35,0)),"")
B18: =IFERROR(INDEX(Subscriptions!$B$6:$B$35,MATCH(SMALL(Subscriptions!$S$6:$S$35,4),Subscriptions!$S$6:$S$35,0)),"") | C18: =IFERROR(INDEX(Subscriptions!$D$6:$D$35,MATCH(SMALL(Subscriptions!$S$6:$S$35,4),Subscriptions!$S$6:$S$35,0)),"") | D18: =IFERROR(INDEX(Subscriptions!$N$6:$N$35,MATCH(SMALL(Subscriptions!$S$6:$S$35,4),Subscriptions!$S$6:$S$35,0)),"") | E18: =IFERROR(INDEX(Subscriptions!$O$6:$O$35,MATCH(SMALL(Subscriptions!$S$6:$S$35,4),Subscriptions!$S$6:$S$35,0)),"")
B19: =IFERROR(INDEX(Subscriptions!$B$6:$B$35,MATCH(SMALL(Subscriptions!$S$6:$S$35,5),Subscriptions!$S$6:$S$35,0)),"") | C19: =IFERROR(INDEX(Subscriptions!$D$6:$D$35,MATCH(SMALL(Subscriptions!$S$6:$S$35,5),Subscriptions!$S$6:$S$35,0)),"") | D19: =IFERROR(INDEX(Subscriptions!$N$6:$N$35,MATCH(SMALL(Subscriptions!$S$6:$S$35,5),Subscriptions!$S$6:$S$35,0)),"") | E19: =IFERROR(INDEX(Subscriptions!$O$6:$O$35,MATCH(SMALL(Subscriptions!$S$6:$S$35,5),Subscriptions!$S$6:$S$35,0)),"")
B20: =IFERROR(INDEX(Subscriptions!$B$6:$B$35,MATCH(SMALL(Subscriptions!$S$6:$S$35,6),Subscriptions!$S$6:$S$35,0)),"") | C20: =IFERROR(INDEX(Subscriptions!$D$6:$D$35,MATCH(SMALL(Subscriptions!$S$6:$S$35,6),Subscriptions!$S$6:$S$35,0)),"") | D20: =IFERROR(INDEX(Subscriptions!$N$6:$N$35,MATCH(SMALL(Subscriptions!$S$6:$S$35,6),Subscriptions!$S$6:$S$35,0)),"") | E20: =IFERROR(INDEX(Subscriptions!$O$6:$O$35,MATCH(SMALL(Subscriptions!$S$6:$S$35,6),Subscriptions!$S$6:$S$35,0)),"")
B22: FREE TRIALS · CANCEL BEFORE YOU'RE CHARGED
B23: FREE TRIAL | C23: THEN COSTS | D23: CANCEL BY | E23: DAYS LEFT
B24: =IFERROR(INDEX(Subscriptions!$B$6:$B$35,MATCH(SMALL(Subscriptions!$U$6:$U$35,1),Subscriptions!$U$6:$U$35,0)),"") | C24: =IFERROR(INDEX(Subscriptions!$D$6:$D$35,MATCH(SMALL(Subscriptions!$U$6:$U$35,1),Subscriptions!$U$6:$U$35,0)),"") | D24: =IFERROR(INDEX(Subscriptions!$P$6:$P$35,MATCH(SMALL(Subscriptions!$U$6:$U$35,1),Subscriptions!$U$6:$U$35,0)),"") | E24: =IFERROR(INDEX(Subscriptions!$Q$6:$Q$35,MATCH(SMALL(Subscriptions!$U$6:$U$35,1),Subscriptions!$U$6:$U$35,0)),"")
B25: =IFERROR(INDEX(Subscriptions!$B$6:$B$35,MATCH(SMALL(Subscriptions!$U$6:$U$35,2),Subscriptions!$U$6:$U$35,0)),"") | C25: =IFERROR(INDEX(Subscriptions!$D$6:$D$35,MATCH(SMALL(Subscriptions!$U$6:$U$35,2),Subscriptions!$U$6:$U$35,0)),"") | D25: =IFERROR(INDEX(Subscriptions!$P$6:$P$35,MATCH(SMALL(Subscriptions!$U$6:$U$35,2),Subscriptions!$U$6:$U$35,0)),"") | E25: =IFERROR(INDEX(Subscriptions!$Q$6:$Q$35,MATCH(SMALL(Subscriptions!$U$6:$U$35,2),Subscriptions!$U$6:$U$35,0)),"")
B26: =IFERROR(INDEX(Subscriptions!$B$6:$B$35,MATCH(SMALL(Subscriptions!$U$6:$U$35,3),Subscriptions!$U$6:$U$35,0)),"") | C26: =IFERROR(INDEX(Subscriptions!$D$6:$D$35,MATCH(SMALL(Subscriptions!$U$6:$U$35,3),Subscriptions!$U$6:$U$35,0)),"") | D26: =IFERROR(INDEX(Subscriptions!$P$6:$P$35,MATCH(SMALL(Subscriptions!$U$6:$U$35,3),Subscriptions!$U$6:$U$35,0)),"") | E26: =IFERROR(INDEX(Subscriptions!$Q$6:$Q$35,MATCH(SMALL(Subscriptions!$U$6:$U$35,3),Subscriptions!$U$6:$U$35,0)),"")
B27: =IFERROR(INDEX(Subscriptions!$B$6:$B$35,MATCH(SMALL(Subscriptions!$U$6:$U$35,4),Subscriptions!$U$6:$U$35,0)),"") | C27: =IFERROR(INDEX(Subscriptions!$D$6:$D$35,MATCH(SMALL(Subscriptions!$U$6:$U$35,4),Subscriptions!$U$6:$U$35,0)),"") | D27: =IFERROR(INDEX(Subscriptions!$P$6:$P$35,MATCH(SMALL(Subscriptions!$U$6:$U$35,4),Subscriptions!$U$6:$U$35,0)),"") | E27: =IFERROR(INDEX(Subscriptions!$Q$6:$Q$35,MATCH(SMALL(Subscriptions!$U$6:$U$35,4),Subscriptions!$U$6:$U$35,0)),"") | F27: SPEND VS SAVINGS (YEARLY) | H27: VIEW ▸ | I27: By category
B29: DEBTS · PAY EXTRA ON #1 FIRST (HIGHEST REAL APR)
B30: DEBT | C30: REAL APR | D30: FLAG | E30: INTEREST LEFT
B31: ='Chart Data'!B24 | C31: ='Chart Data'!C24 | D31: ='Chart Data'!D24 | E31: ='Chart Data'!E24
B32: ='Chart Data'!B25 | C32: ='Chart Data'!C25 | D32: ='Chart Data'!D25 | E32: ='Chart Data'!E25
B33: ='Chart Data'!B26 | C33: ='Chart Data'!C26 | D33: ='Chart Data'!D26 | E33: ='Chart Data'!E26
B34: ='Chart Data'!B27 | C34: ='Chart Data'!C27 | D34: ='Chart Data'!D27 | E34: ='Chart Data'!E27
B35: ='Chart Data'!B28 | C35: ='Chart Data'!C28 | D35: ='Chart Data'!D28 | E35: ='Chart Data'!E28
B36: ='Chart Data'!B29 | C36: ='Chart Data'!C29 | D36: ='Chart Data'!D29 | E36: ='Chart Data'!E29
B38: MONTHLY MONEY MAP
B39: WHERE THE MONEY GOES | C39: PER MONTH | D39: SHARE
B40: Take-home income | C40: =Settings!$C$5
B41: Loans & cards | C41: =SUM('Debts & Installments'!$E$6:$E$25)-SUMIFS('Debts & Installments'!$E$6:$E$25,'Debts & Installments'!$C$6:$C$25,"Installment")-SUMIFS('Debts & Installments'!$E$6:$E$25,'Debts & Installments'!$C$6:$C$25,"BNPL") | D41: =IF($C$40>0,C41/$C$40,0)
B42: Installments & BNPL | C42: =SUMIFS('Debts & Installments'!$E$6:$E$25,'Debts & Installments'!$C$6:$C$25,"Installment")+SUMIFS('Debts & Installments'!$E$6:$E$25,'Debts & Installments'!$C$6:$C$25,"BNPL") | D42: =IF($C$40>0,C42/$C$40,0)
B43: Subscriptions | C43: =SUM(Subscriptions!$L$6:$L$35) | D43: =IF($C$40>0,C43/$C$40,0)
B44: Committed before you spend a cent | C44: =SUM(C41:C43) | D44: =IF($C$40>0,C44/$C$40,0) | F44: REAL APR BY DEBT
B45: Left for everything else | C45: =C40-C44 | D45: =IF($C$40>0,C45/$C$40,0)
B47: WHAT THE FLAGS MEAN
B48: HIGH | C48: ="Real APR at or above "&TEXT(Settings!$C$6,"0%")&". Pay these down first."
...

Sheet How to Use
B2: How to use
B3: Five minutes to set up.
B5: 1. Settings: enter your monthly take-home income. Adjust the red/amber APR levels if you like (defaults 20% / 10%).
B6: 2. Debts & Installments: one row per debt. BLUE-header columns are yours; ORANGE-header columns calculate themselves.
B7: • Installment / BNPL / store financing: enter Original amount, Monthly payment, Total payments and Payments made. Leave Stated APR empty: the Real APR is worked out for you.
B8: • Credit card / loan: enter Monthly payment, Stated APR and Balance now.
B9: • Family loan with no interest: enter 0% as the Stated APR.
B10: 3. Subscriptions: one row per subscription. Tick Cancel it? on anything you'd drop: the Dashboard shows the yearly saving.
B11: • Free trial? Tick Free trial? and enter Trial days. You get a 'cancel by' date and a countdown.
B12: 4. Dashboard: see what share of your income is committed before you spend anything, your highest-cost debt, and what's coming up.
B13: • Switch the spending chart between By category and By subscription with the VIEW box above it.
B14: • Use the filter buttons on each table's header row (or the filter bars above it in Google Sheets) to sort and filter.
... B19: Estimates only. Not financial advice. The Real APR is an estimate from your payment schedule and does not include fees charged separately.

Sheet Settings
B2: Settings
B3: Blue-header cells are yours to edit.
B4: SETTING | C4: VALUE | D4: WHAT IT DOES
B5: Monthly take-home income | C5: 4200 | D5: Your income after tax, per month.
B6: High-cost APR (red flag) | C6: 0.2 | D6: Any debt at or above this APR is flagged HIGH.
B7: Check APR (amber flag) | C7: 0.1 | D7: At or above this APR is flagged CHECK.
B8: Warn me this many days ahead | C8: 7 | D8: Trials and bills due within this many days are highlighted.
B9: Today's date | C9: =TODAY() | D9: Updates automatically. Every date calculation uses it.
B12: DEBT TYPES | C12: BILLING | D12: CATEGORIES | E12: PAID WITH
B13: Credit card | C13: Weekly | D13: Streaming | E13: Credit card | F13: Rename or add items here and the drop-downs follow.
B14: Loan | C14: Monthly | D14: Software | E14: Debit card
B15: Installment | C15: Quarterly | D15: Fitness | E15: PayPal
B16: BNPL | C16: Yearly | D16: Shopping | E16: Apple Pay
B17: Family / friend | D17: News | E17: Google Pay
B18: Other | D18: Cloud | E18: Bank transfer
D19: Food | E19: Other
D20: Education
D21: Other

Sheet Debts & Installments
B2: Debts & Installments | M2: BLUE headers: you fill in · ORANGE headers: calculated for you
B3: =COUNT('Debts & Installments'!$J$6:$J$25)&" debts · owed now "&TEXT(SUM('Debts & Installments'!$L$6:$L$25),"$#,##0")&" · paying "&TEXT(SUM('Debts & Installments'!$E$6:$E$25),"$#,##0")&" a month · interest still to pay "&TEXT(SUM('Debts & Installments'!$N$6:$N$25),"$#,##0")&" · debt-free "&IF(COUNT('Debts & Installments'!$O$6:$O$25)=0,"-",TEXT(MAX('Debts & Installments'!$O$6:$O$25),"mmm yyyy"))
B5: NAME | C5: TYPE | D5: ORIGINAL AMOUNT | E5: MONTHLY PAYMENT | F5: TOTAL PAYMENTS | G5: PAYMENTS MADE | H5: STATED APR (IF KNOWN) | I5: BALANCE NOW (IF KNOWN) | J5: REAL APR | K5: PAYMENTS LEFT | L5: BALANCE (EST.) | M5: STILL TO PAY | N5: INTEREST STILL TO PAY | O5: DEBT-FREE DATE | P5: AVALANCHE ORDER | Q5: SNOWBALL ORDER | R5: FLAG | S5: key
B6: Credit card | C6: Credit card | E6: 120 | H6: 0.2499 | I6: 3200 | J6: =IF(NOT(AND($B6<>"",$E6>0)),"",IF(ISNUMBER($H6),$H6,IF(AND($D6>0,$F6>0),IFERROR(RATE($F6,-$E6,$D6)*12,""),""))) | K6: =IF(NOT(AND($B6<>"",$E6>0)),"",IF($F6>0,MAX(0,$F6-N($G6)),IF(AND(ISNUMBER($I6),ISNUMBER($J6)),IF($J6=0,ROUNDUP($I6/$E6,0),IFERROR(ROUNDUP(NPER($J6/12,-$E6,$I6),0),"Never")),""))) | L6: =IF(NOT(AND($B6<>"",$E6>0)),"",IF(ISNUMBER($I6),$I6,IF(AND(ISNUMBER($K6),ISNUMBER($J6)),IF($J6=0,$E6*$K6,PV($J6/12,$K6,-$E6)),""))) | M6: =IF(ISNUMBER($K6),$E6*$K6,"") | N6: =IF(AND(ISNUMBER($M6),ISNUMBER($L6)),MAX(0,$M6-$L6),"") | O6: =IF(ISNUMBER($K6),EDATE(Settings!$C$9,$K6),"") | P6: =IF(ISNUMBER($J6),COUNTIF($J$6:$J$25,">"&$J6)+1,"") | Q6: =IF(ISNUMBER($L6),COUNTIF($L$6:$L$25,"<"&$L6)+1,"") | R6: =IF(NOT(ISNUMBER($J6)),"",IF($J6>=Settings!$C$6,"HIGH",IF($J6>=Settings!$C$7,"CHECK","OK"))) | S6: =IF(ISNUMBER($J6),$J6+ROW()/10000000,"")
B7: Store credit card | C7: Credit card | E7: 40 | H7: 0.2999 | I7: 850 | J7: =IF(NOT(AND($B7<>"",$E7>0)),"",IF(ISNUMBER($H7),$H7,IF(AND($D7>0,$F7>0),IFERROR(RATE($F7,-$E7,$D7)*12,""),""))) | K7: =IF(NOT(AND($B7<>"",$E7>0)),"",IF($F7>0,MAX(0,$F7-N($G7)),IF(AND(ISNUMBER($I7),ISNUMBER($J7)),IF($J7=0,ROUNDUP($I7/$E7,0),IFERROR(ROUNDUP(NPER($J7/12,-$E7,$I7),0),"Never")),""))) | L7: =IF(NOT(AND($B7<>"",$E7>0)),"",IF(ISNUMBER($I7),$I7,IF(AND(ISNUMBER($K7),ISNUMBER($J7)),IF($J7=0,$E7*$K7,PV($J7/12,$K7,-$E7)),""))) | M7: =IF(ISNUMBER($K7),$E7*$K7,"") | N7: =IF(AND(ISNUMBER($M7),ISNUMBER($L7)),MAX(0,$M7-$L7),"") | O7: =IF(ISNUMBER($K7),EDATE(Settings!$C$9,$K7),"") | P7: =IF(ISNUMBER($J7),COUNTIF($J$6:$J$25,">"&$J7)+1,"") | Q7: =IF(ISNUMBER($L7),COUNTIF($L$6:$L$25,"<"&$L7)+1,"") | R7: =IF(NOT(ISNUMBER($J7)),"",IF($J7>=Settings!$C$6,"HIGH",IF($J7>=Settings!$C$7,"CHECK","OK"))) | S7: =IF(ISNUMBER($J7),$J7+ROW()/10000000,"")
B8: Car loan | C8: Loan | E8: 330 | H8: 0.069 | I8: 14500 | J8: =IF(NOT(AND($B8<>"",$E8>0)),"",IF(ISNUMBER($H8),$H8,IF(AND($D8>0,$F8>0),IFERROR(RATE($F8,-$E8,$D8)*12,""),""))) | K8: =IF(NOT(AND($B8<>"",$E8>0)),"",IF($F8>0,MAX(0,$F8-N($G8)),IF(AND(ISNUMBER($I8),ISNUMBER($J8)),IF($J8=0,ROUNDUP($I8/$E8,0),IFERROR(ROUNDUP(NPER($J8/12,-$E8,$I8),0),"Never")),""))) | L8: =IF(NOT(AND($B8<>"",$E8>0)),"",IF(ISNUMBER($I8),$I8,IF(AND(ISNUMBER($K8),ISNUMBER($J8)),IF($J8=0,$E8*$K8,PV($J8/12,$K8,-$E8)),""))) | M8: =IF(ISNUMBER($K8),$E8*$K8,"") | N8: =IF(AND(ISNUMBER($M8),ISNUMBER($L8)),MAX(0,$M8-$L8),"") | O8: =IF(ISNUMBER($K8),EDATE(Settings!$C$9,$K8),"") | P8: =IF(ISNUMBER($J8),COUNTIF($J$6:$J$25,">"&$J8)+1,"") | Q8: =IF(ISNUMBER($L8),COUNTIF($L$6:$L$25,"<"&$L8)+1,"") | R8: =IF(NOT(ISNUMBER($J8)),"",IF($J8>=Settings!$C$6,"HIGH",IF($J8>=Settings!$C$7,"CHECK","OK"))) | S8: =IF(ISNUMBER($J8),$J8+ROW()/10000000,"")
B9: Student loan | C9: Loan | E9: 110 | H9: 0.055 | I9: 9800 | J9: =IF(NOT(AND($B9<>"",$E9>0)),"",IF(ISNUMBER($H9),$H9,IF(AND($D9>0,$F9>0),IFERROR(RATE($F9,-$E9,$D9)*12,""),""))) | K9: =IF(NOT(AND($B9<>"",$E9>0)),"",IF($F9>0,MAX(0,$F9-N($G9)),IF(AND(ISNUMBER($I9),ISNUMBER($J9)),IF($J9=0,ROUNDUP($I9/$E9,0),IFERROR(ROUNDUP(NPER($J9/12,-$E9,$I9),0),"Never")),""))) | L9: =IF(NOT(AND($B9<>"",$E9>0)),"",IF(ISNUMBER($I9),$I9,IF(AND(ISNUMBER($K9),ISNUMBER($J9)),IF($J9=0,$E9*$K9,PV($J9/12,$K9,-$E9)),""))) | M9: =IF(ISNUMBER($K9),$E9*$K9,"") | N9: =IF(AND(ISNUMBER($M9),ISNUMBER($L9)),MAX(0,$M9-$L9),"") | O9: =IF(ISNUMBER($K9),EDATE(Settings!$C$9,$K9),"") | P9: =IF(ISNUMBER($J9),COUNTIF($J$6:$J$25,">"&$J9)+1,"") | Q9: =IF(ISNUMBER($L9),COUNTIF($L$6:$L$25,"<"&$L9)+1,"") | R9: =IF(NOT(ISNUMBER($J9)),"",IF($J9>=Settings!$C$6,"HIGH",IF($J9>=Settings!$C$7,"CHECK","OK"))) | S9: =IF(ISNUMBER($J9),$J9+ROW()/10000000,"")
B10: Phone installment plan | C10: Installment | D10: 1200 | E10: 67 | F10: 24 | G10: 6 | J10: =IF(NOT(AND($B10<>"",$E10>0)),"",IF(ISNUMBER($H10),$H10,IF(AND($D10>0,$F10>0),IFERROR(RATE($F10,-$E10,$D10)*12,""),""))) | K10: =IF(NOT(AND($B10<>"",$E10>0)),"",IF($F10>0,MAX(0,$F10-N($G10)),IF(AND(ISNUMBER($I10),ISNUMBER($J10)),IF($J10=0,ROUNDUP($I10/$E10,0),IFERROR(ROUNDUP(NPER($J10/12,-$E10,$I10),0),"Never")),""))) | L10: =IF(NOT(AND($B10<>"",$E10>0)),"",IF(ISNUMBER($I10),$I10,IF(AND(ISNUMBER($K10),ISNUMBER($J10)),IF($J10=0,$E10*$K10,PV($J10/12,$K10,-$E10)),""))) | M10: =IF(ISNUMBER($K10),$E10*$K10,"") | N10: =IF(AND(ISNUMBER($M10),ISNUMBER($L10)),MAX(0,$M10-$L10),"") | O10: =IF(ISNUMBER($K10),EDATE(Settings!$C$9,$K10),"") | P10: =IF(ISNUMBER($J10),COUNTIF($J$6:$J$25,">"&$J10)+1,"") | Q10: =IF(ISNUMBER($L10),COUNTIF($L$6:$L$25,"<"&$L10)+1,"") | R10: =IF(NOT(ISNUMBER($J10)),"",IF($J10>=Settings!$C$6,"HIGH",IF($J10>=Settings!$C$7,"CHECK","OK"))) | S10: =IF(ISNUMBER($J10),$J10+ROW()/10000000,"")
B11: Sofa store financing | C11: Installment | D11: 2000 | E11: 105 | F11: 24 | G11: 3 | J11: =IF(NOT(AND($B11<>"",$E11>0)),"",IF(ISNUMBER($H11),$H11,IF(AND($D11>0,$F11>0),IFERROR(RATE($F11,-$E11,$D11)*12,""),""))) | K11: =IF(NOT(AND($B11<>"",$E11>0)),"",IF($F11>0,MAX(0,$F11-N($G11)),IF(AND(ISNUMBER($I11),ISNUMBER($J11)),IF($J11=0,ROUNDUP($I11/$E11,0),IFERROR(ROUNDUP(NPER($J11/12,-$E11,$I11),0),"Never")),""))) | L11: =IF(NOT(AND($B11<>"",$E11>0)),"",IF(ISNUMBER($I11),$I11,IF(AND(ISNUMBER($K11),ISNUMBER($J11)),IF($J11=0,$E11*$K11,PV($J11/12,$K11,-$E11)),""))) | M11: =IF(ISNUMBER($K11),$E11*$K11,"") | N11: =IF(AND(ISNUMBER($M11),ISNUMBER($L11)),MAX(0,$M11-$L11),"") | O11: =IF(ISNUMBER($K11),EDATE(Settings!$C$9,$K11),"") | P11: =IF(ISNUMBER($J11),COUNTIF($J$6:$J$25,">"&$J11)+1,"") | Q11: =IF(ISNUMBER($L11),COUNTIF($L$6:$L$25,"<"&$L11)+1,"") | R11: =IF(NOT(ISNUMBER($J11)),"",IF($J11>=Settings!$C$6,"HIGH",IF($J11>=Settings!$C$7,"CHECK","OK"))) | S11: =IF(ISNUMBER($J11),$J11+ROW()/10000000,"")
B12: Laptop pay-in-4 | C12: BNPL | D12: 800 | E12: 200 | F12: 4 | G12: 1 | J12: =IF(NOT(AND($B12<>"",$E12>0)),"",IF(ISNUMBER($H12),$H12,IF(AND($D12>0,$F12>0),IFERROR(RATE($F12,-$E12,$D12)*12,""),""))) | K12: =IF(NOT(AND($B12<>"",$E12>0)),"",IF($F12>0,MAX(0,$F12-N($G12)),IF(AND(ISNUMBER($I12),ISNUMBER($J12)),IF($J12=0,ROUNDUP($I12/$E12,0),IFERROR(ROUNDUP(NPER($J12/12,-$E12,$I12),0),"Never")),""))) | L12: =IF(NOT(AND($B12<>"",$E12>0)),"",IF(ISNUMBER($I12),$I12,IF(AND(ISNUMBER($K12),ISNUMBER($J12)),IF($J12=0,$E12*$K12,PV($J12/12,$K12,-$E12)),""))) | M12: =IF(ISNUMBER($K12),$E12*$K12,"") | N12: =IF(AND(ISNUMBER($M12),ISNUMBER($L12)),MAX(0,$M12-$L12),"") | O12: =IF(ISNUMBER($K12),EDATE(Settings!$C$9,$K12),"") | P12: =IF(ISNUMBER($J12),COUNTIF($J$6:$J$25,">"&$J12)+1,"") | Q12: =IF(ISNUMBER($L12),COUNTIF($L$6:$L$25,"<"&$L12)+1,"") | R12: =IF(NOT(ISNUMBER($J12)),"",IF($J12>=Settings!$C$6,"HIGH",IF($J12>=Settings!$C$7,"CHECK","OK"))) | S12: =IF(ISNUMBER($J12),$J12+ROW()/10000000,"")
B13: Loan from family | C13: Family / friend | E13: 100 | H13: 0 | I13: 1500 | J13: =IF(NOT(AND($B13<>"",$E13>0)),"",IF(ISNUMBER($H13),$H13,IF(AND($D13>0,$F13>0),IFERROR(RATE($F13,-$E13,$D13)*12,""),""))) | K13: =IF(NOT(AND($B13<>"",$E13>0)),"",IF($F13>0,MAX(0,$F13-N($G13)),IF(AND(ISNUMBER($I13),ISNUMBER($J13)),IF($J13=0,ROUNDUP($I13/$E13,0),IFERROR(ROUNDUP(NPER($J13/12,-$E13,$I13),0),"Never")),""))) | L13: =IF(NOT(AND($B13<>"",$E13>0)),"",IF(ISNUMBER($I13),$I13,IF(AND(ISNUMBER($K13),ISNUMBER($J13)),IF($J13=0,$E13*$K13,PV($J13/12,$K13,-$E13)),""))) | M13: =IF(ISNUMBER($K13),$E13*$K13,"") | N13: =IF(AND(ISNUMBER($M13),ISNUMBER($L13)),MAX(0,$M13-$L13),"") | O13: =IF(ISNUMBER($K13),EDATE(Settings!$C$9,$K13),"") | P13: =IF(ISNUMBER($J13),COUNTIF($J$6:$J$25,">"&$J13)+1,"") | Q13: =IF(ISNUMBER($L13),COUNTIF($L$6:$L$25,"<"&$L13)+1,"") | R13: =IF(NOT(ISNUMBER($J13)),"",IF($J13>=Settings!$C$6,"HIGH",IF($J13>=Settings!$C$7,"CHECK","OK"))) | S13: =IF(ISNUMBER($J13),$J13+ROW()/10000000,"")
J14: =IF(NOT(AND($B14<>"",$E14>0)),"",IF(ISNUMBER($H14),$H14,IF(AND($D14>0,$F14>0),IFERROR(RATE($F14,-$E14,$D14)*12,""),""))) | K14: =IF(NOT(AND($B14<>"",$E14>0)),"",IF($F14>0,MAX(0,$F14-N($G14)),IF(AND(ISNUMBER($I14),ISNUMBER($J14)),IF($J14=0,ROUNDUP($I14/$E14,0),IFERROR(ROUNDUP(NPER($J14/12,-$E14,$I14),0),"Never")),""))) | L14: =IF(NOT(AND($B14<>"",$E14>0)),"",IF(ISNUMBER($I14),$I14,IF(AND(ISNUMBER($K14),ISNUMBER($J14)),IF($J14=0,$E14*$K14,PV($J14/12,$K14,-$E14)),""))) | M14: =IF(ISNUMBER($K14),$E14*$K14,"") | N14: =IF(AND(ISNUMBER($M14),ISNUMBER($L14)),MAX(0,$M14-$L14),"") | O14: =IF(ISNUMBER($K14),EDATE(Settings!$C$9,$K14),"") | P14: =IF(ISNUMBER($J14),COUNTIF($J$6:$J$25,">"&$J14)+1,"") | Q14: =IF(ISNUMBER($L14),COUNTIF($L$6:$L$25,"<"&$L14)+1,"") | R14: =IF(NOT(ISNUMBER($J14)),"",IF($J14>=Settings!$C$6,"HIGH",IF($J14>=Settings!$C$7,"CHECK","OK"))) | S14: =IF(ISNUMBER($J14),$J14+ROW()/10000000,"")
J15: =IF(NOT(AND($B15<>"",$E15>0)),"",IF(ISNUMBER($H15),$H15,IF(AND($D15>0,$F15>0),IFERROR(RATE($F15,-$E15,$D15)*12,""),""))) | K15: =IF(NOT(AND($B15<>"",$E15>0)),"",IF($F15>0,MAX(0,$F15-N($G15)),IF(AND(ISNUMBER($I15),ISNUMBER($J15)),IF($J15=0,ROUNDUP($I15/$E15,0),IFERROR(ROUNDUP(NPER($J15/12,-$E15,$I15),0),"Never")),""))) | L15: =IF(NOT(AND($B15<>"",$E15>0)),"",IF(ISNUMBER($I15),$I15,IF(AND(ISNUMBER($K15),ISNUMBER($J15)),IF($J15=0,$E15*$K15,PV($J15/12,$K15,-$E15)),""))) | M15: =IF(ISNUMBER($K15),$E15*$K15,"") | N15: =IF(AND(ISNUMBER($M15),ISNUMBER($L15)),MAX(0,$M15-$L15),"") | O15: =IF(ISNUMBER($K15),EDATE(Settings!$C$9,$K15),"") | P15: =IF(ISNUMBER($J15),COUNTIF($J$6:$J$25,">"&$J15)+1,"") | Q15: =IF(ISNUMBER($L15),COUNTIF($L$6:$L$25,"<"&$L15)+1,"") | R15: =IF(NOT(ISNUMBER($J15)),"",IF($J15>=Settings!$C$6,"HIGH",IF($J15>=Settings!$C$7,"CHECK","OK"))) | S15: =IF(ISNUMBER($J15),$J15+ROW()/10000000,"")
J16: =IF(NOT(AND($B16<>"",$E16>0)),"",IF(ISNUMBER($H16),$H16,IF(AND($D16>0,$F16>0),IFERROR(RATE($F16,-$E16,$D16)*12,""),""))) | K16: =IF(NOT(AND($B16<>"",$E16>0)),"",IF($F16>0,MAX(0,$F16-N($G16)),IF(AND(ISNUMBER($I16),ISNUMBER($J16)),IF($J16=0,ROUNDUP($I16/$E16,0),IFERROR(ROUNDUP(NPER($J16/12,-$E16,$I16),0),"Never")),""))) | L16: =IF(NOT(AND($B16<>"",$E16>0)),"",IF(ISNUMBER($I16),$I16,IF(AND(ISNUMBER($K16),ISNUMBER($J16)),IF($J16=0,$E16*$K16,PV($J16/12,$K16,-$E16)),""))) | M16: =IF(ISNUMBER($K16),$E16*$K16,"") | N16: =IF(AND(ISNUMBER($M16),ISNUMBER($L16)),MAX(0,$M16-$L16),"") | O16: =IF(ISNUMBER($K16),EDATE(Settings!$C$9,$K16),"") | P16: =IF(ISNUMBER($J16),COUNTIF($J$6:$J$25,">"&$J16)+1,"") | Q16: =IF(ISNUMBER($L16),COUNTIF($L$6:$L$25,"<"&$L16)+1,"") | R16: =IF(NOT(ISNUMBER($J16)),"",IF($J16>=Settings!$C$6,"HIGH",IF($J16>=Settings!$C$7,"CHECK","OK"))) | S16: =IF(ISNUMBER($J16),$J16+ROW()/10000000,"")
J17: =IF(NOT(AND($B17<>"",$E17>0)),"",IF(ISNUMBER($H17),$H17,IF(AND($D17>0,$F17>0),IFERROR(RATE($F17,-$E17,$D17)*12,""),""))) | K17: =IF(NOT(AND($B17<>"",$E17>0)),"",IF($F17>0,MAX(0,$F17-N($G17)),IF(AND(ISNUMBER($I17),ISNUMBER($J17)),IF($J17=0,ROUNDUP($I17/$E17,0),IFERROR(ROUNDUP(NPER($J17/12,-$E17,$I17),0),"Never")),""))) | L17: =IF(NOT(AND($B17<>"",$E17>0)),"",IF(ISNUMBER($I17),$I17,IF(AND(ISNUMBER($K17),ISNUMBER($J17)),IF($J17=0,$E17*$K17,PV($J17/12,$K17,-$E17)),""))) | M17: =IF(ISNUMBER($K17),$E17*$K17,"") | N17: =IF(AND(ISNUMBER($M17),ISNUMBER($L17)),MAX(0,$M17-$L17),"") | O17: =IF(ISNUMBER($K17),EDATE(Settings!$C$9,$K17),"") | P17: =IF(ISNUMBER($J17),COUNTIF($J$6:$J$25,">"&$J17)+1,"") | Q17: =IF(ISNUMBER($L17),COUNTIF($L$6:$L$25,"<"&$L17)+1,"") | R17: =IF(NOT(ISNUMBER($J17)),"",IF($J17>=Settings!$C$6,"HIGH",IF($J17>=Settings!$C$7,"CHECK","OK"))) | S17: =IF(ISNUMBER($J17),$J17+ROW()/10000000,"")
J18: =IF(NOT(AND($B18<>"",$E18>0)),"",IF(ISNUMBER($H18),$H18,IF(AND($D18>0,$F18>0),IFERROR(RATE($F18,-$E18,$D18)*12,""),""))) | K18: =IF(NOT(AND($B18<>"",$E18>0)),"",IF($F18>0,MAX(0,$F18-N($G18)),IF(AND(ISNUMBER($I18),ISNUMBER($J18)),IF($J18=0,ROUNDUP($I18/$E18,0),IFERROR(ROUNDUP(NPER($J18/12,-$E18,$I18),0),"Never")),""))) | L18: =IF(NOT(AND($B18<>"",$E18>0)),"",IF(ISNUMBER($I18),$I18,IF(AND(ISNUMBER($K18),ISNUMBER($J18)),IF($J18=0,$E18*$K18,PV($J18/12,$K18,-$E18)),""))) | M18: =IF(ISNUMBER($K18),$E18*$K18,"") | N18: =IF(AND(ISNUMBER($M18),ISNUMBER($L18)),MAX(0,$M18-$L18),"") | O18: =IF(ISNUMBER($K18),EDATE(Settings!$C$9,$K18),"") | P18: =IF(ISNUMBER($J18),COUNTIF($J$6:$J$25,">"&$J18)+1,"") | Q18: =IF(ISNUMBER($L18),COUNTIF($L$6:$L$25,"<"&$L18)+1,"") | R18: =IF(NOT(ISNUMBER($J18)),"",IF($J18>=Settings!$C$6,"HIGH",IF($J18>=Settings!$C$7,"CHECK","OK"))) | S18: =IF(ISNUMBER($J18),$J18+ROW()/10000000,"")
J19: =IF(NOT(AND($B19<>"",$E19>0)),"",IF(ISNUMBER($H19),$H19,IF(AND($D19>0,$F19>0),IFERROR(RATE($F19,-$E19,$D19)*12,""),""))) | K19: =IF(NOT(AND($B19<>"",$E19>0)),"",IF($F19>0,MAX(0,$F19-N($G19)),IF(AND(ISNUMBER($I19),ISNUMBER($J19)),IF($J19=0,ROUNDUP($I19/$E19,0),IFERROR(ROUNDUP(NPER($J19/12,-$E19,$I19),0),"Never")),""))) | L19: =IF(NOT(AND($B19<>"",$E19>0)),"",IF(ISNUMBER($I19),$I19,IF(AND(ISNUMBER($K19),ISNUMBER($J19)),IF($J19=0,$E19*$K19,PV($J19/12,$K19,-$E19)),""))) | M19: =IF(ISNUMBER($K19),$E19*$K19,"") | N19: =IF(AND(ISNUMBER($M19),ISNUMBER($L19)),MAX(0,$M19-$L19),"") | O19: =IF(ISNUMBER($K19),EDATE(Settings!$C$9,$K19),"") | P19: =IF(ISNUMBER($J19),COUNTIF($J$6:$J$25,">"&$J19)+1,"") | Q19: =IF(ISNUMBER($L19),COUNTIF($L$6:$L$25,"<"&$L19)+1,"") | R19: =IF(NOT(ISNUMBER($J19)),"",IF($J19>=Settings!$C$6,"HIGH",IF($J19>=Settings!$C$7,"CHECK","OK"))) | S19: =IF(ISNUMBER($J19),$J19+ROW()/10000000,"")
J20: =IF(NOT(AND($B20<>"",$E20>0)),"",IF(ISNUMBER($H20),$H20,IF(AND($D20>0,$F20>0),IFERROR(RATE($F20,-$E20,$D20)*12,""),""))) | K20: =IF(NOT(AND($B20<>"",$E20>0)),"",IF($F20>0,MAX(0,$F20-N($G20)),IF(AND(ISNUMBER($I20),ISNUMBER($J20)),IF($J20=0,ROUNDUP($I20/$E20,0),IFERROR(ROUNDUP(NPER($J20/12,-$E20,$I20),0),"Never")),""))) | L20: =IF(NOT(AND($B20<>"",$E20>0)),"",IF(ISNUMBER($I20),$I20,IF(AND(ISNUMBER($K20),ISNUMBER($J20)),IF($J20=0,$E20*$K20,PV($J20/12,$K20,-$E20)),""))) | M20: =IF(ISNUMBER($K20),$E20*$K20,"") | N20: =IF(AND(ISNUMBER($M20),ISNUMBER($L20)),MAX(0,$M20-$L20),"") | O20: =IF(ISNUMBER($K20),EDATE(Settings!$C$9,$K20),"") | P20: =IF(ISNUMBER($J20),COUNTIF($J$6:$J$25,">"&$J20)+1,"") | Q20: =IF(ISNUMBER($L20),COUNTIF($L$6:$L$25,"<"&$L20)+1,"") | R20: =IF(NOT(ISNUMBER($J20)),"",IF($J20>=Settings!$C$6,"HIGH",IF($J20>=Settings!$C$7,"CHECK","OK"))) | S20: =IF(ISNUMBER($J20),$J20+ROW()/10000000,"")
J21: =IF(NOT(AND($B21<>"",$E21>0)),"",IF(ISNUMBER($H21),$H21,IF(AND($D21>0,$F21>0),IFERROR(RATE($F21,-$E21,$D21)*12,""),""))) | K21: =IF(NOT(AND($B21<>"",$E21>0)),"",IF($F21>0,MAX(0,$F21-N($G21)),IF(AND(ISNUMBER($I21),ISNUMBER($J21)),IF($J21=0,ROUNDUP($I21/$E21,0),IFERROR(ROUNDUP(NPER($J21/12,-$E21,$I21),0),"Never")),""))) | L21: =IF(NOT(AND($B21<>"",$E21>0)),"",IF(ISNUMBER($I21),$I21,IF(AND(ISNUMBER($K21),ISNUMBER($J21)),IF($J21=0,$E21*$K21,PV($J21/12,$K21,-$E21)),""))) | M21: =IF(ISNUMBER($K21),$E21*$K21,"") | N21: =IF(AND(ISNUMBER($M21),ISNUMBER($L21)),MAX(0,$M21-$L21),"") | O21: =IF(ISNUMBER($K21),EDATE(Settings!$C$9,$K21),"") | P21: =IF(ISNUMBER($J21),COUNTIF($J$6:$J$25,">"&$J21)+1,"") | Q21: =IF(ISNUMBER($L21),COUNTIF($L$6:$L$25,"<"&$L21)+1,"") | R21: =IF(NOT(ISNUMBER($J21)),"",IF($J21>=Settings!$C$6,"HIGH",IF($J21>=Settings!$C$7,"CHECK","OK"))) | S21: =IF(ISNUMBER($J21),$J21+ROW()/10000000,"")
J22: =IF(NOT(AND($B22<>"",$E22>0)),"",IF(ISNUMBER($H22),$H22,IF(AND($D22>0,$F22>0),IFERROR(RATE($F22,-$E22,$D22)*12,""),""))) | K22: =IF(NOT(AND($B22<>"",$E22>0)),"",IF($F22>0,MAX(0,$F22-N($G22)),IF(AND(ISNUMBER($I22),ISNUMBER($J22)),IF($J22=0,ROUNDUP($I22/$E22,0),IFERROR(ROUNDUP(NPER($J22/12,-$E22,$I22),0),"Never")),""))) | L22: =IF(NOT(AND($B22<>"",$E22>0)),"",IF(ISNUMBER($I22),$I22,IF(AND(ISNUMBER($K22),ISNUMBER($J22)),IF($J22=0,$E22*$K22,PV($J22/12,$K22,-$E22)),""))) | M22: =IF(ISNUMBER($K22),$E22*$K22,"") | N22: =IF(AND(ISNUMBER($M22),ISNUMBER($L22)),MAX(0,$M22-$L22),"") | O22: =IF(ISNUMBER($K22),EDATE(Settings!$C$9,$K22),"") | P22: =IF(ISNUMBER($J22),COUNTIF($J$6:$J$25,">"&$J22)+1,"") | Q22: =IF(ISNUMBER($L22),COUNTIF($L$6:$L$25,"<"&$L22)+1,"") | R22: =IF(NOT(ISNUMBER($J22)),"",IF($J22>=Settings!$C$6,"HIGH",IF($J22>=Settings!$C$7,"CHECK","OK"))) | S22: =IF(ISNUMBER($J22),$J22+ROW()/10000000,"")
J23: =IF(NOT(AND($B23<>"",$E23>0)),"",IF(ISNUMBER($H23),$H23,IF(AND($D23>0,$F23>0),IFERROR(RATE($F23,-$E23,$D23)*12,""),""))) | K23: =IF(NOT(AND($B23<>"",$E23>0)),"",IF($F23>0,MAX(0,$F23-N($G23)),IF(AND(ISNUMBER($I23),ISNUMBER($J23)),IF($J23=0,ROUNDUP($I23/$E23,0),IFERROR(ROUNDUP(NPER($J23/12,-$E23,$I23),0),"Never")),""))) | L23: =IF(NOT(AND($B23<>"",$E23>0)),"",IF(ISNUMBER($I23),$I23,IF(AND(ISNUMBER($K23),ISNUMBER($J23)),IF($J23=0,$E23*$K23,PV($J23/12,$K23,-$E23)),""))) | M23: =IF(ISNUMBER($K23),$E23*$K23,"") | N23: =IF(AND(ISNUMBER($M23),ISNUMBER($L23)),MAX(0,$M23-$L23),"") | O23: =IF(ISNUMBER($K23),EDATE(Settings!$C$9,$K23),"") | P23: =IF(ISNUMBER($J23),COUNTIF($J$6:$J$25,">"&$J23)+1,"") | Q23: =IF(ISNUMBER($L23),COUNTIF($L$6:$L$25,"<"&$L23)+1,"") | R23: =IF(NOT(ISNUMBER($J23)),"",IF($J23>=Settings!$C$6,"HIGH",IF($J23>=Settings!$C$7,"CHECK","OK"))) | S23: =IF(ISNUMBER($J23),$J23+ROW()/10000000,"")
J24: =IF(NOT(AND($B24<>"",$E24>0)),"",IF(ISNUMBER($H24),$H24,IF(AND($D24>0,$F24>0),IFERROR(RATE($F24,-$E24,$D24)*12,""),""))) | K24: =IF(NOT(AND($B24<>"",$E24>0)),"",IF($F24>0,MAX(0,$F24-N($G24)),IF(AND(ISNUMBER($I24),ISNUMBER($J24)),IF($J24=0,ROUNDUP($I24/$E24,0),IFERROR(ROUNDUP(NPER($J24/12,-$E24,$I24),0),"Never")),""))) | L24: =IF(NOT(AND($B24<>"",$E24>0)),"",IF(ISNUMBER($I24),$I24,IF(AND(ISNUMBER($K24),ISNUMBER($J24)),IF($J24=0,$E24*$K24,PV($J24/12,$K24,-$E24)),""))) | M24: =IF(ISNUMBER($K24),$E24*$K24,"") | N24: =IF(AND(ISNUMBER($M24),ISNUMBER($L24)),MAX(0,$M24-$L24),"") | O24: =IF(ISNUMBER($K24),EDATE(Settings!$C$9,$K24),"") | P24: =IF(ISNUMBER($J24),COUNTIF($J$6:$J$25,">"&$J24)+1,"") | Q24: =IF(ISNUMBER($L24),COUNTIF($L$6:$L$25,"<"&$L24)+1,"") | R24: =IF(NOT(ISNUMBER($J24)),"",IF($J24>=Settings!$C$6,"HIGH",IF($J24>=Settings!$C$7,"CHECK","OK"))) | S24: =IF(ISNUMBER($J24),$J24+ROW()/10000000,"")
J25: =IF(NOT(AND($B25<>"",$E25>0)),"",IF(ISNUMBER($H25),$H25,IF(AND($D25>0,$F25>0),IFERROR(RATE($F25,-$E25,$D25)*12,""),""))) | K25: =IF(NOT(AND($B25<>"",$E25>0)),"",IF($F25>0,MAX(0,$F25-N($G25)),IF(AND(ISNUMBER($I25),ISNUMBER($J25)),IF($J25=0,ROUNDUP($I25/$E25,0),IFERROR(ROUNDUP(NPER($J25/12,-$E25,$I25),0),"Never")),""))) | L25: =IF(NOT(AND($B25<>"",$E25>0)),"",IF(ISNUMBER($I25),$I25,IF(AND(ISNUMBER($K25),ISNUMBER($J25)),IF($J25=0,$E25*$K25,PV($J25/12,$K25,-$E25)),""))) | M25: =IF(ISNUMBER($K25),$E25*$K25,"") | N25: =IF(AND(ISNUMBER($M25),ISNUMBER($L25)),MAX(0,$M25-$L25),"") | O25: =IF(ISNUMBER($K25),EDATE(Settings!$C$9,$K25),"") | P25: =IF(ISNUMBER($J25),COUNTIF($J$6:$J$25,">"&$J25)+1,"") | Q25: =IF(ISNUMBER($L25),COUNTIF($L$6:$L$25,"<"&$L25)+1,"") | R25: =IF(NOT(ISNUMBER($J25)),"",IF($J25>=Settings!$C$6,"HIGH",IF($J25>=Settings!$C$7,"CHECK","OK"))) | S25: =IF(ISNUMBER($J25),$J25+ROW()/10000000,"")

Sheet Subscriptions
B2: Subscriptions & Free Trials | M2: BLUE headers: you fill in · ORANGE headers: calculated for you
B3: =COUNT(Subscriptions!$L$6:$L$35)&" subscriptions · "&TEXT(SUM(Subscriptions!$L$6:$L$35),"$#,##0.00")&" a month · "&TEXT(SUM(Subscriptions!$M$6:$M$35),"$#,##0")&" a year · cancel the ticked ones and save "&TEXT(SUMIFS(Subscriptions!$M$6:$M$35,Subscriptions!$I$6:$I$35,"Yes"),"$#,##0")&" a year"
B5: NAME | C5: CATEGORY | D5: PRICE | E5: BILLING | F5: START DATE | G5: PAID WITH | H5: AUTO-RENEW? | I5: CANCEL IT? | J5: FREE TRIAL? | K5: TRIAL DAYS | L5: MONTHLY COST | M5: YEARLY COST | N5: NEXT CHARGE | O5: DAYS TO CHARGE | P5: TRIAL: CANCEL BY | Q5: TRIAL DAYS LEFT | R5: ALERT | S5: key | T5: key | U5: key
B6: Netflix | C6: Streaming | D6: 15.49 | E6: Monthly | F6: 45721 | G6: Credit card | H6: Yes | I6: No | J6: No | L6: =IF(NOT(AND($B6<>"",$D6>0)),"",IF($E6="Weekly",$D6*52/12,IF($E6="Quarterly",$D6/3,IF($E6="Yearly",$D6/12,$D6)))) | M6: =IF(ISNUMBER($L6),$L6*12,"") | N6: =IF(OR(NOT(AND($B6<>"",$D6>0)),$F6=""),"",IF($E6="Weekly",IF(IF($J6="Yes",$F6+N($K6),$F6)>=Settings!$C$9,IF($J6="Yes",$F6+N($K6),$F6),IF($J6="Yes",$F6+N($K6),$F6)+7*CEILING((Settings!$C$9-IF($J6="Yes",$F6+N($K6),$F6))/7,1)),IF(EDATE(IF($J6="Yes",$F6+N($K6),$F6),IF($E6="Monthly",1,IF($E6="Quarterly",3,IF($E6="Yearly",12,0)))*(IF(IF($J6="Yes",$F6+N($K6),$F6)>=Settings!$C$9,0,CEILING(DATEDIF(IF($J6="Yes",$F6+N($K6),$F6),Settings!$C$9,"M")/IF($E6="Monthly",1,IF($E6="Quarterly",3,IF($E6="Yearly",12,0))),1))))>=Settings!$C$9,EDATE(IF($J6="Yes",$F6+N($K6),$F6),IF($E6="Monthly",1,IF($E6="Quarterly",3,IF($E6="Yearly",12,0)))*(IF(IF($J6="Yes",$F6+N($K6),$F6)>=Settings!$C$9,0,CEILING(DATEDIF(IF($J6="Yes",$F6+N($K6),$F6),Settings!$C$9,"M")/IF($E6="Monthly",1,IF($E6="Quarterly",3,IF($E6="Yearly",12,0))),1)))),EDATE(IF($J6="Yes",$F6+N($K6),$F6),IF($E6="Monthly",1,IF($E6="Quarterly",3,IF($E6="Yearly",12,0)))*(IF(IF($J6="Yes",$F6+N($K6),$F6)>=Settings!$C$9,0,CEILING(DATEDIF(IF($J6="Yes",$F6+N($K6),$F6),Settings!$C$9,"M")/IF($E6="Monthly",1,IF($E6="Quarterly",3,IF($E6="Yearly",12,0))),1))+1))))) | O6: =IF(ISNUMBER($N6),$N6-Settings!$C$9,"") | P6: =IF(AND(AND($B6<>"",$D6>0),$J6="Yes",ISNUMBER($K6)),$F6+$K6-1,"") | Q6: =IF(ISNUMBER($P6),$P6-Settings!$C$9,"") | R6: =IF(NOT(AND($B6<>"",$D6>0)),"",IF(AND(ISNUMBER($Q6),$Q6<0,$I6<>"Yes"),"Trial ended",IF(AND(ISNUMBER($Q6),$Q6<=Settings!$C$8),"Cancel soon?",IF($I6="Yes","To cancel",IF(AND(ISNUMBER($O6),$O6<=Settings!$C$8),"Charge soon","OK"))))) | S6: =IF(ISNUMBER($O6),$O6+ROW()/1000,"") | T6: =IF(ISNUMBER($M6),$M6+ROW()/100000,"") | U6: =IF(AND(ISNUMBER($Q6),N($Q6)>=0,$I6<>"Yes"),$Q6+ROW()/1000,"")
B7: Spotify | C7: Streaming | D7: 11.99 | E7: Monthly | F7: 45616 | G7: PayPal | H7: Yes | I7: No | J7: No | L7: =IF(NOT(AND($B7<>"",$D7>0)),"",IF($E7="Weekly",$D7*52/12,IF($E7="Quarterly",$D7/3,IF($E7="Yearly",$D7/12,$D7)))) | M7: =IF(ISNUMBER($L7),$L7*12,"") | N7: =IF(OR(NOT(AND($B7<>"",$D7>0)),$F7=""),"",IF($E7="Weekly",IF(IF($J7="Yes",$F7+N($K7),$F7)>=Settings!$C$9,IF($J7="Yes",$F7+N($K7),$F7),IF($J7="Yes",$F7+N($K7),$F7)+7*CEILING((Settings!$C$9-IF($J7="Yes",$F7+N($K7),$F7))/7,1)),IF(EDATE(IF($J7="Yes",$F7+N($K7),$F7),IF($E7="Monthly",1,IF($E7="Quarterly",3,IF($E7="Yearly",12,0)))*(IF(IF($J7="Yes",$F7+N($K7),$F7)>=Settings!$C$9,0,CEILING(DATEDIF(IF($J7="Yes",$F7+N($K7),$F7),Settings!$C$9,"M")/IF($E7="Monthly",1,IF($E7="Quarterly",3,IF($E7="Yearly",12,0))),1))))>=Settings!$C$9,EDATE(IF($J7="Yes",$F7+N($K7),$F7),IF($E7="Monthly",1,IF($E7="Quarterly",3,IF($E7="Yearly",12,0)))*(IF(IF($J7="Yes",$F7+N($K7),$F7)>=Settings!$C$9,0,CEILING(DATEDIF(IF($J7="Yes",$F7+N($K7),$F7),Settings!$C$9,"M")/IF($E7="Monthly",1,IF($E7="Quarterly",3,IF($E7="Yearly",12,0))),1)))),EDATE(IF($J7="Yes",$F7+N($K7),$F7),IF($E7="Monthly",1,IF($E7="Quarterly",3,IF($E7="Yearly",12,0)))*(IF(IF($J7="Yes",$F7+N($K7),$F7)>=Settings!$C$9,0,CEILING(DATEDIF(IF($J7="Yes",$F7+N($K7),$F7),Settings!$C$9,"M")/IF($E7="Monthly",1,IF($E7="Quarterly",3,IF($E7="Yearly",12,0))),1))+1))))) | O7: =IF(ISNUMBER($N7),$N7-Settings!$C$9,"") | P7: =IF(AND(AND($B7<>"",$D7>0),$J7="Yes",ISNUMBER($K7)),$F7+$K7-1,"") | Q7: =IF(ISNUMBER($P7),$P7-Settings!$C$9,"") | R7: =IF(NOT(AND($B7<>"",$D7>0)),"",IF(AND(ISNUMBER($Q7),$Q7<0,$I7<>"Yes"),"Trial ended",IF(AND(ISNUMBER($Q7),$Q7<=Settings!$C$8),"Cancel soon?",IF($I7="Yes","To cancel",IF(AND(ISNUMBER($O7),$O7<=Settings!$C$8),"Charge soon","OK"))))) | S7: =IF(ISNUMBER($O7),$O7+ROW()/1000,"") | T7: =IF(ISNUMBER($M7),$M7+ROW()/100000,"") | U7: =IF(AND(ISNUMBER($Q7),N($Q7)>=0,$I7<>"Yes"),$Q7+ROW()/1000,"")
B8: Disney+ | C8: Streaming | D8: 13.99 | E8: Monthly | F8: 45881 | G8: Credit card | H8: Yes | I8: Yes | J8: No | L8: =IF(NOT(AND($B8<>"",$D8>0)),"",IF($E8="Weekly",$D8*52/12,IF($E8="Quarterly",$D8/3,IF($E8="Yearly",$D8/12,$D8)))) | M8: =IF(ISNUMBER($L8),$L8*12,"") | N8: =IF(OR(NOT(AND($B8<>"",$D8>0)),$F8=""),"",IF($E8="Weekly",IF(IF($J8="Yes",$F8+N($K8),$F8)>=Settings!$C$9,IF($J8="Yes",$F8+N($K8),$F8),IF($J8="Yes",$F8+N($K8),$F8)+7*CEILING((Settings!$C$9-IF($J8="Yes",$F8+N($K8),$F8))/7,1)),IF(EDATE(IF($J8="Yes",$F8+N($K8),$F8),IF($E8="Monthly",1,IF($E8="Quarterly",3,IF($E8="Yearly",12,0)))*(IF(IF($J8="Yes",$F8+N($K8),$F8)>=Settings!$C$9,0,CEILING(DATEDIF(IF($J8="Yes",$F8+N($K8),$F8),Settings!$C$9,"M")/IF($E8="Monthly",1,IF($E8="Quarterly",3,IF($E8="Yearly",12,0))),1))))>=Settings!$C$9,EDATE(IF($J8="Yes",$F8+N($K8),$F8),IF($E8="Monthly",1,IF($E8="Quarterly",3,IF($E8="Yearly",12,0)))*(IF(IF($J8="Yes",$F8+N($K8),$F8)>=Settings!$C$9,0,CEILING(DATEDIF(IF($J8="Yes",$F8+N($K8),$F8),Settings!$C$9,"M")/IF($E8="Monthly",1,IF($E8="Quarterly",3,IF($E8="Yearly",12,0))),1)))),EDATE(IF($J8="Yes",$F8+N($K8),$F8),IF($E8="Monthly",1,IF($E8="Quarterly",3,IF($E8="Yearly",12,0)))*(IF(IF($J8="Yes",$F8+N($K8),$F8)>=Settings!$C$9,0,CEILING(DATEDIF(IF($J8="Yes",$F8+N($K8),$F8),Settings!$C$9,"M")/IF($E8="Monthly",1,IF($E8="Quarterly",3,IF($E8="Yearly",12,0))),1))+1))))) | O8: =IF(ISNUMBER($N8),$N8-Settings!$C$9,"") | P8: =IF(AND(AND($B8<>"",$D8>0),$J8="Yes",ISNUMBER($K8)),$F8+$K8-1,"") | Q8: =IF(ISNUMBER($P8),$P8-Settings!$C$9,"") | R8: =IF(NOT(AND($B8<>"",$D8>0)),"",IF(AND(ISNUMBER($Q8),$Q8<0,$I8<>"Yes"),"Trial ended",IF(AND(ISNUMBER($Q8),$Q8<=Settings!$C$8),"Cancel soon?",IF($I8="Yes","To cancel",IF(AND(ISNUMBER($O8),$O8<=Settings!$C$8),"Charge soon","OK"))))) | S8: =IF(ISNUMBER($O8),$O8+ROW()/1000,"") | T8: =IF(ISNUMBER($M8),$M8+ROW()/100000,"") | U8: =IF(AND(ISNUMBER($Q8),N($Q8)>=0,$I8<>"Yes"),$Q8+ROW()/1000,"")
B9: YouTube Premium | C9: Streaming | D9: 13.99 | E9: Monthly | F9: 45805 | G9: Google Pay | H9: Yes | I9: No | J9: No | L9: =IF(NOT(AND($B9<>"",$D9>0)),"",IF($E9="Weekly",$D9*52/12,IF($E9="Quarterly",$D9/3,IF($E9="Yearly",$D9/12,$D9)))) | M9: =IF(ISNUMBER($L9),$L9*12,"") | N9: =IF(OR(NOT(AND($B9<>"",$D9>0)),$F9=""),"",IF($E9="Weekly",IF(IF($J9="Yes",$F9+N($K9),$F9)>=Settings!$C$9,IF($J9="Yes",$F9+N($K9),$F9),IF($J9="Yes",$F9+N($K9),$F9)+7*CEILING((Settings!$C$9-IF($J9="Yes",$F9+N($K9),$F9))/7,1)),IF(EDATE(IF($J9="Yes",$F9+N($K9),$F9),IF($E9="Monthly",1,IF($E9="Quarterly",3,IF($E9="Yearly",12,0)))*(IF(IF($J9="Yes",$F9+N($K9),$F9)>=Settings!$C$9,0,CEILING(DATEDIF(IF($J9="Yes",$F9+N($K9),$F9),Settings!$C$9,"M")/IF($E9="Monthly",1,IF($E9="Quarterly",3,IF($E9="Yearly",12,0))),1))))>=Settings!$C$9,EDATE(IF($J9="Yes",$F9+N($K9),$F9),IF($E9="Monthly",1,IF($E9="Quarterly",3,IF($E9="Yearly",12,0)))*(IF(IF($J9="Yes",$F9+N($K9),$F9)>=Settings!$C$9,0,CEILING(DATEDIF(IF($J9="Yes",$F9+N($K9),$F9),Settings!$C$9,"M")/IF($E9="Monthly",1,IF($E9="Quarterly",3,IF($E9="Yearly",12,0))),1)))),EDATE(IF($J9="Yes",$F9+N($K9),$F9),IF($E9="Monthly",1,IF($E9="Quarterly",3,IF($E9="Yearly",12,0)))*(IF(IF($J9="Yes",$F9+N($K9),$F9)>=Settings!$C$9,0,CEILING(DATEDIF(IF($J9="Yes",$F9+N($K9),$F9),Settings!$C$9,"M")/IF($E9="Monthly",1,IF($E9="Quarterly",3,IF($E9="Yearly",12,0))),1))+1))))) | O9: =IF(ISNUMBER($N9),$N9-Settings!$C$9,"") | P9: =IF(AND(AND($B9<>"",$D9>0),$J9="Yes",ISNUMBER($K9)),$F9+$K9-1,"") | Q9: =IF(ISNUMBER($P9),$P9-Settings!$C$9,"") | R9: =IF(NOT(AND($B9<>"",$D9>0)),"",IF(AND(ISNUMBER($Q9),$Q9<0,$I9<>"Yes"),"Trial ended",IF(AND(ISNUMBER($Q9),$Q9<=Settings!$C$8),"Cancel soon?",IF($I9="Yes","To cancel",IF(AND(ISNUMBER($O9),$O9<=Settings!$C$8),"Charge soon","OK"))))) | S9: =IF(ISNUMBER($O9),$O9+ROW()/1000,"") | T9: =IF(ISNUMBER($M9),$M9+ROW()/100000,"") | U9: =IF(AND(ISNUMBER($Q9),N($Q9)>=0,$I9<>"Yes"),$Q9+ROW()/1000,"")
B10: Sports streaming | C10: Streaming | D10: 9.99 | E10: Monthly | F10: 46289 | G10: Credit card | H10: Yes | I10: No | J10: Yes | K10: 7 | L10: =IF(NOT(AND($B10<>"",$D10>0)),"",IF($E10="Weekly",$D10*52/12,IF($E10="Quarterly",$D10/3,IF($E10="Yearly",$D10/12,$D10)))) | M10: =IF(ISNUMBER($L10),$L10*12,"") | N10: =IF(OR(NOT(AND($B10<>"",$D10>0)),$F10=""),"",IF($E10="Weekly",IF(IF($J10="Yes",$F10+N($K10),$F10)>=Settings!$C$9,IF($J10="Yes",$F10+N($K10),$F10),IF($J10="Yes",$F10+N($K10),$F10)+7*CEILING((Settings!$C$9-IF($J10="Yes",$F10+N($K10),$F10))/7,1)),IF(EDATE(IF($J10="Yes",$F10+N($K10),$F10),IF($E10="Monthly",1,IF($E10="Quarterly",3,IF($E10="Yearly",12,0)))*(IF(IF($J10="Yes",$F10+N($K10),$F10)>=Settings!$C$9,0,CEILING(DATEDIF(IF($J10="Yes",$F10+N($K10),$F10),Settings!$C$9,"M")/IF($E10="Monthly",1,IF($E10="Quarterly",3,IF($E10="Yearly",12,0))),1))))>=Settings!$C$9,EDATE(IF($J10="Yes",$F10+N($K10),$F10),IF($E10="Monthly",1,IF($E10="Quarterly",3,IF($E10="Yearly",12,0)))*(IF(IF($J10="Yes",$F10+N($K10),$F10)>=Settings!$C$9,0,CEILING(DATEDIF(IF($J10="Yes",$F10+N($K10),$F10),Settings!$C$9,"M")/IF($E10="Monthly",1,IF($E10="Quarterly",3,IF($E10="Yearly",12,0))),1)))),EDATE(IF($J10="Yes",$F10+N($K10),$F10),IF($E10="Monthly",1,IF($E10="Quarterly",3,IF($E10="Yearly",12,0)))*(IF(IF($J10="Yes",$F10+N($K10),$F10)>=Settings!$C$9,0,CEILING(DATEDIF(IF($J10="Yes",$F10+N($K10),$F10),Settings!$C$9,"M")/IF($E10="Monthly",1,IF($E10="Quarterly",3,IF($E10="Yearly",12,0))),1))+1))))) | O10: =IF(ISNUMBER($N10),$N10-Settings!$C$9,"") | P10: =IF(AND(AND($B10<>"",$D10>0),$J10="Yes",ISNUMBER($K10)),$F10+$K10-1,"") | Q10: =IF(ISNUMBER($P10),$P10-Settings!$C$9,"") | R10: =IF(NOT(AND($B10<>"",$D10>0)),"",IF(AND(ISNUMBER($Q10),$Q10<0,$I10<>"Yes"),"Trial ended",IF(AND(ISNUMBER($Q10),$Q10<=Settings!$C$8),"Cancel soon?",IF($I10="Yes","To cancel",IF(AND(ISNUMBER($O10),$O10<=Settings!$C$8),"Charge soon","OK"))))) | S10: =IF(ISNUMBER($O10),$O10+ROW()/1000,"") | T10: =IF(ISNUMBER($M10),$M10+ROW()/100000,"") | U10: =IF(AND(ISNUMBER($Q10),N($Q10)>=0,$I10<>"Yes"),$Q10+ROW()/1000,"")
B11: Gym membership | C11: Fitness | D11: 45 | E11: Monthly | F11: 45667 | G11: Debit card | H11: Yes | I11: Yes | J11: No | L11: =IF(NOT(AND($B11<>"",$D11>0)),"",IF($E11="Weekly",$D11*52/12,IF($E11="Quarterly",$D11/3,IF($E11="Yearly",$D11/12,$D11)))) | M11: =IF(ISNUMBER($L11),$L11*12,"") | N11: =IF(OR(NOT(AND($B11<>"",$D11>0)),$F11=""),"",IF($E11="Weekly",IF(IF($J11="Yes",$F11+N($K11),$F11)>=Settings!$C$9,IF($J11="Yes",$F11+N($K11),$F11),IF($J11="Yes",$F11+N($K11),$F11)+7*CEILING((Settings!$C$9-IF($J11="Yes",$F11+N($K11),$F11))/7,1)),IF(EDATE(IF($J11="Yes",$F11+N($K11),$F11),IF($E11="Monthly",1,IF($E11="Quarterly",3,IF($E11="Yearly",12,0)))*(IF(IF($J11="Yes",$F11+N($K11),$F11)>=Settings!$C$9,0,CEILING(DATEDIF(IF($J11="Yes",$F11+N($K11),$F11),Settings!$C$9,"M")/IF($E11="Monthly",1,IF($E11="Quarterly",3,IF($E11="Yearly",12,0))),1))))>=Settings!$C$9,EDATE(IF($J11="Yes",$F11+N($K11),$F11),IF($E11="Monthly",1,IF($E11="Quarterly",3,IF($E11="Yearly",12,0)))*(IF(IF($J11="Yes",$F11+N($K11),$F11)>=Settings!$C$9,0,CEILING(DATEDIF(IF($J11="Yes",$F11+N($K11),$F11),Settings!$C$9,"M")/IF($E11="Monthly",1,IF($E11="Quarterly",3,IF($E11="Yearly",12,0))),1)))),EDATE(IF($J11="Yes",$F11+N($K11),$F11),IF($E11="Monthly",1,IF($E11="Quarterly",3,IF($E11="Yearly",12,0)))*(IF(IF($J11="Yes",$F11+N($K11),$F11)>=Settings!$C$9,0,CEILING(DATEDIF(IF($J11="Yes",$F11+N($K11),$F11),Settings!$C$9,"M")/IF($E11="Monthly",1,IF($E11="Quarterly",3,IF($E11="Yearly",12,0))),1))+1))))) | O11: =IF(ISNUMBER($N11),$N11-Settings!$C$9,"") | P11: =IF(AND(AND($B11<>"",$D11>0),$J11="Yes",ISNUMBER($K11)),$F11+$K11-1,"") | Q11: =IF(ISNUMBER($P11),$P11-Settings!$C$9,"") | R11: =IF(NOT(AND($B11<>"",$D11>0)),"",IF(AND(ISNUMBER($Q11),$Q11<0,$I11<>"Yes"),"Trial ended",IF(AND(ISNUMBER($Q11),$Q11<=Settings!$C$8),"Cancel soon?",IF($I11="Yes","To cancel",IF(AND(ISNUMBER($O11),$O11<=Settings!$C$8),"Charge soon","OK"))))) | S11: =IF(ISNUMBER($O11),$O11+ROW()/1000,"") | T11: =IF(ISNUMBER($M11),$M11+ROW()/100000,"") | U11: =IF(AND(ISNUMBER($Q11),N($Q11)>=0,$I11<>"Yes"),$Q11+ROW()/1000,"")
B12: Yoga app | C12: Fitness | D12: 69.99 | E12: Yearly | F12: 46037 | G12: Apple Pay | H12: Yes | I12: No | J12: No | L12: =IF(NOT(AND($B12<>"",$D12>0)),"",IF($E12="Weekly",$D12*52/12,IF($E12="Quarterly",$D12/3,IF($E12="Yearly",$D12/12,$D12)))) | M12: =IF(ISNUMBER($L12),$L12*12,"") | N12: =IF(OR(NOT(AND($B12<>"",$D12>0)),$F12=""),"",IF($E12="Weekly",IF(IF($J12="Yes",$F12+N($K12),$F12)>=Settings!$C$9,IF($J12="Yes",$F12+N($K12),$F12),IF($J12="Yes",$F12+N($K12),$F12)+7*CEILING((Settings!$C$9-IF($J12="Yes",$F12+N($K12),$F12))/7,1)),IF(EDATE(IF($J12="Yes",$F12+N($K12),$F12),IF($E12="Monthly",1,IF($E12="Quarterly",3,IF($E12="Yearly",12,0)))*(IF(IF($J12="Yes",$F12+N($K12),$F12)>=Settings!$C$9,0,CEILING(DATEDIF(IF($J12="Yes",$F12+N($K12),$F12),Settings!$C$9,"M")/IF($E12="Monthly",1,IF($E12="Quarterly",3,IF($E12="Yearly",12,0))),1))))>=Settings!$C$9,EDATE(IF($J12="Yes",$F12+N($K12),$F12),IF($E12="Monthly",1,IF($E12="Quarterly",3,IF($E12="Yearly",12,0)))*(IF(IF($J12="Yes",$F12+N($K12),$F12)>=Settings!$C$9,0,CEILING(DATEDIF(IF($J12="Yes",$F12+N($K12),$F12),Settings!$C$9,"M")/IF($E12="Monthly",1,IF($E12="Quarterly",3,IF($E12="Yearly",12,0))),1)))),EDATE(IF($J12="Yes",$F12+N($K12),$F12),IF($E12="Monthly",1,IF($E12="Quarterly",3,IF($E12="Yearly",12,0)))*(IF(IF($J12="Yes",$F12+N($K12),$F12)>=Settings!$C$9,0,CEILING(DATEDIF(IF($J12="Yes",$F12+N($K12),$F12),Settings!$C$9,"M")/IF($E12="Monthly",1,IF($E12="Quarterly",3,IF($E12="Yearly",12,0))),1))+1))))) | O12: =IF(ISNUMBER($N12),$N12-Settings!$C$9,"") | P12: =IF(AND(AND($B12<>"",$D12>0),$J12="Yes",ISNUMBER($K12)),$F12+$K12-1,"") | Q12: =IF(ISNUMBER($P12),$P12-Settings!$C$9,"") | R12: =IF(NOT(AND($B12<>"",$D12>0)),"",IF(AND(ISNUMBER($Q12),$Q12<0,$I12<>"Yes"),"Trial ended",IF(AND(ISNUMBER($Q12),$Q12<=Settings!$C$8),"Cancel soon?",IF($I12="Yes","To cancel",IF(AND(ISNUMBER($O12),$O12<=Settings!$C$8),"Charge soon","OK"))))) | S12: =IF(ISNUMBER($O12),$O12+ROW()/1000,"") | T12: =IF(ISNUMBER($M12),$M12+ROW()/100000,"") | U12: =IF(AND(ISNUMBER($Q12),N($Q12)>=0,$I12<>"Yes"),$Q12+ROW()/1000,"")
B13: Photo editing app | C13: Software | D13: 22.99 | E13: Monthly | F13: 46067 | G13: Credit card | H13: Yes | I13: No | J13: No | L13: =IF(NOT(AND($B13<>"",$D13>0)),"",IF($E13="Weekly",$D13*52/12,IF($E13="Quarterly",$D13/3,IF($E13="Yearly",$D13/12,$D13)))) | M13: =IF(ISNUMBER($L13),$L13*12,"") | N13: =IF(OR(NOT(AND($B13<>"",$D13>0)),$F13=""),"",IF($E13="Weekly",IF(IF($J13="Yes",$F13+N($K13),$F13)>=Settings!$C$9,IF($J13="Yes",$F13+N($K13),$F13),IF($J13="Yes",$F13+N($K13),$F13)+7*CEILING((Settings!$C$9-IF($J13="Yes",$F13+N($K13),$F13))/7,1)),IF(EDATE(IF($J13="Yes",$F13+N($K13),$F13),IF($E13="Monthly",1,IF($E13="Quarterly",3,IF($E13="Yearly",12,0)))*(IF(IF($J13="Yes",$F13+N($K13),$F13)>=Settings!$C$9,0,CEILING(DATEDIF(IF($J13="Yes",$F13+N($K13),$F13),Settings!$C$9,"M")/IF($E13="Monthly",1,IF($E13="Quarterly",3,IF($E13="Yearly",12,0))),1))))>=Settings!$C$9,EDATE(IF($J13="Yes",$F13+N($K13),$F13),IF($E13="Monthly",1,IF($E13="Quarterly",3,IF($E13="Yearly",12,0)))*(IF(IF($J13="Yes",$F13+N($K13),$F13)>=Settings!$C$9,0,CEILING(DATEDIF(IF($J13="Yes",$F13+N($K13),$F13),Settings!$C$9,"M")/IF($E13="Monthly",1,IF($E13="Quarterly",3,IF($E13="Yearly",12,0))),1)))),EDATE(IF($J13="Yes",$F13+N($K13),$F13),IF($E13="Monthly",1,IF($E13="Quarterly",3,IF($E13="Yearly",12,0)))*(IF(IF($J13="Yes",$F13+N($K13),$F13)>=Settings!$C$9,0,CEILING(DATEDIF(IF($J13="Yes",$F13+N($K13),$F13),Settings!$C$9,"M")/IF($E13="Monthly",1,IF($E13="Quarterly",3,IF($E13="Yearly",12,0))),1))+1))))) | O13: =IF(ISNUMBER($N13),$N13-Settings!$C$9,"") | P13: =IF(AND(AND($B13<>"",$D13>0),$J13="Yes",ISNUMBER($K13)),$F13+$K13-1,"") | Q13: =IF(ISNUMBER($P13),$P13-Settings!$C$9,"") | R13: =IF(NOT(AND($B13<>"",$D13>0)),"",IF(AND(ISNUMBER($Q13),$Q13<0,$I13<>"Yes"),"Trial ended",IF(AND(ISNUMBER($Q13),$Q13<=Settings!$C$8),"Cancel soon?",IF($I13="Yes","To cancel",IF(AND(ISNUMBER($O13),$O13<=Settings!$C$8),"Charge soon","OK"))))) | S13: =IF(ISNUMBER($O13),$O13+ROW()/1000,"") | T13: =IF(ISNUMBER($M13),$M13+ROW()/100000,"") | U13: =IF(AND(ISNUMBER($Q13),N($Q13)>=0,$I13<>"Yes"),$Q13+ROW()/1000,"")
B14: AI assistant | C14: Software | D14: 20 | E14: Monthly | F14: 45903 | G14: Credit card | H14: Yes | I14: No | J14: No | L14: =IF(NOT(AND($B14<>"",$D14>0)),"",IF($E14="Weekly",$D14*52/12,IF($E14="Quarterly",$D14/3,IF($E14="Yearly",$D14/12,$D14)))) | M14: =IF(ISNUMBER($L14),$L14*12,"") | N14: =IF(OR(NOT(AND($B14<>"",$D14>0)),$F14=""),"",IF($E14="Weekly",IF(IF($J14="Yes",$F14+N($K14),$F14)>=Settings!$C$9,IF($J14="Yes",$F14+N($K14),$F14),IF($J14="Yes",$F14+N($K14),$F14)+7*CEILING((Settings!$C$9-IF($J14="Yes",$F14+N($K14),$F14))/7,1)),IF(EDATE(IF($J14="Yes",$F14+N($K14),$F14),IF($E14="Monthly",1,IF($E14="Quarterly",3,IF($E14="Yearly",12,0)))*(IF(IF($J14="Yes",$F14+N($K14),$F14)>=Settings!$C$9,0,CEILING(DATEDIF(IF($J14="Yes",$F14+N($K14),$F14),Settings!$C$9,"M")/IF($E14="Monthly",1,IF($E14="Quarterly",3,IF($E14="Yearly",12,0))),1))))>=Settings!$C$9,EDATE(IF($J14="Yes",$F14+N($K14),$F14),IF($E14="Monthly",1,IF($E14="Quarterly",3,IF($E14="Yearly",12,0)))*(IF(IF($J14="Yes",$F14+N($K14),$F14)>=Settings!$C$9,0,CEILING(DATEDIF(IF($J14="Yes",$F14+N($K14),$F14),Settings!$C$9,"M")/IF($E14="Monthly",1,IF($E14="Quarterly",3,IF($E14="Yearly",12,0))),1)))),EDATE(IF($J14="Yes",$F14+N($K14),$F14),IF($E14="Monthly",1,IF($E14="Quarterly",3,IF($E14="Yearly",12,0)))*(IF(IF($J14="Yes",$F14+N($K14),$F14)>=Settings!$C$9,0,CEILING(DATEDIF(IF($J14="Yes",$F14+N($K14),$F14),Settings!$C$9,"M")/IF($E14="Monthly",1,IF($E14="Quarterly",3,IF($E14="Yearly",12,0))),1))+1))))) | O14: =IF(ISNUMBER($N14),$N14-Settings!$C$9,"") | P14: =IF(AND(AND($B14<>"",$D14>0),$J14="Yes",ISNUMBER($K14)),$F14+$K14-1,"") | Q14: =IF(ISNUMBER($P14),$P14-Settings!$C$9,"") | R14: =IF(NOT(AND($B14<>"",$D14>0)),"",IF(AND(ISNUMBER($Q14),$Q14<0,$I14<>"Yes"),"Trial ended",IF(AND(ISNUMBER($Q14),$Q14<=Settings!$C$8),"Cancel soon?",IF($I14="Yes","To cancel",IF(AND(ISNUMBER($O14),$O14<=Settings!$C$8),"Charge soon","OK"))))) | S14: =IF(ISNUMBER($O14),$O14+ROW()/1000,"") | T14: =IF(ISNUMBER($M14),$M14+ROW()/100000,"") | U14: =IF(AND(ISNUMBER($Q14),N($Q14)>=0,$I14<>"Yes"),$Q14+ROW()/1000,"")
B15: Password manager | C15: Software | D15: 35.88 | E15: Yearly | F15: 45992 | G15: Credit card | H15: Yes | I15: No | J15: No | L15: =IF(NOT(AND($B15<>"",$D15>0)),"",IF($E15="Weekly",$D15*52/12,IF($E15="Quarterly",$D15/3,IF($E15="Yearly",$D15/12,$D15)))) | M15: =IF(ISNUMBER($L15),$L15*12,"") | N15: =IF(OR(NOT(AND($B15<>"",$D15>0)),$F15=""),"",IF($E15="Weekly",IF(IF($J15="Yes",$F15+N($K15),$F15)>=Settings!$C$9,IF($J15="Yes",$F15+N($K15),$F15),IF($J15="Yes",$F15+N($K15),$F15)+7*CEILING((Settings!$C$9-IF($J15="Yes",$F15+N($K15),$F15))/7,1)),IF(EDATE(IF($J15="Yes",$F15+N($K15),$F15),IF($E15="Monthly",1,IF($E15="Quarterly",3,IF($E15="Yearly",12,0)))*(IF(IF($J15="Yes",$F15+N($K15),$F15)>=Settings!$C$9,0,CEILING(DATEDIF(IF($J15="Yes",$F15+N($K15),$F15),Settings!$C$9,"M")/IF($E15="Monthly",1,IF($E15="Quarterly",3,IF($E15="Yearly",12,0))),1))))>=Settings!$C$9,EDATE(IF($J15="Yes",$F15+N($K15),$F15),IF($E15="Monthly",1,IF($E15="Quarterly",3,IF($E15="Yearly",12,0)))*(IF(IF($J15="Yes",$F15+N($K15),$F15)>=Settings!$C$9,0,CEILING(DATEDIF(IF($J15="Yes",$F15+N($K15),$F15),Settings!$C$9,"M")/IF($E15="Monthly",1,IF($E15="Quarterly",3,IF($E15="Yearly",12,0))),1)))),EDATE(IF($J15="Yes",$F15+N($K15),$F15),IF($E15="Monthly",1,IF($E15="Quarterly",3,IF($E15="Yearly",12,0)))*(IF(IF($J15="Yes",$F15+N($K15),$F15)>=Settings!$C$9,0,CEILING(DATEDIF(IF($J15="Yes",$F15+N($K15),$F15),Settings!$C$9,"M")/IF($E15="Monthly",1,IF($E15="Quarterly",3,IF($E15="Yearly",12,0))),1))+1))))) | O15: =IF(ISNUMBER($N15),$N15-Settings!$C$9,"") | P15: =IF(AND(AND($B15<>"",$D15>0),$J15="Yes",ISNUMBER($K15)),$F15+$K15-1,"") | Q15: =IF(ISNUMBER($P15),$P15-Settings!$C$9,"") | R15: =IF(NOT(AND($B15<>"",$D15>0)),"",IF(AND(ISNUMBER($Q15),$Q15<0,$I15<>"Yes"),"Trial ended",IF(AND(ISNUMBER($Q15),$Q15<=Settings!$C$8),"Cancel soon?",IF($I15="Yes","To cancel",IF(AND(ISNUMBER($O15),$O15<=Settings!$C$8),"Charge soon","OK"))))) | S15: =IF(ISNUMBER($O15),$O15+ROW()/1000,"") | T15: =IF(ISNUMBER($M15),$M15+ROW()/100000,"") | U15: =IF(AND(ISNUMBER($Q15),N($Q15)>=0,$I15<>"Yes"),$Q15+ROW()/1000,"")
B16: VPN | C16: Software | D16: 59.88 | E16: Yearly | F16: 46073 | G16: PayPal | H16: Yes | I16: No | J16: No | L16: =IF(NOT(AND($B16<>"",$D16>0)),"",IF($E16="Weekly",$D16*52/12,IF($E16="Quarterly",$D16/3,IF($E16="Yearly",$D16/12,$D16)))) | M16: =IF(ISNUMBER($L16),$L16*12,"") | N16: =IF(OR(NOT(AND($B16<>"",$D16>0)),$F16=""),"",IF($E16="Weekly",IF(IF($J16="Yes",$F16+N($K16),$F16)>=Settings!$C$9,IF($J16="Yes",$F16+N($K16),$F16),IF($J16="Yes",$F16+N($K16),$F16)+7*CEILING((Settings!$C$9-IF($J16="Yes",$F16+N($K16),$F16))/7,1)),IF(EDATE(IF($J16="Yes",$F16+N($K16),$F16),IF($E16="Monthly",1,IF($E16="Quarterly",3,IF($E16="Yearly",12,0)))*(IF(IF($J16="Yes",$F16+N($K16),$F16)>=Settings!$C$9,0,CEILING(DATEDIF(IF($J16="Yes",$F16+N($K16),$F16),Settings!$C$9,"M")/IF($E16="Monthly",1,IF($E16="Quarterly",3,IF($E16="Yearly",12,0))),1))))>=Settings!$C$9,EDATE(IF($J16="Yes",$F16+N($K16),$F16),IF($E16="Monthly",1,IF($E16="Quarterly",3,IF($E16="Yearly",12,0)))*(IF(IF($J16="Yes",$F16+N($K16),$F16)>=Settings!$C$9,0,CEILING(DATEDIF(IF($J16="Yes",$F16+N($K16),$F16),Settings!$C$9,"M")/IF($E16="Monthly",1,IF($E16="Quarterly",3,IF($E16="Yearly",12,0))),1)))),EDATE(IF($J16="Yes",$F16+N($K16),$F16),IF($E16="Monthly",1,IF($E16="Quarterly",3,IF($E16="Yearly",12,0)))*(IF(IF($J16="Yes",$F16+N($K16),$F16)>=Settings!$C$9,0,CEILING(DATEDIF(IF($J16="Yes",$F16+N($K16),$F16),Settings!$C$9,"M")/IF($E16="Monthly",1,IF($E16="Quarterly",3,IF($E16="Yearly",12,0))),1))+1))))) | O16: =IF(ISNUMBER($N16),$N16-Settings!$C$9,"") | P16: =IF(AND(AND($B16<>"",$D16>0),$J16="Yes",ISNUMBER($K16)),$F16+$K16-1,"") | Q16: =IF(ISNUMBER($P16),$P16-Settings!$C$9,"") | R16: =IF(NOT(AND($B16<>"",$D16>0)),"",IF(AND(ISNUMBER($Q16),$Q16<0,$I16<>"Yes"),"Trial ended",IF(AND(ISNUMBER($Q16),$Q16<=Settings!$C$8),"Cancel soon?",IF($I16="Yes","To cancel",IF(AND(ISNUMBER($O16),$O16<=Settings!$C$8),"Charge soon","OK"))))) | S16: =IF(ISNUMBER($O16),$O16+ROW()/1000,"") | T16: =IF(ISNUMBER($M16),$M16+ROW()/100000,"") | U16: =IF(AND(ISNUMBER($Q16),N($Q16)>=0,$I16<>"Yes"),$Q16+ROW()/1000,"")
B17: Online shopping club | C17: Shopping | D17: 139 | E17: Yearly | F17: 45932 | G17: Credit card | H17: Yes | I17: No | J17: No | L17: =IF(NOT(AND($B17<>"",$D17>0)),"",IF($E17="Weekly",$D17*52/12,IF($E17="Quarterly",$D17/3,IF($E17="Yearly",$D17/12,$D17)))) | M17: =IF(ISNUMBER($L17),$L17*12,"") | N17: =IF(OR(NOT(AND($B17<>"",$D17>0)),$F17=""),"",IF($E17="Weekly",IF(IF($J17="Yes",$F17+N($K17),$F17)>=Settings!$C$9,IF($J17="Yes",$F17+N($K17),$F17),IF($J17="Yes",$F17+N($K17),$F17)+7*CEILING((Settings!$C$9-IF($J17="Yes",$F17+N($K17),$F17))/7,1)),IF(EDATE(IF($J17="Yes",$F17+N($K17),$F17),IF($E17="Monthly",1,IF($E17="Quarterly",3,IF($E17="Yearly",12,0)))*(IF(IF($J17="Yes",$F17+N($K17),$F17)>=Settings!$C$9,0,CEILING(DATEDIF(IF($J17="Yes",$F17+N($K17),$F17),Settings!$C$9,"M")/IF($E17="Monthly",1,IF($E17="Quarterly",3,IF($E17="Yearly",12,0))),1))))>=Settings!$C$9,EDATE(IF($J17="Yes",$F17+N($K17),$F17),IF($E17="Monthly",1,IF($E17="Quarterly",3,IF($E17="Yearly",12,0)))*(IF(IF($J17="Yes",$F17+N($K17),$F17)>=Settings!$C$9,0,CEILING(DATEDIF(IF($J17="Yes",$F17+N($K17),$F17),Settings!$C$9,"M")/IF($E17="Monthly",1,IF($E17="Quarterly",3,IF($E17="Yearly",12,0))),1)))),EDATE(IF($J17="Yes",$F17+N($K17),$F17),IF($E17="Monthly",1,IF($E17="Quarterly",3,IF($E17="Yearly",12,0)))*(IF(IF($J17="Yes",$F17+N($K17),$F17)>=Settings!$C$9,0,CEILING(DATEDIF(IF($J17="Yes",$F17+N($K17),$F17),Settings!$C$9,"M")/IF($E17="Monthly",1,IF($E17="Quarterly",3,IF($E17="Yearly",12,0))),1))+1))))) | O17: =IF(ISNUMBER($N17),$N17-Settings!$C$9,"") | P17: =IF(AND(AND($B17<>"",$D17>0),$J17="Yes",ISNUMBER($K17)),$F17+$K17-1,"") | Q17: =IF(ISNUMBER($P17),$P17-Settings!$C$9,"") | R17: =IF(NOT(AND($B17<>"",$D17>0)),"",IF(AND(ISNUMBER($Q17),$Q17<0,$I17<>"Yes"),"Trial ended",IF(AND(ISNUMBER($Q17),$Q17<=Settings!$C$8),"Cancel soon?",IF($I17="Yes","To cancel",IF(AND(ISNUMBER($O17),$O17<=Settings!$C$8),"Charge soon","OK"))))) | S17: =IF(ISNUMBER($O17),$O17+ROW()/1000,"") | T17: =IF(ISNUMBER($M17),$M17+ROW()/100000,"") | U17: =IF(AND(ISNUMBER($Q17),N($Q17)>=0,$I17<>"Yes"),$Q17+ROW()/1000,"")
B18: Beauty box | C18: Shopping | D18: 28 | E18: Monthly | F18: 45856 | G18: Debit card | H18: Yes | I18: Yes | J18: No | L18: =IF(NOT(AND($B18<>"",$D18>0)),"",IF($E18="Weekly",$D18*52/12,IF($E18="Quarterly",$D18/3,IF($E18="Yearly",$D18/12,$D18)))) | M18: =IF(ISNUMBER($L18),$L18*12,"") | N18: =IF(OR(NOT(AND($B18<>"",$D18>0)),$F18=""),"",IF($E18="Weekly",IF(IF($J18="Yes",$F18+N($K18),$F18)>=Settings!$C$9,IF($J18="Yes",$F18+N($K18),$F18),IF($J18="Yes",$F18+N($K18),$F18)+7*CEILING((Settings!$C$9-IF($J18="Yes",$F18+N($K18),$F18))/7,1)),IF(EDATE(IF($J18="Yes",$F18+N($K18),$F18),IF($E18="Monthly",1,IF($E18="Quarterly",3,IF($E18="Yearly",12,0)))*(IF(IF($J18="Yes",$F18+N($K18),$F18)>=Settings!$C$9,0,CEILING(DATEDIF(IF($J18="Yes",$F18+N($K18),$F18),Settings!$C$9,"M")/IF($E18="Monthly",1,IF($E18="Quarterly",3,IF($E18="Yearly",12,0))),1))))>=Settings!$C$9,EDATE(IF($J18="Yes",$F18+N($K18),$F18),IF($E18="Monthly",1,IF($E18="Quarterly",3,IF($E18="Yearly",12,0)))*(IF(IF($J18="Yes",$F18+N($K18),$F18)>=Settings!$C$9,0,CEILING(DATEDIF(IF($J18="Yes",$F18+N($K18),$F18),Settings!$C$9,"M")/IF($E18="Monthly",1,IF($E18="Quarterly",3,IF($E18="Yearly",12,0))),1)))),EDATE(IF($J18="Yes",$F18+N($K18),$F18),IF($E18="Monthly",1,IF($E18="Quarterly",3,IF($E18="Yearly",12,0)))*(IF(IF($J18="Yes",$F18+N($K18),$F18)>=Settings!$C$9,0,CEILING(DATEDIF(IF($J18="Yes",$F18+N($K18),$F18),Settings!$C$9,"M")/IF($E18="Monthly",1,IF($E18="Quarterly",3,IF($E18="Yearly",12,0))),1))+1))))) | O18: =IF(ISNUMBER($N18),$N18-Settings!$C$9,"") | P18: =IF(AND(AND($B18<>"",$D18>0),$J18="Yes",ISNUMBER($K18)),$F18+$K18-1,"") | Q18: =IF(ISNUMBER($P18),$P18-Settings!$C$9,"") | R18: =IF(NOT(AND($B18<>"",$D18>0)),"",IF(AND(ISNUMBER($Q18),$Q18<0,$I18<>"Yes"),"Trial ended",IF(AND(ISNUMBER($Q18),$Q18<=Settings!$C$8),"Cancel soon?",IF($I18="Yes","To cancel",IF(AND(ISNUMBER($O18),$O18<=Settings!$C$8),"Charge soon","OK"))))) | S18: =IF(ISNUMBER($O18),$O18+ROW()/1000,"") | T18: =IF(ISNUMBER($M18),$M18+ROW()/100000,"") | U18: =IF(AND(ISNUMBER($Q18),N($Q18)>=0,$I18<>"Yes"),$Q18+ROW()/1000,"")
B19: Cloud storage | C19: Cloud | D19: 2.99 | E19: Monthly | F19: 45809 | G19: Apple Pay | H19: Yes | I19: No | J19: No | L19: =IF(NOT(AND($B19<>"",$D19>0)),"",IF($E19="Weekly",$D19*52/12,IF($E19="Quarterly",$D19/3,IF($E19="Yearly",$D19/12,$D19)))) | M19: =IF(ISNUMBER($L19),$L19*12,"") | N19: =IF(OR(NOT(AND($B19<>"",$D19>0)),$F19=""),"",IF($E19="Weekly",IF(IF($J19="Yes",$F19+N($K19),$F19)>=Settings!$C$9,IF($J19="Yes",$F19+N($K19),$F19),IF($J19="Yes",$F19+N($K19),$F19)+7*CEILING((Settings!$C$9-IF($J19="Yes",$F19+N($K19),$F19))/7,1)),IF(EDATE(IF($J19="Yes",$F19+N($K19),$F19),IF($E19="Monthly",1,IF($E19="Quarterly",3,IF($E19="Yearly",12,0)))*(IF(IF($J19="Yes",$F19+N($K19),$F19)>=Settings!$C$9,0,CEILING(DATEDIF(IF($J19="Yes",$F19+N($K19),$F19),Settings!$C$9,"M")/IF($E19="Monthly",1,IF($E19="Quarterly",3,IF($E19="Yearly",12,0))),1))))>=Settings!$C$9,EDATE(IF($J19="Yes",$F19+N($K19),$F19),IF($E19="Monthly",1,IF($E19="Quarterly",3,IF($E19="Yearly",12,0)))*(IF(IF($J19="Yes",$F19+N($K19),$F19)>=Settings!$C$9,0,CEILING(DATEDIF(IF($J19="Yes",$F19+N($K19),$F19),Settings!$C$9,"M")/IF($E19="Monthly",1,IF($E19="Quarterly",3,IF($E19="Yearly",12,0))),1)))),EDATE(IF($J19="Yes",$F19+N($K19),$F19),IF($E19="Monthly",1,IF($E19="Quarterly",3,IF($E19="Yearly",12,0)))*(IF(IF($J19="Yes",$F19+N($K19),$F19)>=Settings!$C$9,0,CEILING(DATEDIF(IF($J19="Yes",$F19+N($K19),$F19),Settings!$C$9,"M")/IF($E19="Monthly",1,IF($E19="Quarterly",3,IF($E19="Yearly",12,0))),1))+1))))) | O19: =IF(ISNUMBER($N19),$N19-Settings!$C$9,"") | P19: =IF(AND(AND($B19<>"",$D19>0),$J19="Yes",ISNUMBER($K19)),$F19+$K19-1,"") | Q19: =IF(ISNUMBER($P19),$P19-Settings!$C$9,"") | R19: =IF(NOT(AND($B19<>"",$D19>0)),"",IF(AND(ISNUMBER($Q19),$Q19<0,$I19<>"Yes"),"Trial ended",IF(AND(ISNUMBER($Q19),$Q19<=Settings!$C$8),"Cancel soon?",IF($I19="Yes","To cancel",IF(AND(ISNUMBER($O19),$O19<=Settings!$C$8),"Charge soon","OK"))))) | S19: =IF(ISNUMBER($O19),$O19+ROW()/1000,"") | T19: =IF(ISNUMBER($M19),$M19+ROW()/100000,"") | U19: =IF(AND(ISNUMBER($Q19),N($Q19)>=0,$I19<>"Yes"),$Q19+ROW()/1000,"")
