Workbook

Sheet Start Here
B2: Start here
B3: 10 minutes to set up. Works with any currency.
B5: 1. My Debts: one row per debt. Fill the blue columns. Only Name, Balance, APR and Minimum payment are needed.
B6: • Optional columns can stay blank: blank = no fee, no lock, no promo, not behind. The maths still works.
B7: • Early payoff rule: if your contract charges a fee for paying early, pick 'Allowed with a fee' and enter the fee and when it ends.
B8: The sheet compares the fee with the interest you'd save. If the fee costs more, extra payments wait until the fee ends.
B9: • Locked until a date: no extra goes in until that date (minimums still get paid).
B10: • Not sure: minimums only, until you ask your lender and change the rule.
B11: • 0% / promo deals: enter the promo end date and the APR after it. Deferred interest = Yes if back-interest is added when you don't clear it in time.
B12: 2. Plan: enter how much you can put toward all debts each month, the start month, and any one-time extra.
B13: 3. Plan: pick a payoff order and compare all four. Smart is CheckMaybe's default:
B14: behind-on-payments first → deferred-interest deadlines → highest APR (or, if minimums take 35%+ of income, the debt that frees up the most monthly money).
... B21: Example rows are made up. Replace or clear them.

Sheet Plan
B2: Debt Payoff Planner
B3: Set your budget here, list your debts on My Debts. Blue headers = you fill in.
B4: SETTING | C4: VALUE | H4: YOUR CHOSEN ORDER
B5: Money for debts each month | C5: 1500 | D5: Total you can put toward ALL debts each month, minimums included. | H5: DEBT-FREE | I5: =INDEX(C15:F15,Plan!$K$5) | K5: =MATCH($C$9,{"Smart (CheckMaybe order)","Avalanche (highest APR first)","Snowball (smallest balance first)","Cash-flow (free up monthly money first)"},0)
B6: Plan starts | C6: 46327 | D6: First month of the plan. Use the 1st of the month. | H6: MONTHS TO GO | I6: =INDEX(C16:F16,Plan!$K$5) | K6: =SUMPRODUCT(('My Debts'!$D$7:$D$18>0)*N(+'My Debts'!$F$7:$F$18))
B7: One-time extra (optional) | C7: 0 | D7: A bonus, tax refund or savings you'll throw at debt once. Leave 0 if none. | H7: INTEREST YOU'LL PAY | I7: =INDEX(C17:F17,Plan!$K$5) | K7: =AND(N($C$10)>0,$K$6/MAX(1,N($C$10))>=0.35)
B8: …in plan month # | C8: 1 | D8: Which month the one-time extra goes in (1 = first month). | H8: EARLY-PAYOFF FEES | I8: =INDEX(C18:F18,Plan!$K$5) | K8: =COUNTIFS('My Debts'!$D$7:$D$18,">0")
B9: Payoff order | C9: Smart (CheckMaybe order) | D9: Smart is the default. Compare all four on the right. | H9: MINIMUMS ONLY: INTEREST | I9: =IF(COUNT('My Debts'!$P$7:$P$18)=0,"",SUM('My Debts'!$P$7:$P$18))
B10: Monthly take-home income (optional) | C10: 3800 | D10: Used only to spot money pressure: if minimums take 35%+ of income, Smart frees up monthly money first. | H10: YOU SAVE VS MINIMUMS ONLY | I10: =IF(OR(I9="",NOT(ISNUMBER(I7))),"",MAX(0,I9-I7-I8))
H11: Minimums-only ignores debts that minimums never clear.
B13: COMPARE THE FOUR ORDERS | H13: TOTAL LEFT, FIRST 10 YEARS
C14: SMART | D14: AVALANCHE | E14: SNOWBALL | F14: CASH-FLOW
B15: Debt-free | C15: ='Calc Smart'!$B$5 | D15: ='Calc Avalanche'!$B$5 | E15: ='Calc Snowball'!$B$5 | F15: ='Calc Cashflow'!$B$5
B16: Months to debt-free | C16: ='Calc Smart'!$B$6 | D16: ='Calc Avalanche'!$B$6 | E16: ='Calc Snowball'!$B$6 | F16: ='Calc Cashflow'!$B$6
B17: Total interest | C17: ='Calc Smart'!$B$7 | D17: ='Calc Avalanche'!$B$7 | E17: ='Calc Snowball'!$B$7 | F17: ='Calc Cashflow'!$B$7
B18: Early-payoff fees paid | C18: ='Calc Smart'!$B$8 | D18: ='Calc Avalanche'!$B$8 | E18: ='Calc Snowball'!$B$8 | F18: ='Calc Cashflow'!$B$8
B19: Interest + fees | C19: ='Calc Smart'!$B$7+'Calc Smart'!$B$8 | D19: ='Calc Avalanche'!$B$7+'Calc Avalanche'!$B$8 | E19: ='Calc Snowball'!$B$7+'Calc Snowball'!$B$8 | F19: ='Calc Cashflow'!$B$7+'Calc Cashflow'!$B$8
B20: First debt cleared | C20: ='Calc Smart'!$B$9 | D20: ='Calc Avalanche'!$B$9 | E20: ='Calc Snowball'!$B$9 | F20: ='Calc Cashflow'!$B$9
B21: Green = best in that row. If a month shows "-", that plan doesn't finish within 30 years: raise the monthly amount.
B23: CHECKS
B24: =IF(Plan!$C$5<Plan!$K$6,"⚠ Your monthly amount is less than your minimum payments ("&TEXT(Plan!$K$6,"#,##0")&"). The plan assumes you still pay every minimum.","✓ Monthly amount covers all minimums ("&TEXT(Plan!$K$6,"#,##0")&"). Extra each month: "&TEXT(Plan!$C$5-Plan!$K$6,"#,##0"))
B25: =IF(COUNTIF('My Debts'!$Q$7:$Q$18,"Minimum doesn't cover interest*")>0,"⚠ At least one minimum payment doesn't cover its interest: that debt grows unless you pay more.","✓ Every minimum payment covers its interest.")
B26: =IF(COUNTIF('My Debts'!$Q$7:$Q$18,"Ask your lender*")+COUNTIF('My Debts'!$Q$7:$Q$18,"Locked*")+COUNTIF('My Debts'!$Q$7:$Q$18,"Wait*")>0,"ℹ Some debts get minimums only until they unlock (see My Debts › Early payoff check).","✓ No locked or uncertain debts.")
B27: =IF(Plan!$K$7,"ℹ Minimums take 35%+ of your income: Smart frees up monthly money first, then switches to highest APR.","ℹ Smart: behind-on-payments first, then 0%-promo deadlines, then highest APR.")
B28: =IF(COUNTIF('My Debts'!$AE$7:$AE$18,TRUE)>0,"⚠ A deferred-interest debt is cleared after its promo ends in this order: back-interest would be added (not in these totals). Smart avoids this when it can.","✓ No deferred-interest deadline missed in this order.")
B29: YOUR PAYOFF ORDER (CHOSEN)
B30: # | C30: DEBT | D30: BALANCE | E30: APR | F30: PAID OFF | G30: WHY / NOTE
B31: =IF(1<=Plan!$K$8,1,"") | C31: =IFERROR(INDEX('My Debts'!$B$7:$B$18,MATCH(1,'My Debts'!$S$7:$S$18,0)),"") | D31: =IFERROR(INDEX('My Debts'!$D$7:$D$18,MATCH(1,'My Debts'!$S$7:$S$18,0)),"") | E31: =IFERROR(INDEX('My Debts'!$E$7:$E$18,MATCH(1,'My Debts'!$S$7:$S$18,0)),"") | F31: =IFERROR(INDEX('My Debts'!$T$7:$T$18,MATCH(1,'My Debts'!$S$7:$S$18,0)),"") | G31: =IFERROR(INDEX('My Debts'!$V$7:$V$18,MATCH(1,'My Debts'!$S$7:$S$18,0)),"")
B32: =IF(2<=Plan!$K$8,2,"") | C32: =IFERROR(INDEX('My Debts'!$B$7:$B$18,MATCH(2,'My Debts'!$S$7:$S$18,0)),"") | D32: =IFERROR(INDEX('My Debts'!$D$7:$D$18,MATCH(2,'My Debts'!$S$7:$S$18,0)),"") | E32: =IFERROR(INDEX('My Debts'!$E$7:$E$18,MATCH(2,'My Debts'!$S$7:$S$18,0)),"") | F32: =IFERROR(INDEX('My Debts'!$T$7:$T$18,MATCH(2,'My Debts'!$S$7:$S$18,0)),"") | G32: =IFERROR(INDEX('My Debts'!$V$7:$V$18,MATCH(2,'My Debts'!$S$7:$S$18,0)),"")
B33: =IF(3<=Plan!$K$8,3,"") | C33: =IFERROR(INDEX('My Debts'!$B$7:$B$18,MATCH(3,'My Debts'!$S$7:$S$18,0)),"") | D33: =IFERROR(INDEX('My Debts'!$D$7:$D$18,MATCH(3,'My Debts'!$S$7:$S$18,0)),"") | E33: =IFERROR(INDEX('My Debts'!$E$7:$E$18,MATCH(3,'My Debts'!$S$7:$S$18,0)),"") | F33: =IFERROR(INDEX('My Debts'!$T$7:$T$18,MATCH(3,'My Debts'!$S$7:$S$18,0)),"") | G33: =IFERROR(INDEX('My Debts'!$V$7:$V$18,MATCH(3,'My Debts'!$S$7:$S$18,0)),"")
B34: =IF(4<=Plan!$K$8,4,"") | C34: =IFERROR(INDEX('My Debts'!$B$7:$B$18,MATCH(4,'My Debts'!$S$7:$S$18,0)),"") | D34: =IFERROR(INDEX('My Debts'!$D$7:$D$18,MATCH(4,'My Debts'!$S$7:$S$18,0)),"") | E34: =IFERROR(INDEX('My Debts'!$E$7:$E$18,MATCH(4,'My Debts'!$S$7:$S$18,0)),"") | F34: =IFERROR(INDEX('My Debts'!$T$7:$T$18,MATCH(4,'My Debts'!$S$7:$S$18,0)),"") | G34: =IFERROR(INDEX('My Debts'!$V$7:$V$18,MATCH(4,'My Debts'!$S$7:$S$18,0)),"")
B35: =IF(5<=Plan!$K$8,5,"") | C35: =IFERROR(INDEX('My Debts'!$B$7:$B$18,MATCH(5,'My Debts'!$S$7:$S$18,0)),"") | D35: =IFERROR(INDEX('My Debts'!$D$7:$D$18,MATCH(5,'My Debts'!$S$7:$S$18,0)),"") | E35: =IFERROR(INDEX('My Debts'!$E$7:$E$18,MATCH(5,'My Debts'!$S$7:$S$18,0)),"") | F35: =IFERROR(INDEX('My Debts'!$T$7:$T$18,MATCH(5,'My Debts'!$S$7:$S$18,0)),"") | G35: =IFERROR(INDEX('My Debts'!$V$7:$V$18,MATCH(5,'My Debts'!$S$7:$S$18,0)),"")
B36: =IF(6<=Plan!$K$8,6,"") | C36: =IFERROR(INDEX('My Debts'!$B$7:$B$18,MATCH(6,'My Debts'!$S$7:$S$18,0)),"") | D36: =IFERROR(INDEX('My Debts'!$D$7:$D$18,MATCH(6,'My Debts'!$S$7:$S$18,0)),"") | E36: =IFERROR(INDEX('My Debts'!$E$7:$E$18,MATCH(6,'My Debts'!$S$7:$S$18,0)),"") | F36: =IFERROR(INDEX('My Debts'!$T$7:$T$18,MATCH(6,'My Debts'!$S$7:$S$18,0)),"") | G36: =IFERROR(INDEX('My Debts'!$V$7:$V$18,MATCH(6,'My Debts'!$S$7:$S$18,0)),"")
B37: =IF(7<=Plan!$K$8,7,"") | C37: =IFERROR(INDEX('My Debts'!$B$7:$B$18,MATCH(7,'My Debts'!$S$7:$S$18,0)),"") | D37: =IFERROR(INDEX('My Debts'!$D$7:$D$18,MATCH(7,'My Debts'!$S$7:$S$18,0)),"") | E37: =IFERROR(INDEX('My Debts'!$E$7:$E$18,MATCH(7,'My Debts'!$S$7:$S$18,0)),"") | F37: =IFERROR(INDEX('My Debts'!$T$7:$T$18,MATCH(7,'My Debts'!$S$7:$S$18,0)),"") | G37: =IFERROR(INDEX('My Debts'!$V$7:$V$18,MATCH(7,'My Debts'!$S$7:$S$18,0)),"")
B38: =IF(8<=Plan!$K$8,8,"") | C38: =IFERROR(INDEX('My Debts'!$B$7:$B$18,MATCH(8,'My Debts'!$S$7:$S$18,0)),"") | D38: =IFERROR(INDEX('My Debts'!$D$7:$D$18,MATCH(8,'My Debts'!$S$7:$S$18,0)),"") | E38: =IFERROR(INDEX('My Debts'!$E$7:$E$18,MATCH(8,'My Debts'!$S$7:$S$18,0)),"") | F38: =IFERROR(INDEX('My Debts'!$T$7:$T$18,MATCH(8,'My Debts'!$S$7:$S$18,0)),"") | G38: =IFERROR(INDEX('My Debts'!$V$7:$V$18,MATCH(8,'My Debts'!$S$7:$S$18,0)),"")
B39: =IF(9<=Plan!$K$8,9,"") | C39: =IFERROR(INDEX('My Debts'!$B$7:$B$18,MATCH(9,'My Debts'!$S$7:$S$18,0)),"") | D39: =IFERROR(INDEX('My Debts'!$D$7:$D$18,MATCH(9,'My Debts'!$S$7:$S$18,0)),"") | E39: =IFERROR(INDEX('My Debts'!$E$7:$E$18,MATCH(9,'My Debts'!$S$7:$S$18,0)),"") | F39: =IFERROR(INDEX('My Debts'!$T$7:$T$18,MATCH(9,'My Debts'!$S$7:$S$18,0)),"") | G39: =IFERROR(INDEX('My Debts'!$V$7:$V$18,MATCH(9,'My Debts'!$S$7:$S$18,0)),"")
B40: =IF(10<=Plan!$K$8,10,"") | C40: =IFERROR(INDEX('My Debts'!$B$7:$B$18,MATCH(10,'My Debts'!$S$7:$S$18,0)),"") | D40: =IFERROR(INDEX('My Debts'!$D$7:$D$18,MATCH(10,'My Debts'!$S$7:$S$18,0)),"") | E40: =IFERROR(INDEX('My Debts'!$E$7:$E$18,MATCH(10,'My Debts'!$S$7:$S$18,0)),"") | F40: =IFERROR(INDEX('My Debts'!$T$7:$T$18,MATCH(10,'My Debts'!$S$7:$S$18,0)),"") | G40: =IFERROR(INDEX('My Debts'!$V$7:$V$18,MATCH(10,'My Debts'!$S$7:$S$18,0)),"")
B41: =IF(11<=Plan!$K$8,11,"") | C41: =IFERROR(INDEX('My Debts'!$B$7:$B$18,MATCH(11,'My Debts'!$S$7:$S$18,0)),"") | D41: =IFERROR(INDEX('My Debts'!$D$7:$D$18,MATCH(11,'My Debts'!$S$7:$S$18,0)),"") | E41: =IFERROR(INDEX('My Debts'!$E$7:$E$18,MATCH(11,'My Debts'!$S$7:$S$18,0)),"") | F41: =IFERROR(INDEX('My Debts'!$T$7:$T$18,MATCH(11,'My Debts'!$S$7:$S$18,0)),"") | G41: =IFERROR(INDEX('My Debts'!$V$7:$V$18,MATCH(11,'My Debts'!$S$7:$S$18,0)),"")
B42: =IF(12<=Plan!$K$8,12,"") | C42: =IFERROR(INDEX('My Debts'!$B$7:$B$18,MATCH(12,'My Debts'!$S$7:$S$18,0)),"") | D42: =IFERROR(INDEX('My Debts'!$D$7:$D$18,MATCH(12,'My Debts'!$S$7:$S$18,0)),"") | E42: =IFERROR(INDEX('My Debts'!$E$7:$E$18,MATCH(12,'My Debts'!$S$7:$S$18,0)),"") | F42: =IFERROR(INDEX('My Debts'!$T$7:$T$18,MATCH(12,'My Debts'!$S$7:$S$18,0)),"") | G42: =IFERROR(INDEX('My Debts'!$V$7:$V$18,MATCH(12,'My Debts'!$S$7:$S$18,0)),"")
B44: Estimates only, not financial advice. Interest is worked out monthly at APR÷12; your lender's method, fees and rules are the final word. Example debts are made up: replace them with yours.
...

Sheet My Debts
B2: My Debts
B3: One row per debt. Blue = you fill in (blank is fine for optional ones). Orange = calculated.
B4: Any currency works: just use the same one everywhere. APR as a percent (24.99%).
B6: DEBT NAME | C6: TYPE | D6: BALANCE NOW | E6: APR | F6: MINIMUM MONTHLY PAYMENT | G6: BEHIND ON PAYMENTS? | H6: EARLY PAYOFF RULE | I6: FEE TO PAY OFF EARLY | J6: FEE / LOCK ENDS | K6: 0% / PROMO RATE ENDS | L6: APR AFTER PROMO | M6: DEFERRED INTEREST? | N6: NOTES | O6: INTEREST THIS MONTH | P6: INTEREST IF MINIMUMS ONLY | Q6: EARLY PAYOFF CHECK | R6: EXTRA CAN START | S6: ORDER # | T6: PAID OFF | V6: WHY / NOTE
B7: Store card (sample) | C7: Store card | D7: 1200 | E7: 0 | F7: 60 | G7: No | H7: Allowed, no fee | K7: 46508 | L7: 0.2999 | M7: Yes | N7: 0% until May | O7: =IF(AND(ISNUMBER($D7),$D7>0),$D7*N(+$E7)/12,"") | P7: =IF(NOT(AND(ISNUMBER($D7),$D7>0)),"",IF(N(+$F7)<=0,"No minimum",IF(N(+$F7)<=$D7*N(+$E7)/12,"Never at minimum",IF(N(+$E7)=0,0,N(+$F7)*NPER(N(+$E7)/12,-N(+$F7),$D7)-$D7)))) | Q7: =IF(NOT(AND(ISNUMBER($D7),$D7>0)),"",IF(AND(N(+$F7)>0,N(+$F7)<=$D7*N(+$E7)/12),"Minimum doesn't cover interest: pay more here",IF(N(+$F7)<=0,"Add the minimum payment",IF($H7="Not sure - ask lender","Ask your lender before paying extra",IF($H7="Locked until a date",IF(N(+$J7)=0,"Locked: add the unlock date","Locked until "&CHOOSE(MONTH($J7),"Jan","Feb","Mar","Apr","May","Jun","Jul","Aug","Sep","Oct","Nov","Dec")&" "&YEAR($J7)),IF($H7="Allowed with a fee",IF(N(+$I7)=0,"Add the fee amount (blank = no fee)",IF(NOT(ISNUMBER($P7)),"Fee is worth paying: minimums never clear this",IF(N(+$I7)<$P7,"Worth it: saves about "&TEXT($P7-$I7,"#,##0")&" after the fee","Wait: the fee is more than the interest you'd save"&IF(N(+$J7)>0," (until "&CHOOSE(MONTH($J7),"Jan","Feb","Mar","Apr","May","Jun","Jul","Aug","Sep","Oct","Nov","Dec")&" "&YEAR($J7)&")","")))),"OK to pay early")))))) | R7: =IF($U7="","",IF($U7<=Plan!$C$6,"Now",IF($U7>=DATE(2199,12,1),"Not yet",CHOOSE(MONTH($U7),"Jan","Feb","Mar","Apr","May","Jun","Jul","Aug","Sep","Oct","Nov","Dec")&" "&YEAR($U7)))) | S7: =IF(AND(ISNUMBER($D7),$D7>0),CHOOSE(Plan!$K$5,AA7,AB7,AC7,AD7),"") | T7: =IF(AND(ISNUMBER($D7),$D7>0),CHOOSE(Plan!$K$5,'Calc Smart'!C$10,'Calc Avalanche'!C$10,'Calc Snowball'!C$10,'Calc Cashflow'!C$10),"") | U7: =IF(NOT(AND(ISNUMBER($D7),$D7>0)),"",IF($H7="Not sure - ask lender",DATE(2199,12,1),IF($H7="Locked until a date",IF(N(+$J7)=0,DATE(2199,12,1),$J7),IF(AND($H7="Allowed with a fee",N(+$I7)>0,ISNUMBER($P7),N(+$I7)>=N(+$P7)),IF(N(+$J7)=0,DATE(2199,12,1),$J7),DATE(1900,1,1))))) | V7: =IF(NOT(AND(ISNUMBER($D7),$D7>0)),"",IF($AE7,"⚠ Cleared after the promo ends ("&CHOOSE(MONTH($K7),"Jan","Feb","Mar","Apr","May","Jun","Jul","Aug","Sep","Oct","Nov","Dec")&" "&YEAR($K7)&"): back-interest likely, not counted here. Try Smart.",IF($G7="Yes","Behind on payments: deal with this first",IF(AND($M7="Yes",N(+$K7)>Plan!$C$6),"Deferred interest: clear by "&CHOOSE(MONTH($K7),"Jan","Feb","Mar","Apr","May","Jun","Jul","Aug","Sep","Oct","Nov","Dec")&" "&YEAR($K7)&" or back-interest is added",IF($U7>Plan!$C$6,$Q7,CHOOSE(Plan!$K$5,IF(Plan!$K$7,"Frees up monthly money fastest","Highest APR among the rest"),"APR "&TEXT(N(+$E7),"0.0%"),"Balance "&TEXT($D7,"#,##0"),"Frees "&TEXT(N(+$F7),"#,##0")&"/month when cleared")))))) | W7: =IF(AND(ISNUMBER($D7),$D7>0),1000-N(+$E7)*100+ROW()/1000000,"") | X7: =IF(AND(ISNUMBER($D7),$D7>0),$D7+ROW()/1000000,"") | Y7: =IF(AND(ISNUMBER($D7),$D7>0),1000-IF(N(+$F7)>0,N(+$F7)/$D7,0)*100+ROW()/1000000,"") | Z7: =IF(AND(ISNUMBER($D7),$D7>0),IF($G7="Yes",0,IF(AND($M7="Yes",N(+$K7)>Plan!$C$6),1,2))*1000000+IF(IF($G7="Yes",0,IF(AND($M7="Yes",N(+$K7)>Plan!$C$6),1,2))=0,1000-IF(N(+$F7)>0,N(+$F7)/$D7,0)*100+ROW()/1000000,IF(IF($G7="Yes",0,IF(AND($M7="Yes",N(+$K7)>Plan!$C$6),1,2))=1,N(+$K7)/100,IF(Plan!$K$7,1000-IF(N(+$F7)>0,N(+$F7)/$D7,0)*100+ROW()/1000000,1000-N(+$E7)*100+ROW()/1000000))),"") | AA7: =IF(Z7="","",COUNTIF(Z$7:Z$18,"<"&Z7)+1) | AB7: =IF(W7="","",COUNTIF(W$7:W$18,"<"&W7)+1) | AC7: =IF(X7="","",COUNTIF(X$7:X$18,"<"&X7)+1) | AD7: =IF(Y7="","",COUNTIF(Y$7:Y$18,"<"&Y7)+1) | AE7: =AND(AND(ISNUMBER($D7),$D7>0),$M7="Yes",N(+$K7)>0,ISNUMBER($T7),N(+$T7)>=N(+$K7))
B8: Credit card (sample) | C8: Credit card | D8: 4800 | E8: 0.2449 | F8: 120 | G8: No | H8: Allowed, no fee | O8: =IF(AND(ISNUMBER($D8),$D8>0),$D8*N(+$E8)/12,"") | P8: =IF(NOT(AND(ISNUMBER($D8),$D8>0)),"",IF(N(+$F8)<=0,"No minimum",IF(N(+$F8)<=$D8*N(+$E8)/12,"Never at minimum",IF(N(+$E8)=0,0,N(+$F8)*NPER(N(+$E8)/12,-N(+$F8),$D8)-$D8)))) | Q8: =IF(NOT(AND(ISNUMBER($D8),$D8>0)),"",IF(AND(N(+$F8)>0,N(+$F8)<=$D8*N(+$E8)/12),"Minimum doesn't cover interest: pay more here",IF(N(+$F8)<=0,"Add the minimum payment",IF($H8="Not sure - ask lender","Ask your lender before paying extra",IF($H8="Locked until a date",IF(N(+$J8)=0,"Locked: add the unlock date","Locked until "&CHOOSE(MONTH($J8),"Jan","Feb","Mar","Apr","May","Jun","Jul","Aug","Sep","Oct","Nov","Dec")&" "&YEAR($J8)),IF($H8="Allowed with a fee",IF(N(+$I8)=0,"Add the fee amount (blank = no fee)",IF(NOT(ISNUMBER($P8)),"Fee is worth paying: minimums never clear this",IF(N(+$I8)<$P8,"Worth it: saves about "&TEXT($P8-$I8,"#,##0")&" after the fee","Wait: the fee is more than the interest you'd save"&IF(N(+$J8)>0," (until "&CHOOSE(MONTH($J8),"Jan","Feb","Mar","Apr","May","Jun","Jul","Aug","Sep","Oct","Nov","Dec")&" "&YEAR($J8)&")","")))),"OK to pay early")))))) | R8: =IF($U8="","",IF($U8<=Plan!$C$6,"Now",IF($U8>=DATE(2199,12,1),"Not yet",CHOOSE(MONTH($U8),"Jan","Feb","Mar","Apr","May","Jun","Jul","Aug","Sep","Oct","Nov","Dec")&" "&YEAR($U8)))) | S8: =IF(AND(ISNUMBER($D8),$D8>0),CHOOSE(Plan!$K$5,AA8,AB8,AC8,AD8),"") | T8: =IF(AND(ISNUMBER($D8),$D8>0),CHOOSE(Plan!$K$5,'Calc Smart'!D$10,'Calc Avalanche'!D$10,'Calc Snowball'!D$10,'Calc Cashflow'!D$10),"") | U8: =IF(NOT(AND(ISNUMBER($D8),$D8>0)),"",IF($H8="Not sure - ask lender",DATE(2199,12,1),IF($H8="Locked until a date",IF(N(+$J8)=0,DATE(2199,12,1),$J8),IF(AND($H8="Allowed with a fee",N(+$I8)>0,ISNUMBER($P8),N(+$I8)>=N(+$P8)),IF(N(+$J8)=0,DATE(2199,12,1),$J8),DATE(1900,1,1))))) | V8: =IF(NOT(AND(ISNUMBER($D8),$D8>0)),"",IF($AE8,"⚠ Cleared after the promo ends ("&CHOOSE(MONTH($K8),"Jan","Feb","Mar","Apr","May","Jun","Jul","Aug","Sep","Oct","Nov","Dec")&" "&YEAR($K8)&"): back-interest likely, not counted here. Try Smart.",IF($G8="Yes","Behind on payments: deal with this first",IF(AND($M8="Yes",N(+$K8)>Plan!$C$6),"Deferred interest: clear by "&CHOOSE(MONTH($K8),"Jan","Feb","Mar","Apr","May","Jun","Jul","Aug","Sep","Oct","Nov","Dec")&" "&YEAR($K8)&" or back-interest is added",IF($U8>Plan!$C$6,$Q8,CHOOSE(Plan!$K$5,IF(Plan!$K$7,"Frees up monthly money fastest","Highest APR among the rest"),"APR "&TEXT(N(+$E8),"0.0%"),"Balance "&TEXT($D8,"#,##0"),"Frees "&TEXT(N(+$F8),"#,##0")&"/month when cleared")))))) | W8: =IF(AND(ISNUMBER($D8),$D8>0),1000-N(+$E8)*100+ROW()/1000000,"") | X8: =IF(AND(ISNUMBER($D8),$D8>0),$D8+ROW()/1000000,"") | Y8: =IF(AND(ISNUMBER($D8),$D8>0),1000-IF(N(+$F8)>0,N(+$F8)/$D8,0)*100+ROW()/1000000,"") | Z8: =IF(AND(ISNUMBER($D8),$D8>0),IF($G8="Yes",0,IF(AND($M8="Yes",N(+$K8)>Plan!$C$6),1,2))*1000000+IF(IF($G8="Yes",0,IF(AND($M8="Yes",N(+$K8)>Plan!$C$6),1,2))=0,1000-IF(N(+$F8)>0,N(+$F8)/$D8,0)*100+ROW()/1000000,IF(IF($G8="Yes",0,IF(AND($M8="Yes",N(+$K8)>Plan!$C$6),1,2))=1,N(+$K8)/100,IF(Plan!$K$7,1000-IF(N(+$F8)>0,N(+$F8)/$D8,0)*100+ROW()/1000000,1000-N(+$E8)*100+ROW()/1000000))),"") | AA8: =IF(Z8="","",COUNTIF(Z$7:Z$18,"<"&Z8)+1) | AB8: =IF(W8="","",COUNTIF(W$7:W$18,"<"&W8)+1) | AC8: =IF(X8="","",COUNTIF(X$7:X$18,"<"&X8)+1) | AD8: =IF(Y8="","",COUNTIF(Y$7:Y$18,"<"&Y8)+1) | AE8: =AND(AND(ISNUMBER($D8),$D8>0),$M8="Yes",N(+$K8)>0,ISNUMBER($T8),N(+$T8)>=N(+$K8))
B9: Car loan (sample) | C9: Car loan | D9: 9500 | E9: 0.089 | F9: 310 | G9: No | H9: Allowed with a fee | I9: 400 | J9: 46600 | N9: fee until Aug 2027 | O9: =IF(AND(ISNUMBER($D9),$D9>0),$D9*N(+$E9)/12,"") | P9: =IF(NOT(AND(ISNUMBER($D9),$D9>0)),"",IF(N(+$F9)<=0,"No minimum",IF(N(+$F9)<=$D9*N(+$E9)/12,"Never at minimum",IF(N(+$E9)=0,0,N(+$F9)*NPER(N(+$E9)/12,-N(+$F9),$D9)-$D9)))) | Q9: =IF(NOT(AND(ISNUMBER($D9),$D9>0)),"",IF(AND(N(+$F9)>0,N(+$F9)<=$D9*N(+$E9)/12),"Minimum doesn't cover interest: pay more here",IF(N(+$F9)<=0,"Add the minimum payment",IF($H9="Not sure - ask lender","Ask your lender before paying extra",IF($H9="Locked until a date",IF(N(+$J9)=0,"Locked: add the unlock date","Locked until "&CHOOSE(MONTH($J9),"Jan","Feb","Mar","Apr","May","Jun","Jul","Aug","Sep","Oct","Nov","Dec")&" "&YEAR($J9)),IF($H9="Allowed with a fee",IF(N(+$I9)=0,"Add the fee amount (blank = no fee)",IF(NOT(ISNUMBER($P9)),"Fee is worth paying: minimums never clear this",IF(N(+$I9)<$P9,"Worth it: saves about "&TEXT($P9-$I9,"#,##0")&" after the fee","Wait: the fee is more than the interest you'd save"&IF(N(+$J9)>0," (until "&CHOOSE(MONTH($J9),"Jan","Feb","Mar","Apr","May","Jun","Jul","Aug","Sep","Oct","Nov","Dec")&" "&YEAR($J9)&")","")))),"OK to pay early")))))) | R9: =IF($U9="","",IF($U9<=Plan!$C$6,"Now",IF($U9>=DATE(2199,12,1),"Not yet",CHOOSE(MONTH($U9),"Jan","Feb","Mar","Apr","May","Jun","Jul","Aug","Sep","Oct","Nov","Dec")&" "&YEAR($U9)))) | S9: =IF(AND(ISNUMBER($D9),$D9>0),CHOOSE(Plan!$K$5,AA9,AB9,AC9,AD9),"") | T9: =IF(AND(ISNUMBER($D9),$D9>0),CHOOSE(Plan!$K$5,'Calc Smart'!E$10,'Calc Avalanche'!E$10,'Calc Snowball'!E$10,'Calc Cashflow'!E$10),"") | U9: =IF(NOT(AND(ISNUMBER($D9),$D9>0)),"",IF($H9="Not sure - ask lender",DATE(2199,12,1),IF($H9="Locked until a date",IF(N(+$J9)=0,DATE(2199,12,1),$J9),IF(AND($H9="Allowed with a fee",N(+$I9)>0,ISNUMBER($P9),N(+$I9)>=N(+$P9)),IF(N(+$J9)=0,DATE(2199,12,1),$J9),DATE(1900,1,1))))) | V9: =IF(NOT(AND(ISNUMBER($D9),$D9>0)),"",IF($AE9,"⚠ Cleared after the promo ends ("&CHOOSE(MONTH($K9),"Jan","Feb","Mar","Apr","May","Jun","Jul","Aug","Sep","Oct","Nov","Dec")&" "&YEAR($K9)&"): back-interest likely, not counted here. Try Smart.",IF($G9="Yes","Behind on payments: deal with this first",IF(AND($M9="Yes",N(+$K9)>Plan!$C$6),"Deferred interest: clear by "&CHOOSE(MONTH($K9),"Jan","Feb","Mar","Apr","May","Jun","Jul","Aug","Sep","Oct","Nov","Dec")&" "&YEAR($K9)&" or back-interest is added",IF($U9>Plan!$C$6,$Q9,CHOOSE(Plan!$K$5,IF(Plan!$K$7,"Frees up monthly money fastest","Highest APR among the rest"),"APR "&TEXT(N(+$E9),"0.0%"),"Balance "&TEXT($D9,"#,##0"),"Frees "&TEXT(N(+$F9),"#,##0")&"/month when cleared")))))) | W9: =IF(AND(ISNUMBER($D9),$D9>0),1000-N(+$E9)*100+ROW()/1000000,"") | X9: =IF(AND(ISNUMBER($D9),$D9>0),$D9+ROW()/1000000,"") | Y9: =IF(AND(ISNUMBER($D9),$D9>0),1000-IF(N(+$F9)>0,N(+$F9)/$D9,0)*100+ROW()/1000000,"") | Z9: =IF(AND(ISNUMBER($D9),$D9>0),IF($G9="Yes",0,IF(AND($M9="Yes",N(+$K9)>Plan!$C$6),1,2))*1000000+IF(IF($G9="Yes",0,IF(AND($M9="Yes",N(+$K9)>Plan!$C$6),1,2))=0,1000-IF(N(+$F9)>0,N(+$F9)/$D9,0)*100+ROW()/1000000,IF(IF($G9="Yes",0,IF(AND($M9="Yes",N(+$K9)>Plan!$C$6),1,2))=1,N(+$K9)/100,IF(Plan!$K$7,1000-IF(N(+$F9)>0,N(+$F9)/$D9,0)*100+ROW()/1000000,1000-N(+$E9)*100+ROW()/1000000))),"") | AA9: =IF(Z9="","",COUNTIF(Z$7:Z$18,"<"&Z9)+1) | AB9: =IF(W9="","",COUNTIF(W$7:W$18,"<"&W9)+1) | AC9: =IF(X9="","",COUNTIF(X$7:X$18,"<"&X9)+1) | AD9: =IF(Y9="","",COUNTIF(Y$7:Y$18,"<"&Y9)+1) | AE9: =AND(AND(ISNUMBER($D9),$D9>0),$M9="Yes",N(+$K9)>0,ISNUMBER($T9),N(+$T9)>=N(+$K9))
B10: Personal loan (sample) | C10: Personal loan | D10: 3000 | E10: 0.159 | F10: 140 | G10: No | H10: Not sure - ask lender | N10: call lender | O10: =IF(AND(ISNUMBER($D10),$D10>0),$D10*N(+$E10)/12,"") | P10: =IF(NOT(AND(ISNUMBER($D10),$D10>0)),"",IF(N(+$F10)<=0,"No minimum",IF(N(+$F10)<=$D10*N(+$E10)/12,"Never at minimum",IF(N(+$E10)=0,0,N(+$F10)*NPER(N(+$E10)/12,-N(+$F10),$D10)-$D10)))) | Q10: =IF(NOT(AND(ISNUMBER($D10),$D10>0)),"",IF(AND(N(+$F10)>0,N(+$F10)<=$D10*N(+$E10)/12),"Minimum doesn't cover interest: pay more here",IF(N(+$F10)<=0,"Add the minimum payment",IF($H10="Not sure - ask lender","Ask your lender before paying extra",IF($H10="Locked until a date",IF(N(+$J10)=0,"Locked: add the unlock date","Locked until "&CHOOSE(MONTH($J10),"Jan","Feb","Mar","Apr","May","Jun","Jul","Aug","Sep","Oct","Nov","Dec")&" "&YEAR($J10)),IF($H10="Allowed with a fee",IF(N(+$I10)=0,"Add the fee amount (blank = no fee)",IF(NOT(ISNUMBER($P10)),"Fee is worth paying: minimums never clear this",IF(N(+$I10)<$P10,"Worth it: saves about "&TEXT($P10-$I10,"#,##0")&" after the fee","Wait: the fee is more than the interest you'd save"&IF(N(+$J10)>0," (until "&CHOOSE(MONTH($J10),"Jan","Feb","Mar","Apr","May","Jun","Jul","Aug","Sep","Oct","Nov","Dec")&" "&YEAR($J10)&")","")))),"OK to pay early")))))) | R10: =IF($U10="","",IF($U10<=Plan!$C$6,"Now",IF($U10>=DATE(2199,12,1),"Not yet",CHOOSE(MONTH($U10),"Jan","Feb","Mar","Apr","May","Jun","Jul","Aug","Sep","Oct","Nov","Dec")&" "&YEAR($U10)))) | S10: =IF(AND(ISNUMBER($D10),$D10>0),CHOOSE(Plan!$K$5,AA10,AB10,AC10,AD10),"") | T10: =IF(AND(ISNUMBER($D10),$D10>0),CHOOSE(Plan!$K$5,'Calc Smart'!F$10,'Calc Avalanche'!F$10,'Calc Snowball'!F$10,'Calc Cashflow'!F$10),"") | U10: =IF(NOT(AND(ISNUMBER($D10),$D10>0)),"",IF($H10="Not sure - ask lender",DATE(2199,12,1),IF($H10="Locked until a date",IF(N(+$J10)=0,DATE(2199,12,1),$J10),IF(AND($H10="Allowed with a fee",N(+$I10)>0,ISNUMBER($P10),N(+$I10)>=N(+$P10)),IF(N(+$J10)=0,DATE(2199,12,1),$J10),DATE(1900,1,1))))) | V10: =IF(NOT(AND(ISNUMBER($D10),$D10>0)),"",IF($AE10,"⚠ Cleared after the promo ends ("&CHOOSE(MONTH($K10),"Jan","Feb","Mar","Apr","May","Jun","Jul","Aug","Sep","Oct","Nov","Dec")&" "&YEAR($K10)&"): back-interest likely, not counted here. Try Smart.",IF($G10="Yes","Behind on payments: deal with this first",IF(AND($M10="Yes",N(+$K10)>Plan!$C$6),"Deferred interest: clear by "&CHOOSE(MONTH($K10),"Jan","Feb","Mar","Apr","May","Jun","Jul","Aug","Sep","Oct","Nov","Dec")&" "&YEAR($K10)&" or back-interest is added",IF($U10>Plan!$C$6,$Q10,CHOOSE(Plan!$K$5,IF(Plan!$K$7,"Frees up monthly money fastest","Highest APR among the rest"),"APR "&TEXT(N(+$E10),"0.0%"),"Balance "&TEXT($D10,"#,##0"),"Frees "&TEXT(N(+$F10),"#,##0")&"/month when cleared")))))) | W10: =IF(AND(ISNUMBER($D10),$D10>0),1000-N(+$E10)*100+ROW()/1000000,"") | X10: =IF(AND(ISNUMBER($D10),$D10>0),$D10+ROW()/1000000,"") | Y10: =IF(AND(ISNUMBER($D10),$D10>0),1000-IF(N(+$F10)>0,N(+$F10)/$D10,0)*100+ROW()/1000000,"") | Z10: =IF(AND(ISNUMBER($D10),$D10>0),IF($G10="Yes",0,IF(AND($M10="Yes",N(+$K10)>Plan!$C$6),1,2))*1000000+IF(IF($G10="Yes",0,IF(AND($M10="Yes",N(+$K10)>Plan!$C$6),1,2))=0,1000-IF(N(+$F10)>0,N(+$F10)/$D10,0)*100+ROW()/1000000,IF(IF($G10="Yes",0,IF(AND($M10="Yes",N(+$K10)>Plan!$C$6),1,2))=1,N(+$K10)/100,IF(Plan!$K$7,1000-IF(N(+$F10)>0,N(+$F10)/$D10,0)*100+ROW()/1000000,1000-N(+$E10)*100+ROW()/1000000))),"") | AA10: =IF(Z10="","",COUNTIF(Z$7:Z$18,"<"&Z10)+1) | AB10: =IF(W10="","",COUNTIF(W$7:W$18,"<"&W10)+1) | AC10: =IF(X10="","",COUNTIF(X$7:X$18,"<"&X10)+1) | AD10: =IF(Y10="","",COUNTIF(Y$7:Y$18,"<"&Y10)+1) | AE10: =AND(AND(ISNUMBER($D10),$D10>0),$M10="Yes",N(+$K10)>0,ISNUMBER($T10),N(+$T10)>=N(+$K10))
B11: Medical bill (sample) | C11: Medical bill | D11: 650 | E11: 0 | F11: 50 | G11: Yes | N11: late notice | O11: =IF(AND(ISNUMBER($D11),$D11>0),$D11*N(+$E11)/12,"") | P11: =IF(NOT(AND(ISNUMBER($D11),$D11>0)),"",IF(N(+$F11)<=0,"No minimum",IF(N(+$F11)<=$D11*N(+$E11)/12,"Never at minimum",IF(N(+$E11)=0,0,N(+$F11)*NPER(N(+$E11)/12,-N(+$F11),$D11)-$D11)))) | Q11: =IF(NOT(AND(ISNUMBER($D11),$D11>0)),"",IF(AND(N(+$F11)>0,N(+$F11)<=$D11*N(+$E11)/12),"Minimum doesn't cover interest: pay more here",IF(N(+$F11)<=0,"Add the minimum payment",IF($H11="Not sure - ask lender","Ask your lender before paying extra",IF($H11="Locked until a date",IF(N(+$J11)=0,"Locked: add the unlock date","Locked until "&CHOOSE(MONTH($J11),"Jan","Feb","Mar","Apr","May","Jun","Jul","Aug","Sep","Oct","Nov","Dec")&" "&YEAR($J11)),IF($H11="Allowed with a fee",IF(N(+$I11)=0,"Add the fee amount (blank = no fee)",IF(NOT(ISNUMBER($P11)),"Fee is worth paying: minimums never clear this",IF(N(+$I11)<$P11,"Worth it: saves about "&TEXT($P11-$I11,"#,##0")&" after the fee","Wait: the fee is more than the interest you'd save"&IF(N(+$J11)>0," (until "&CHOOSE(MONTH($J11),"Jan","Feb","Mar","Apr","May","Jun","Jul","Aug","Sep","Oct","Nov","Dec")&" "&YEAR($J11)&")","")))),"OK to pay early")))))) | R11: =IF($U11="","",IF($U11<=Plan!$C$6,"Now",IF($U11>=DATE(2199,12,1),"Not yet",CHOOSE(MONTH($U11),"Jan","Feb","Mar","Apr","May","Jun","Jul","Aug","Sep","Oct","Nov","Dec")&" "&YEAR($U11)))) | S11: =IF(AND(ISNUMBER($D11),$D11>0),CHOOSE(Plan!$K$5,AA11,AB11,AC11,AD11),"") | T11: =IF(AND(ISNUMBER($D11),$D11>0),CHOOSE(Plan!$K$5,'Calc Smart'!G$10,'Calc Avalanche'!G$10,'Calc Snowball'!G$10,'Calc Cashflow'!G$10),"") | U11: =IF(NOT(AND(ISNUMBER($D11),$D11>0)),"",IF($H11="Not sure - ask lender",DATE(2199,12,1),IF($H11="Locked until a date",IF(N(+$J11)=0,DATE(2199,12,1),$J11),IF(AND($H11="Allowed with a fee",N(+$I11)>0,ISNUMBER($P11),N(+$I11)>=N(+$P11)),IF(N(+$J11)=0,DATE(2199,12,1),$J11),DATE(1900,1,1))))) | V11: =IF(NOT(AND(ISNUMBER($D11),$D11>0)),"",IF($AE11,"⚠ Cleared after the promo ends ("&CHOOSE(MONTH($K11),"Jan","Feb","Mar","Apr","May","Jun","Jul","Aug","Sep","Oct","Nov","Dec")&" "&YEAR($K11)&"): back-interest likely, not counted here. Try Smart.",IF($G11="Yes","Behind on payments: deal with this first",IF(AND($M11="Yes",N(+$K11)>Plan!$C$6),"Deferred interest: clear by "&CHOOSE(MONTH($K11),"Jan","Feb","Mar","Apr","May","Jun","Jul","Aug","Sep","Oct","Nov","Dec")&" "&YEAR($K11)&" or back-interest is added",IF($U11>Plan!$C$6,$Q11,CHOOSE(Plan!$K$5,IF(Plan!$K$7,"Frees up monthly money fastest","Highest APR among the rest"),"APR "&TEXT(N(+$E11),"0.0%"),"Balance "&TEXT($D11,"#,##0"),"Frees "&TEXT(N(+$F11),"#,##0")&"/month when cleared")))))) | W11: =IF(AND(ISNUMBER($D11),$D11>0),1000-N(+$E11)*100+ROW()/1000000,"") | X11: =IF(AND(ISNUMBER($D11),$D11>0),$D11+ROW()/1000000,"") | Y11: =IF(AND(ISNUMBER($D11),$D11>0),1000-IF(N(+$F11)>0,N(+$F11)/$D11,0)*100+ROW()/1000000,"") | Z11: =IF(AND(ISNUMBER($D11),$D11>0),IF($G11="Yes",0,IF(AND($M11="Yes",N(+$K11)>Plan!$C$6),1,2))*1000000+IF(IF($G11="Yes",0,IF(AND($M11="Yes",N(+$K11)>Plan!$C$6),1,2))=0,1000-IF(N(+$F11)>0,N(+$F11)/$D11,0)*100+ROW()/1000000,IF(IF($G11="Yes",0,IF(AND($M11="Yes",N(+$K11)>Plan!$C$6),1,2))=1,N(+$K11)/100,IF(Plan!$K$7,1000-IF(N(+$F11)>0,N(+$F11)/$D11,0)*100+ROW()/1000000,1000-N(+$E11)*100+ROW()/1000000))),"") | AA11: =IF(Z11="","",COUNTIF(Z$7:Z$18,"<"&Z11)+1) | AB11: =IF(W11="","",COUNTIF(W$7:W$18,"<"&W11)+1) | AC11: =IF(X11="","",COUNTIF(X$7:X$18,"<"&X11)+1) | AD11: =IF(Y11="","",COUNTIF(Y$7:Y$18,"<"&Y11)+1) | AE11: =AND(AND(ISNUMBER($D11),$D11>0),$M11="Yes",N(+$K11)>0,ISNUMBER($T11),N(+$T11)>=N(+$K11))
O12: =IF(AND(ISNUMBER($D12),$D12>0),$D12*N(+$E12)/12,"") | P12: =IF(NOT(AND(ISNUMBER($D12),$D12>0)),"",IF(N(+$F12)<=0,"No minimum",IF(N(+$F12)<=$D12*N(+$E12)/12,"Never at minimum",IF(N(+$E12)=0,0,N(+$F12)*NPER(N(+$E12)/12,-N(+$F12),$D12)-$D12)))) | Q12: =IF(NOT(AND(ISNUMBER($D12),$D12>0)),"",IF(AND(N(+$F12)>0,N(+$F12)<=$D12*N(+$E12)/12),"Minimum doesn't cover interest: pay more here",IF(N(+$F12)<=0,"Add the minimum payment",IF($H12="Not sure - ask lender","Ask your lender before paying extra",IF($H12="Locked until a date",IF(N(+$J12)=0,"Locked: add the unlock date","Locked until "&CHOOSE(MONTH($J12),"Jan","Feb","Mar","Apr","May","Jun","Jul","Aug","Sep","Oct","Nov","Dec")&" "&YEAR($J12)),IF($H12="Allowed with a fee",IF(N(+$I12)=0,"Add the fee amount (blank = no fee)",IF(NOT(ISNUMBER($P12)),"Fee is worth paying: minimums never clear this",IF(N(+$I12)<$P12,"Worth it: saves about "&TEXT($P12-$I12,"#,##0")&" after the fee","Wait: the fee is more than the interest you'd save"&IF(N(+$J12)>0," (until "&CHOOSE(MONTH($J12),"Jan","Feb","Mar","Apr","May","Jun","Jul","Aug","Sep","Oct","Nov","Dec")&" "&YEAR($J12)&")","")))),"OK to pay early")))))) | R12: =IF($U12="","",IF($U12<=Plan!$C$6,"Now",IF($U12>=DATE(2199,12,1),"Not yet",CHOOSE(MONTH($U12),"Jan","Feb","Mar","Apr","May","Jun","Jul","Aug","Sep","Oct","Nov","Dec")&" "&YEAR($U12)))) | S12: =IF(AND(ISNUMBER($D12),$D12>0),CHOOSE(Plan!$K$5,AA12,AB12,AC12,AD12),"") | T12: =IF(AND(ISNUMBER($D12),$D12>0),CHOOSE(Plan!$K$5,'Calc Smart'!H$10,'Calc Avalanche'!H$10,'Calc Snowball'!H$10,'Calc Cashflow'!H$10),"") | U12: =IF(NOT(AND(ISNUMBER($D12),$D12>0)),"",IF($H12="Not sure - ask lender",DATE(2199,12,1),IF($H12="Locked until a date",IF(N(+$J12)=0,DATE(2199,12,1),$J12),IF(AND($H12="Allowed with a fee",N(+$I12)>0,ISNUMBER($P12),N(+$I12)>=N(+$P12)),IF(N(+$J12)=0,DATE(2199,12,1),$J12),DATE(1900,1,1))))) | V12: =IF(NOT(AND(ISNUMBER($D12),$D12>0)),"",IF($AE12,"⚠ Cleared after the promo ends ("&CHOOSE(MONTH($K12),"Jan","Feb","Mar","Apr","May","Jun","Jul","Aug","Sep","Oct","Nov","Dec")&" "&YEAR($K12)&"): back-interest likely, not counted here. Try Smart.",IF($G12="Yes","Behind on payments: deal with this first",IF(AND($M12="Yes",N(+$K12)>Plan!$C$6),"Deferred interest: clear by "&CHOOSE(MONTH($K12),"Jan","Feb","Mar","Apr","May","Jun","Jul","Aug","Sep","Oct","Nov","Dec")&" "&YEAR($K12)&" or back-interest is added",IF($U12>Plan!$C$6,$Q12,CHOOSE(Plan!$K$5,IF(Plan!$K$7,"Frees up monthly money fastest","Highest APR among the rest"),"APR "&TEXT(N(+$E12),"0.0%"),"Balance "&TEXT($D12,"#,##0"),"Frees "&TEXT(N(+$F12),"#,##0")&"/month when cleared")))))) | W12: =IF(AND(ISNUMBER($D12),$D12>0),1000-N(+$E12)*100+ROW()/1000000,"") | X12: =IF(AND(ISNUMBER($D12),$D12>0),$D12+ROW()/1000000,"") | Y12: =IF(AND(ISNUMBER($D12),$D12>0),1000-IF(N(+$F12)>0,N(+$F12)/$D12,0)*100+ROW()/1000000,"") | Z12: =IF(AND(ISNUMBER($D12),$D12>0),IF($G12="Yes",0,IF(AND($M12="Yes",N(+$K12)>Plan!$C$6),1,2))*1000000+IF(IF($G12="Yes",0,IF(AND($M12="Yes",N(+$K12)>Plan!$C$6),1,2))=0,1000-IF(N(+$F12)>0,N(+$F12)/$D12,0)*100+ROW()/1000000,IF(IF($G12="Yes",0,IF(AND($M12="Yes",N(+$K12)>Plan!$C$6),1,2))=1,N(+$K12)/100,IF(Plan!$K$7,1000-IF(N(+$F12)>0,N(+$F12)/$D12,0)*100+ROW()/1000000,1000-N(+$E12)*100+ROW()/1000000))),"") | AA12: =IF(Z12="","",COUNTIF(Z$7:Z$18,"<"&Z12)+1) | AB12: =IF(W12="","",COUNTIF(W$7:W$18,"<"&W12)+1) | AC12: =IF(X12="","",COUNTIF(X$7:X$18,"<"&X12)+1) | AD12: =IF(Y12="","",COUNTIF(Y$7:Y$18,"<"&Y12)+1) | AE12: =AND(AND(ISNUMBER($D12),$D12>0),$M12="Yes",N(+$K12)>0,ISNUMBER($T12),N(+$T12)>=N(+$K12))
O13: =IF(AND(ISNUMBER($D13),$D13>0),$D13*N(+$E13)/12,"") | P13: =IF(NOT(AND(ISNUMBER($D13),$D13>0)),"",IF(N(+$F13)<=0,"No minimum",IF(N(+$F13)<=$D13*N(+$E13)/12,"Never at minimum",IF(N(+$E13)=0,0,N(+$F13)*NPER(N(+$E13)/12,-N(+$F13),$D13)-$D13)))) | Q13: =IF(NOT(AND(ISNUMBER($D13),$D13>0)),"",IF(AND(N(+$F13)>0,N(+$F13)<=$D13*N(+$E13)/12),"Minimum doesn't cover interest: pay more here",IF(N(+$F13)<=0,"Add the minimum payment",IF($H13="Not sure - ask lender","Ask your lender before paying extra",IF($H13="Locked until a date",IF(N(+$J13)=0,"Locked: add the unlock date","Locked until "&CHOOSE(MONTH($J13),"Jan","Feb","Mar","Apr","May","Jun","Jul","Aug","Sep","Oct","Nov","Dec")&" "&YEAR($J13)),IF($H13="Allowed with a fee",IF(N(+$I13)=0,"Add the fee amount (blank = no fee)",IF(NOT(ISNUMBER($P13)),"Fee is worth paying: minimums never clear this",IF(N(+$I13)<$P13,"Worth it: saves about "&TEXT($P13-$I13,"#,##0")&" after the fee","Wait: the fee is more than the interest you'd save"&IF(N(+$J13)>0," (until "&CHOOSE(MONTH($J13),"Jan","Feb","Mar","Apr","May","Jun","Jul","Aug","Sep","Oct","Nov","Dec")&" "&YEAR($J13)&")","")))),"OK to pay early")))))) | R13: =IF($U13="","",IF($U13<=Plan!$C$6,"Now",IF($U13>=DATE(2199,12,1),"Not yet",CHOOSE(MONTH($U13),"Jan","Feb","Mar","Apr","May","Jun","Jul","Aug","Sep","Oct","Nov","Dec")&" "&YEAR($U13)))) | S13: =IF(AND(ISNUMBER($D13),$D13>0),CHOOSE(Plan!$K$5,AA13,AB13,AC13,AD13),"") | T13: =IF(AND(ISNUMBER($D13),$D13>0),CHOOSE(Plan!$K$5,'Calc Smart'!I$10,'Calc Avalanche'!I$10,'Calc Snowball'!I$10,'Calc Cashflow'!I$10),"") | U13: =IF(NOT(AND(ISNUMBER($D13),$D13>0)),"",IF($H13="Not sure - ask lender",DATE(2199,12,1),IF($H13="Locked until a date",IF(N(+$J13)=0,DATE(2199,12,1),$J13),IF(AND($H13="Allowed with a fee",N(+$I13)>0,ISNUMBER($P13),N(+$I13)>=N(+$P13)),IF(N(+$J13)=0,DATE(2199,12,1),$J13),DATE(1900,1,1))))) | V13: =IF(NOT(AND(ISNUMBER($D13),$D13>0)),"",IF($AE13,"⚠ Cleared after the promo ends ("&CHOOSE(MONTH($K13),"Jan","Feb","Mar","Apr","May","Jun","Jul","Aug","Sep","Oct","Nov","Dec")&" "&YEAR($K13)&"): back-interest likely, not counted here. Try Smart.",IF($G13="Yes","Behind on payments: deal with this first",IF(AND($M13="Yes",N(+$K13)>Plan!$C$6),"Deferred interest: clear by "&CHOOSE(MONTH($K13),"Jan","Feb","Mar","Apr","May","Jun","Jul","Aug","Sep","Oct","Nov","Dec")&" "&YEAR($K13)&" or back-interest is added",IF($U13>Plan!$C$6,$Q13,CHOOSE(Plan!$K$5,IF(Plan!$K$7,"Frees up monthly money fastest","Highest APR among the rest"),"APR "&TEXT(N(+$E13),"0.0%"),"Balance "&TEXT($D13,"#,##0"),"Frees "&TEXT(N(+$F13),"#,##0")&"/month when cleared")))))) | W13: =IF(AND(ISNUMBER($D13),$D13>0),1000-N(+$E13)*100+ROW()/1000000,"") | X13: =IF(AND(ISNUMBER($D13),$D13>0),$D13+ROW()/1000000,"") | Y13: =IF(AND(ISNUMBER($D13),$D13>0),1000-IF(N(+$F13)>0,N(+$F13)/$D13,0)*100+ROW()/1000000,"") | Z13: =IF(AND(ISNUMBER($D13),$D13>0),IF($G13="Yes",0,IF(AND($M13="Yes",N(+$K13)>Plan!$C$6),1,2))*1000000+IF(IF($G13="Yes",0,IF(AND($M13="Yes",N(+$K13)>Plan!$C$6),1,2))=0,1000-IF(N(+$F13)>0,N(+$F13)/$D13,0)*100+ROW()/1000000,IF(IF($G13="Yes",0,IF(AND($M13="Yes",N(+$K13)>Plan!$C$6),1,2))=1,N(+$K13)/100,IF(Plan!$K$7,1000-IF(N(+$F13)>0,N(+$F13)/$D13,0)*100+ROW()/1000000,1000-N(+$E13)*100+ROW()/1000000))),"") | AA13: =IF(Z13="","",COUNTIF(Z$7:Z$18,"<"&Z13)+1) | AB13: =IF(W13="","",COUNTIF(W$7:W$18,"<"&W13)+1) | AC13: =IF(X13="","",COUNTIF(X$7:X$18,"<"&X13)+1) | AD13: =IF(Y13="","",COUNTIF(Y$7:Y$18,"<"&Y13)+1) | AE13: =AND(AND(ISNUMBER($D13),$D13>0),$M13="Yes",N(+$K13)>0,ISNUMBER($T13),N(+$T13)>=N(+$K13))
O14: =IF(AND(ISNUMBER($D14),$D14>0),$D14*N(+$E14)/12,"") | P14: =IF(NOT(AND(ISNUMBER($D14),$D14>0)),"",IF(N(+$F14)<=0,"No minimum",IF(N(+$F14)<=$D14*N(+$E14)/12,"Never at minimum",IF(N(+$E14)=0,0,N(+$F14)*NPER(N(+$E14)/12,-N(+$F14),$D14)-$D14)))) | Q14: =IF(NOT(AND(ISNUMBER($D14),$D14>0)),"",IF(AND(N(+$F14)>0,N(+$F14)<=$D14*N(+$E14)/12),"Minimum doesn't cover interest: pay more here",IF(N(+$F14)<=0,"Add the minimum payment",IF($H14="Not sure - ask lender","Ask your lender before paying extra",IF($H14="Locked until a date",IF(N(+$J14)=0,"Locked: add the unlock date","Locked until "&CHOOSE(MONTH($J14),"Jan","Feb","Mar","Apr","May","Jun","Jul","Aug","Sep","Oct","Nov","Dec")&" "&YEAR($J14)),IF($H14="Allowed with a fee",IF(N(+$I14)=0,"Add the fee amount (blank = no fee)",IF(NOT(ISNUMBER($P14)),"Fee is worth paying: minimums never clear this",IF(N(+$I14)<$P14,"Worth it: saves about "&TEXT($P14-$I14,"#,##0")&" after the fee","Wait: the fee is more than the interest you'd save"&IF(N(+$J14)>0," (until "&CHOOSE(MONTH($J14),"Jan","Feb","Mar","Apr","May","Jun","Jul","Aug","Sep","Oct","Nov","Dec")&" "&YEAR($J14)&")","")))),"OK to pay early")))))) | R14: =IF($U14="","",IF($U14<=Plan!$C$6,"Now",IF($U14>=DATE(2199,12,1),"Not yet",CHOOSE(MONTH($U14),"Jan","Feb","Mar","Apr","May","Jun","Jul","Aug","Sep","Oct","Nov","Dec")&" "&YEAR($U14)))) | S14: =IF(AND(ISNUMBER($D14),$D14>0),CHOOSE(Plan!$K$5,AA14,AB14,AC14,AD14),"") | T14: =IF(AND(ISNUMBER($D14),$D14>0),CHOOSE(Plan!$K$5,'Calc Smart'!J$10,'Calc Avalanche'!J$10,'Calc Snowball'!J$10,'Calc Cashflow'!J$10),"") | U14: =IF(NOT(AND(ISNUMBER($D14),$D14>0)),"",IF($H14="Not sure - ask lender",DATE(2199,12,1),IF($H14="Locked until a date",IF(N(+$J14)=0,DATE(2199,12,1),$J14),IF(AND($H14="Allowed with a fee",N(+$I14)>0,ISNUMBER($P14),N(+$I14)>=N(+$P14)),IF(N(+$J14)=0,DATE(2199,12,1),$J14),DATE(1900,1,1))))) | V14: =IF(NOT(AND(ISNUMBER($D14),$D14>0)),"",IF($AE14,"⚠ Cleared after the promo ends ("&CHOOSE(MONTH($K14),"Jan","Feb","Mar","Apr","May","Jun","Jul","Aug","Sep","Oct","Nov","Dec")&" "&YEAR($K14)&"): back-interest likely, not counted here. Try Smart.",IF($G14="Yes","Behind on payments: deal with this first",IF(AND($M14="Yes",N(+$K14)>Plan!$C$6),"Deferred interest: clear by "&CHOOSE(MONTH($K14),"Jan","Feb","Mar","Apr","May","Jun","Jul","Aug","Sep","Oct","Nov","Dec")&" "&YEAR($K14)&" or back-interest is added",IF($U14>Plan!$C$6,$Q14,CHOOSE(Plan!$K$5,IF(Plan!$K$7,"Frees up monthly money fastest","Highest APR among the rest"),"APR "&TEXT(N(+$E14),"0.0%"),"Balance "&TEXT($D14,"#,##0"),"Frees "&TEXT(N(+$F14),"#,##0")&"/month when cleared")))))) | W14: =IF(AND(ISNUMBER($D14),$D14>0),1000-N(+$E14)*100+ROW()/1000000,"") | X14: =IF(AND(ISNUMBER($D14),$D14>0),$D14+ROW()/1000000,"") | Y14: =IF(AND(ISNUMBER($D14),$D14>0),1000-IF(N(+$F14)>0,N(+$F14)/$D14,0)*100+ROW()/1000000,"") | Z14: =IF(AND(ISNUMBER($D14),$D14>0),IF($G14="Yes",0,IF(AND($M14="Yes",N(+$K14)>Plan!$C$6),1,2))*1000000+IF(IF($G14="Yes",0,IF(AND($M14="Yes",N(+$K14)>Plan!$C$6),1,2))=0,1000-IF(N(+$F14)>0,N(+$F14)/$D14,0)*100+ROW()/1000000,IF(IF($G14="Yes",0,IF(AND($M14="Yes",N(+$K14)>Plan!$C$6),1,2))=1,N(+$K14)/100,IF(Plan!$K$7,1000-IF(N(+$F14)>0,N(+$F14)/$D14,0)*100+ROW()/1000000,1000-N(+$E14)*100+ROW()/1000000))),"") | AA14: =IF(Z14="","",COUNTIF(Z$7:Z$18,"<"&Z14)+1) | AB14: =IF(W14="","",COUNTIF(W$7:W$18,"<"&W14)+1) | AC14: =IF(X14="","",COUNTIF(X$7:X$18,"<"&X14)+1) | AD14: =IF(Y14="","",COUNTIF(Y$7:Y$18,"<"&Y14)+1) | AE14: =AND(AND(ISNUMBER($D14),$D14>0),$M14="Yes",N(+$K14)>0,ISNUMBER($T14),N(+$T14)>=N(+$K14))
O15: =IF(AND(ISNUMBER($D15),$D15>0),$D15*N(+$E15)/12,"") | P15: =IF(NOT(AND(ISNUMBER($D15),$D15>0)),"",IF(N(+$F15)<=0,"No minimum",IF(N(+$F15)<=$D15*N(+$E15)/12,"Never at minimum",IF(N(+$E15)=0,0,N(+$F15)*NPER(N(+$E15)/12,-N(+$F15),$D15)-$D15)))) | Q15: =IF(NOT(AND(ISNUMBER($D15),$D15>0)),"",IF(AND(N(+$F15)>0,N(+$F15)<=$D15*N(+$E15)/12),"Minimum doesn't cover interest: pay more here",IF(N(+$F15)<=0,"Add the minimum payment",IF($H15="Not sure - ask lender","Ask your lender before paying extra",IF($H15="Locked until a date",IF(N(+$J15)=0,"Locked: add the unlock date","Locked until "&CHOOSE(MONTH($J15),"Jan","Feb","Mar","Apr","May","Jun","Jul","Aug","Sep","Oct","Nov","Dec")&" "&YEAR($J15)),IF($H15="Allowed with a fee",IF(N(+$I15)=0,"Add the fee amount (blank = no fee)",IF(NOT(ISNUMBER($P15)),"Fee is worth paying: minimums never clear this",IF(N(+$I15)<$P15,"Worth it: saves about "&TEXT($P15-$I15,"#,##0")&" after the fee","Wait: the fee is more than the interest you'd save"&IF(N(+$J15)>0," (until "&CHOOSE(MONTH($J15),"Jan","Feb","Mar","Apr","May","Jun","Jul","Aug","Sep","Oct","Nov","Dec")&" "&YEAR($J15)&")","")))),"OK to pay early")))))) | R15: =IF($U15="","",IF($U15<=Plan!$C$6,"Now",IF($U15>=DATE(2199,12,1),"Not yet",CHOOSE(MONTH($U15),"Jan","Feb","Mar","Apr","May","Jun","Jul","Aug","Sep","Oct","Nov","Dec")&" "&YEAR($U15)))) | S15: =IF(AND(ISNUMBER($D15),$D15>0),CHOOSE(Plan!$K$5,AA15,AB15,AC15,AD15),"") | T15: =IF(AND(ISNUMBER($D15),$D15>0),CHOOSE(Plan!$K$5,'Calc Smart'!K$10,'Calc Avalanche'!K$10,'Calc Snowball'!K$10,'Calc Cashflow'!K$10),"") | U15: =IF(NOT(AND(ISNUMBER($D15),$D15>0)),"",IF($H15="Not sure - ask lender",DATE(2199,12,1),IF($H15="Locked until a date",IF(N(+$J15)=0,DATE(2199,12,1),$J15),IF(AND($H15="Allowed with a fee",N(+$I15)>0,ISNUMBER($P15),N(+$I15)>=N(+$P15)),IF(N(+$J15)=0,DATE(2199,12,1),$J15),DATE(1900,1,1))))) | V15: =IF(NOT(AND(ISNUMBER($D15),$D15>0)),"",IF($AE15,"⚠ Cleared after the promo ends ("&CHOOSE(MONTH($K15),"Jan","Feb","Mar","Apr","May","Jun","Jul","Aug","Sep","Oct","Nov","Dec")&" "&YEAR($K15)&"): back-interest likely, not counted here. Try Smart.",IF($G15="Yes","Behind on payments: deal with this first",IF(AND($M15="Yes",N(+$K15)>Plan!$C$6),"Deferred interest: clear by "&CHOOSE(MONTH($K15),"Jan","Feb","Mar","Apr","May","Jun","Jul","Aug","Sep","Oct","Nov","Dec")&" "&YEAR($K15)&" or back-interest is added",IF($U15>Plan!$C$6,$Q15,CHOOSE(Plan!$K$5,IF(Plan!$K$7,"Frees up monthly money fastest","Highest APR among the rest"),"APR "&TEXT(N(+$E15),"0.0%"),"Balance "&TEXT($D15,"#,##0"),"Frees "&TEXT(N(+$F15),"#,##0")&"/month when cleared")))))) | W15: =IF(AND(ISNUMBER($D15),$D15>0),1000-N(+$E15)*100+ROW()/1000000,"") | X15: =IF(AND(ISNUMBER($D15),$D15>0),$D15+ROW()/1000000,"") | Y15: =IF(AND(ISNUMBER($D15),$D15>0),1000-IF(N(+$F15)>0,N(+$F15)/$D15,0)*100+ROW()/1000000,"") | Z15: =IF(AND(ISNUMBER($D15),$D15>0),IF($G15="Yes",0,IF(AND($M15="Yes",N(+$K15)>Plan!$C$6),1,2))*1000000+IF(IF($G15="Yes",0,IF(AND($M15="Yes",N(+$K15)>Plan!$C$6),1,2))=0,1000-IF(N(+$F15)>0,N(+$F15)/$D15,0)*100+ROW()/1000000,IF(IF($G15="Yes",0,IF(AND($M15="Yes",N(+$K15)>Plan!$C$6),1,2))=1,N(+$K15)/100,IF(Plan!$K$7,1000-IF(N(+$F15)>0,N(+$F15)/$D15,0)*100+ROW()/1000000,1000-N(+$E15)*100+ROW()/1000000))),"") | AA15: =IF(Z15="","",COUNTIF(Z$7:Z$18,"<"&Z15)+1) | AB15: =IF(W15="","",COUNTIF(W$7:W$18,"<"&W15)+1) | AC15: =IF(X15="","",COUNTIF(X$7:X$18,"<"&X15)+1) | AD15: =IF(Y15="","",COUNTIF(Y$7:Y$18,"<"&Y15)+1) | AE15: =AND(AND(ISNUMBER($D15),$D15>0),$M15="Yes",N(+$K15)>0,ISNUMBER($T15),N(+$T15)>=N(+$K15))
O16: =IF(AND(ISNUMBER($D16),$D16>0),$D16*N(+$E16)/12,"") | P16: =IF(NOT(AND(ISNUMBER($D16),$D16>0)),"",IF(N(+$F16)<=0,"No minimum",IF(N(+$F16)<=$D16*N(+$E16)/12,"Never at minimum",IF(N(+$E16)=0,0,N(+$F16)*NPER(N(+$E16)/12,-N(+$F16),$D16)-$D16)))) | Q16: =IF(NOT(AND(ISNUMBER($D16),$D16>0)),"",IF(AND(N(+$F16)>0,N(+$F16)<=$D16*N(+$E16)/12),"Minimum doesn't cover interest: pay more here",IF(N(+$F16)<=0,"Add the minimum payment",IF($H16="Not sure - ask lender","Ask your lender before paying extra",IF($H16="Locked until a date",IF(N(+$J16)=0,"Locked: add the unlock date","Locked until "&CHOOSE(MONTH($J16),"Jan","Feb","Mar","Apr","May","Jun","Jul","Aug","Sep","Oct","Nov","Dec")&" "&YEAR($J16)),IF($H16="Allowed with a fee",IF(N(+$I16)=0,"Add the fee amount (blank = no fee)",IF(NOT(ISNUMBER($P16)),"Fee is worth paying: minimums never clear this",IF(N(+$I16)<$P16,"Worth it: saves about "&TEXT($P16-$I16,"#,##0")&" after the fee","Wait: the fee is more than the interest you'd save"&IF(N(+$J16)>0," (until "&CHOOSE(MONTH($J16),"Jan","Feb","Mar","Apr","May","Jun","Jul","Aug","Sep","Oct","Nov","Dec")&" "&YEAR($J16)&")","")))),"OK to pay early")))))) | R16: =IF($U16="","",IF($U16<=Plan!$C$6,"Now",IF($U16>=DATE(2199,12,1),"Not yet",CHOOSE(MONTH($U16),"Jan","Feb","Mar","Apr","May","Jun","Jul","Aug","Sep","Oct","Nov","Dec")&" "&YEAR($U16)))) | S16: =IF(AND(ISNUMBER($D16),$D16>0),CHOOSE(Plan!$K$5,AA16,AB16,AC16,AD16),"") | T16: =IF(AND(ISNUMBER($D16),$D16>0),CHOOSE(Plan!$K$5,'Calc Smart'!L$10,'Calc Avalanche'!L$10,'Calc Snowball'!L$10,'Calc Cashflow'!L$10),"") | U16: =IF(NOT(AND(ISNUMBER($D16),$D16>0)),"",IF($H16="Not sure - ask lender",DATE(2199,12,1),IF($H16="Locked until a date",IF(N(+$J16)=0,DATE(2199,12,1),$J16),IF(AND($H16="Allowed with a fee",N(+$I16)>0,ISNUMBER($P16),N(+$I16)>=N(+$P16)),IF(N(+$J16)=0,DATE(2199,12,1),$J16),DATE(1900,1,1))))) | V16: =IF(NOT(AND(ISNUMBER($D16),$D16>0)),"",IF($AE16,"⚠ Cleared after the promo ends ("&CHOOSE(MONTH($K16),"Jan","Feb","Mar","Apr","May","Jun","Jul","Aug","Sep","Oct","Nov","Dec")&" "&YEAR($K16)&"): back-interest likely, not counted here. Try Smart.",IF($G16="Yes","Behind on payments: deal with this first",IF(AND($M16="Yes",N(+$K16)>Plan!$C$6),"Deferred interest: clear by "&CHOOSE(MONTH($K16),"Jan","Feb","Mar","Apr","May","Jun","Jul","Aug","Sep","Oct","Nov","Dec")&" "&YEAR($K16)&" or back-interest is added",IF($U16>Plan!$C$6,$Q16,CHOOSE(Plan!$K$5,IF(Plan!$K$7,"Frees up monthly money fastest","Highest APR among the rest"),"APR "&TEXT(N(+$E16),"0.0%"),"Balance "&TEXT($D16,"#,##0"),"Frees "&TEXT(N(+$F16),"#,##0")&"/month when cleared")))))) | W16: =IF(AND(ISNUMBER($D16),$D16>0),1000-N(+$E16)*100+ROW()/1000000,"") | X16: =IF(AND(ISNUMBER($D16),$D16>0),$D16+ROW()/1000000,"") | Y16: =IF(AND(ISNUMBER($D16),$D16>0),1000-IF(N(+$F16)>0,N(+$F16)/$D16,0)*100+ROW()/1000000,"") | Z16: =IF(AND(ISNUMBER($D16),$D16>0),IF($G16="Yes",0,IF(AND($M16="Yes",N(+$K16)>Plan!$C$6),1,2))*1000000+IF(IF($G16="Yes",0,IF(AND($M16="Yes",N(+$K16)>Plan!$C$6),1,2))=0,1000-IF(N(+$F16)>0,N(+$F16)/$D16,0)*100+ROW()/1000000,IF(IF($G16="Yes",0,IF(AND($M16="Yes",N(+$K16)>Plan!$C$6),1,2))=1,N(+$K16)/100,IF(Plan!$K$7,1000-IF(N(+$F16)>0,N(+$F16)/$D16,0)*100+ROW()/1000000,1000-N(+$E16)*100+ROW()/1000000))),"") | AA16: =IF(Z16="","",COUNTIF(Z$7:Z$18,"<"&Z16)+1) | AB16: =IF(W16="","",COUNTIF(W$7:W$18,"<"&W16)+1) | AC16: =IF(X16="","",COUNTIF(X$7:X$18,"<"&X16)+1) | AD16: =IF(Y16="","",COUNTIF(Y$7:Y$18,"<"&Y16)+1) | AE16: =AND(AND(ISNUMBER($D16),$D16>0),$M16="Yes",N(+$K16)>0,ISNUMBER($T16),N(+$T16)>=N(+$K16))
O17: =IF(AND(ISNUMBER($D17),$D17>0),$D17*N(+$E17)/12,"") | P17: =IF(NOT(AND(ISNUMBER($D17),$D17>0)),"",IF(N(+$F17)<=0,"No minimum",IF(N(+$F17)<=$D17*N(+$E17)/12,"Never at minimum",IF(N(+$E17)=0,0,N(+$F17)*NPER(N(+$E17)/12,-N(+$F17),$D17)-$D17)))) | Q17: =IF(NOT(AND(ISNUMBER($D17),$D17>0)),"",IF(AND(N(+$F17)>0,N(+$F17)<=$D17*N(+$E17)/12),"Minimum doesn't cover interest: pay more here",IF(N(+$F17)<=0,"Add the minimum payment",IF($H17="Not sure - ask lender","Ask your lender before paying extra",IF($H17="Locked until a date",IF(N(+$J17)=0,"Locked: add the unlock date","Locked until "&CHOOSE(MONTH($J17),"Jan","Feb","Mar","Apr","May","Jun","Jul","Aug","Sep","Oct","Nov","Dec")&" "&YEAR($J17)),IF($H17="Allowed with a fee",IF(N(+$I17)=0,"Add the fee amount (blank = no fee)",IF(NOT(ISNUMBER($P17)),"Fee is worth paying: minimums never clear this",IF(N(+$I17)<$P17,"Worth it: saves about "&TEXT($P17-$I17,"#,##0")&" after the fee","Wait: the fee is more than the interest you'd save"&IF(N(+$J17)>0," (until "&CHOOSE(MONTH($J17),"Jan","Feb","Mar","Apr","May","Jun","Jul","Aug","Sep","Oct","Nov","Dec")&" "&YEAR($J17)&")","")))),"OK to pay early")))))) | R17: =IF($U17="","",IF($U17<=Plan!$C$6,"Now",IF($U17>=DATE(2199,12,1),"Not yet",CHOOSE(MONTH($U17),"Jan","Feb","Mar","Apr","May","Jun","Jul","Aug","Sep","Oct","Nov","Dec")&" "&YEAR($U17)))) | S17: =IF(AND(ISNUMBER($D17),$D17>0),CHOOSE(Plan!$K$5,AA17,AB17,AC17,AD17),"") | T17: =IF(AND(ISNUMBER($D17),$D17>0),CHOOSE(Plan!$K$5,'Calc Smart'!M$10,'Calc Avalanche'!M$10,'Calc Snowball'!M$10,'Calc Cashflow'!M$10),"") | U17: =IF(NOT(AND(ISNUMBER($D17),$D17>0)),"",IF($H17="Not sure - ask lender",DATE(2199,12,1),IF($H17="Locked until a date",IF(N(+$J17)=0,DATE(2199,12,1),$J17),IF(AND($H17="Allowed with a fee",N(+$I17)>0,ISNUMBER($P17),N(+$I17)>=N(+$P17)),IF(N(+$J17)=0,DATE(2199,12,1),$J17),DATE(1900,1,1))))) | V17: =IF(NOT(AND(ISNUMBER($D17),$D17>0)),"",IF($AE17,"⚠ Cleared after the promo ends ("&CHOOSE(MONTH($K17),"Jan","Feb","Mar","Apr","May","Jun","Jul","Aug","Sep","Oct","Nov","Dec")&" "&YEAR($K17)&"): back-interest likely, not counted here. Try Smart.",IF($G17="Yes","Behind on payments: deal with this first",IF(AND($M17="Yes",N(+$K17)>Plan!$C$6),"Deferred interest: clear by "&CHOOSE(MONTH($K17),"Jan","Feb","Mar","Apr","May","Jun","Jul","Aug","Sep","Oct","Nov","Dec")&" "&YEAR($K17)&" or back-interest is added",IF($U17>Plan!$C$6,$Q17,CHOOSE(Plan!$K$5,IF(Plan!$K$7,"Frees up monthly money fastest","Highest APR among the rest"),"APR "&TEXT(N(+$E17),"0.0%"),"Balance "&TEXT($D17,"#,##0"),"Frees "&TEXT(N(+$F17),"#,##0")&"/month when cleared")))))) | W17: =IF(AND(ISNUMBER($D17),$D17>0),1000-N(+$E17)*100+ROW()/1000000,"") | X17: =IF(AND(ISNUMBER($D17),$D17>0),$D17+ROW()/1000000,"") | Y17: =IF(AND(ISNUMBER($D17),$D17>0),1000-IF(N(+$F17)>0,N(+$F17)/$D17,0)*100+ROW()/1000000,"") | Z17: =IF(AND(ISNUMBER($D17),$D17>0),IF($G17="Yes",0,IF(AND($M17="Yes",N(+$K17)>Plan!$C$6),1,2))*1000000+IF(IF($G17="Yes",0,IF(AND($M17="Yes",N(+$K17)>Plan!$C$6),1,2))=0,1000-IF(N(+$F17)>0,N(+$F17)/$D17,0)*100+ROW()/1000000,IF(IF($G17="Yes",0,IF(AND($M17="Yes",N(+$K17)>Plan!$C$6),1,2))=1,N(+$K17)/100,IF(Plan!$K$7,1000-IF(N(+$F17)>0,N(+$F17)/$D17,0)*100+ROW()/1000000,1000-N(+$E17)*100+ROW()/1000000))),"") | AA17: =IF(Z17="","",COUNTIF(Z$7:Z$18,"<"&Z17)+1) | AB17: =IF(W17="","",COUNTIF(W$7:W$18,"<"&W17)+1) | AC17: =IF(X17="","",COUNTIF(X$7:X$18,"<"&X17)+1) | AD17: =IF(Y17="","",COUNTIF(Y$7:Y$18,"<"&Y17)+1) | AE17: =AND(AND(ISNUMBER($D17),$D17>0),$M17="Yes",N(+$K17)>0,ISNUMBER($T17),N(+$T17)>=N(+$K17))
O18: =IF(AND(ISNUMBER($D18),$D18>0),$D18*N(+$E18)/12,"") | P18: =IF(NOT(AND(ISNUMBER($D18),$D18>0)),"",IF(N(+$F18)<=0,"No minimum",IF(N(+$F18)<=$D18*N(+$E18)/12,"Never at minimum",IF(N(+$E18)=0,0,N(+$F18)*NPER(N(+$E18)/12,-N(+$F18),$D18)-$D18)))) | Q18: =IF(NOT(AND(ISNUMBER($D18),$D18>0)),"",IF(AND(N(+$F18)>0,N(+$F18)<=$D18*N(+$E18)/12),"Minimum doesn't cover interest: pay more here",IF(N(+$F18)<=0,"Add the minimum payment",IF($H18="Not sure - ask lender","Ask your lender before paying extra",IF($H18="Locked until a date",IF(N(+$J18)=0,"Locked: add the unlock date","Locked until "&CHOOSE(MONTH($J18),"Jan","Feb","Mar","Apr","May","Jun","Jul","Aug","Sep","Oct","Nov","Dec")&" "&YEAR($J18)),IF($H18="Allowed with a fee",IF(N(+$I18)=0,"Add the fee amount (blank = no fee)",IF(NOT(ISNUMBER($P18)),"Fee is worth paying: minimums never clear this",IF(N(+$I18)<$P18,"Worth it: saves about "&TEXT($P18-$I18,"#,##0")&" after the fee","Wait: the fee is more than the interest you'd save"&IF(N(+$J18)>0," (until "&CHOOSE(MONTH($J18),"Jan","Feb","Mar","Apr","May","Jun","Jul","Aug","Sep","Oct","Nov","Dec")&" "&YEAR($J18)&")","")))),"OK to pay early")))))) | R18: =IF($U18="","",IF($U18<=Plan!$C$6,"Now",IF($U18>=DATE(2199,12,1),"Not yet",CHOOSE(MONTH($U18),"Jan","Feb","Mar","Apr","May","Jun","Jul","Aug","Sep","Oct","Nov","Dec")&" "&YEAR($U18)))) | S18: =IF(AND(ISNUMBER($D18),$D18>0),CHOOSE(Plan!$K$5,AA18,AB18,AC18,AD18),"") | T18: =IF(AND(ISNUMBER($D18),$D18>0),CHOOSE(Plan!$K$5,'Calc Smart'!N$10,'Calc Avalanche'!N$10,'Calc Snowball'!N$10,'Calc Cashflow'!N$10),"") | U18: =IF(NOT(AND(ISNUMBER($D18),$D18>0)),"",IF($H18="Not sure - ask lender",DATE(2199,12,1),IF($H18="Locked until a date",IF(N(+$J18)=0,DATE(2199,12,1),$J18),IF(AND($H18="Allowed with a fee",N(+$I18)>0,ISNUMBER($P18),N(+$I18)>=N(+$P18)),IF(N(+$J18)=0,DATE(2199,12,1),$J18),DATE(1900,1,1))))) | V18: =IF(NOT(AND(ISNUMBER($D18),$D18>0)),"",IF($AE18,"⚠ Cleared after the promo ends ("&CHOOSE(MONTH($K18),"Jan","Feb","Mar","Apr","May","Jun","Jul","Aug","Sep","Oct","Nov","Dec")&" "&YEAR($K18)&"): back-interest likely, not counted here. Try Smart.",IF($G18="Yes","Behind on payments: deal with this first",IF(AND($M18="Yes",N(+$K18)>Plan!$C$6),"Deferred interest: clear by "&CHOOSE(MONTH($K18),"Jan","Feb","Mar","Apr","May","Jun","Jul","Aug","Sep","Oct","Nov","Dec")&" "&YEAR($K18)&" or back-interest is added",IF($U18>Plan!$C$6,$Q18,CHOOSE(Plan!$K$5,IF(Plan!$K$7,"Frees up monthly money fastest","Highest APR among the rest"),"APR "&TEXT(N(+$E18),"0.0%"),"Balance "&TEXT($D18,"#,##0"),"Frees "&TEXT(N(+$F18),"#,##0")&"/month when cleared")))))) | W18: =IF(AND(ISNUMBER($D18),$D18>0),1000-N(+$E18)*100+ROW()/1000000,"") | X18: =IF(AND(ISNUMBER($D18),$D18>0),$D18+ROW()/1000000,"") | Y18: =IF(AND(ISNUMBER($D18),$D18>0),1000-IF(N(+$F18)>0,N(+$F18)/$D18,0)*100+ROW()/1000000,"") | Z18: =IF(AND(ISNUMBER($D18),$D18>0),IF($G18="Yes",0,IF(AND($M18="Yes",N(+$K18)>Plan!$C$6),1,2))*1000000+IF(IF($G18="Yes",0,IF(AND($M18="Yes",N(+$K18)>Plan!$C$6),1,2))=0,1000-IF(N(+$F18)>0,N(+$F18)/$D18,0)*100+ROW()/1000000,IF(IF($G18="Yes",0,IF(AND($M18="Yes",N(+$K18)>Plan!$C$6),1,2))=1,N(+$K18)/100,IF(Plan!$K$7,1000-IF(N(+$F18)>0,N(+$F18)/$D18,0)*100+ROW()/1000000,1000-N(+$E18)*100+ROW()/1000000))),"") | AA18: =IF(Z18="","",COUNTIF(Z$7:Z$18,"<"&Z18)+1) | AB18: =IF(W18="","",COUNTIF(W$7:W$18,"<"&W18)+1) | AC18: =IF(X18="","",COUNTIF(X$7:X$18,"<"&X18)+1) | AD18: =IF(Y18="","",COUNTIF(Y$7:Y$18,"<"&Y18)+1) | AE18: =AND(AND(ISNUMBER($D18),$D18>0),$M18="Yes",N(+$K18)>0,ISNUMBER($T18),N(+$T18)>=N(+$K18))
B20: Rows marked (sample) are made up: overwrite or clear them. Up to 12 debts.

Sheet Schedule
B2: Month by month
B3: Your chosen order. Each column is one debt's balance at the end of the month.
F4: =IF('My Debts'!$B$7="","",'My Debts'!$B$7) | G4: =IF('My Debts'!$B$8="","",'My Debts'!$B$8) | H4: =IF('My Debts'!$B$9="","",'My Debts'!$B$9) | I4: =IF('My Debts'!$B$10="","",'My Debts'!$B$10) | J4: =IF('My Debts'!$B$11="","",'My Debts'!$B$11) | K4: =IF('My Debts'!$B$12="","",'My Debts'!$B$12) | L4: =IF('My Debts'!$B$13="","",'My Debts'!$B$13) | M4: =IF('My Debts'!$B$14="","",'My Debts'!$B$14) | N4: =IF('My Debts'!$B$15="","",'My Debts'!$B$15) | O4: =IF('My Debts'!$B$16="","",'My Debts'!$B$16) | P4: =IF('My Debts'!$B$17="","",'My Debts'!$B$17) | Q4: =IF('My Debts'!$B$18="","",'My Debts'!$B$18)
B5: MONTH | C5: PAID THIS MONTH | D5: TOTAL LEFT | E5: DEBTS LEFT | F5: DEBT 1 | G5: DEBT 2 | H5: DEBT 3 | I5: DEBT 4 | J5: DEBT 5 | K5: DEBT 6 | L5: DEBT 7 | M5: DEBT 8 | N5: DEBT 9 | O5: DEBT 10 | P5: DEBT 11 | Q5: DEBT 12
B6: =EDATE(Plan!$C$6,0) | C6: =CHOOSE(Plan!$K$5,'Calc Smart'!AE12,'Calc Avalanche'!AE12,'Calc Snowball'!AE12,'Calc Cashflow'!AE12) | D6: =CHOOSE(Plan!$K$5,'Calc Smart'!AD12,'Calc Avalanche'!AD12,'Calc Snowball'!AD12,'Calc Cashflow'!AD12) | E6: =CHOOSE(Plan!$K$5,COUNTIF('Calc Smart'!C12:N12,">0"),COUNTIF('Calc Avalanche'!C12:N12,">0"),COUNTIF('Calc Snowball'!C12:N12,">0"),COUNTIF('Calc Cashflow'!C12:N12,">0")) | F6: =CHOOSE(Plan!$K$5,'Calc Smart'!C12,'Calc Avalanche'!C12,'Calc Snowball'!C12,'Calc Cashflow'!C12) | G6: =CHOOSE(Plan!$K$5,'Calc Smart'!D12,'Calc Avalanche'!D12,'Calc Snowball'!D12,'Calc Cashflow'!D12) | H6: =CHOOSE(Plan!$K$5,'Calc Smart'!E12,'Calc Avalanche'!E12,'Calc Snowball'!E12,'Calc Cashflow'!E12) | I6: =CHOOSE(Plan!$K$5,'Calc Smart'!F12,'Calc Avalanche'!F12,'Calc Snowball'!F12,'Calc Cashflow'!F12) | J6: =CHOOSE(Plan!$K$5,'Calc Smart'!G12,'Calc Avalanche'!G12,'Calc Snowball'!G12,'Calc Cashflow'!G12) | K6: =CHOOSE(Plan!$K$5,'Calc Smart'!H12,'Calc Avalanche'!H12,'Calc Snowball'!H12,'Calc Cashflow'!H12) | L6: =CHOOSE(Plan!$K$5,'Calc Smart'!I12,'Calc Avalanche'!I12,'Calc Snowball'!I12,'Calc Cashflow'!I12) | M6: =CHOOSE(Plan!$K$5,'Calc Smart'!J12,'Calc Avalanche'!J12,'Calc Snowball'!J12,'Calc Cashflow'!J12) | ... Q6: =CHOOSE(Plan!$K$5,'Calc Smart'!N12,'Calc Avalanche'!N12,'Calc Snowball'!N12,'Calc Cashflow'!N12)
B7: =EDATE(Plan!$C$6,1) | C7: =CHOOSE(Plan!$K$5,'Calc Smart'!AE13,'Calc Avalanche'!AE13,'Calc Snowball'!AE13,'Calc Cashflow'!AE13) | D7: =CHOOSE(Plan!$K$5,'Calc Smart'!AD13,'Calc Avalanche'!AD13,'Calc Snowball'!AD13,'Calc Cashflow'!AD13) | E7: =CHOOSE(Plan!$K$5,COUNTIF('Calc Smart'!C13:N13,">0"),COUNTIF('Calc Avalanche'!C13:N13,">0"),COUNTIF('Calc Snowball'!C13:N13,">0"),COUNTIF('Calc Cashflow'!C13:N13,">0")) | F7: =CHOOSE(Plan!$K$5,'Calc Smart'!C13,'Calc Avalanche'!C13,'Calc Snowball'!C13,'Calc Cashflow'!C13) | G7: =CHOOSE(Plan!$K$5,'Calc Smart'!D13,'Calc Avalanche'!D13,'Calc Snowball'!D13,'Calc Cashflow'!D13) | H7: =CHOOSE(Plan!$K$5,'Calc Smart'!E13,'Calc Avalanche'!E13,'Calc Snowball'!E13,'Calc Cashflow'!E13) | I7: =CHOOSE(Plan!$K$5,'Calc Smart'!F13,'Calc Avalanche'!F13,'Calc Snowball'!F13,'Calc Cashflow'!F13) | J7: =CHOOSE(Plan!$K$5,'Calc Smart'!G13,'Calc Avalanche'!G13,'Calc Snowball'!G13,'Calc Cashflow'!G13) | K7: =CHOOSE(Plan!$K$5,'Calc Smart'!H13,'Calc Avalanche'!H13,'Calc Snowball'!H13,'Calc Cashflow'!H13) | L7: =CHOOSE(Plan!$K$5,'Calc Smart'!I13,'Calc Avalanche'!I13,'Calc Snowball'!I13,'Calc Cashflow'!I13) | M7: =CHOOSE(Plan!$K$5,'Calc Smart'!J13,'Calc Avalanche'!J13,'Calc Snowball'!J13,'Calc Cashflow'!J13) | ... Q7: =CHOOSE(Plan!$K$5,'Calc Smart'!N13,'Calc Avalanche'!N13,'Calc Snowball'!N13,'Calc Cashflow'!N13)
B8: =EDATE(Plan!$C$6,2) | C8: =CHOOSE(Plan!$K$5,'Calc Smart'!AE14,'Calc Avalanche'!AE14,'Calc Snowball'!AE14,'Calc Cashflow'!AE14) | D8: =CHOOSE(Plan!$K$5,'Calc Smart'!AD14,'Calc Avalanche'!AD14,'Calc Snowball'!AD14,'Calc Cashflow'!AD14) | E8: =CHOOSE(Plan!$K$5,COUNTIF('Calc Smart'!C14:N14,">0"),COUNTIF('Calc Avalanche'!C14:N14,">0"),COUNTIF('Calc Snowball'!C14:N14,">0"),COUNTIF('Calc Cashflow'!C14:N14,">0")) | F8: =CHOOSE(Plan!$K$5,'Calc Smart'!C14,'Calc Avalanche'!C14,'Calc Snowball'!C14,'Calc Cashflow'!C14) | G8: =CHOOSE(Plan!$K$5,'Calc Smart'!D14,'Calc Avalanche'!D14,'Calc Snowball'!D14,'Calc Cashflow'!D14) | H8: =CHOOSE(Plan!$K$5,'Calc Smart'!E14,'Calc Avalanche'!E14,'Calc Snowball'!E14,'Calc Cashflow'!E14) | I8: =CHOOSE(Plan!$K$5,'Calc Smart'!F14,'Calc Avalanche'!F14,'Calc Snowball'!F14,'Calc Cashflow'!F14) | J8: =CHOOSE(Plan!$K$5,'Calc Smart'!G14,'Calc Avalanche'!G14,'Calc Snowball'!G14,'Calc Cashflow'!G14) | K8: =CHOOSE(Plan!$K$5,'Calc Smart'!H14,'Calc Avalanche'!H14,'Calc Snowball'!H14,'Calc Cashflow'!H14) | L8: =CHOOSE(Plan!$K$5,'Calc Smart'!I14,'Calc Avalanche'!I14,'Calc Snowball'!I14,'Calc Cashflow'!I14) | M8: =CHOOSE(Plan!$K$5,'Calc Smart'!J14,'Calc Avalanche'!J14,'Calc Snowball'!J14,'Calc Cashflow'!J14) | ... Q8: =CHOOSE(Plan!$K$5,'Calc Smart'!N14,'Calc Avalanche'!N14,'Calc Snowball'!N14,'Calc Cashflow'!N14)
