Workbook

Sheet Dashboard
B2: HOLIDAY HIDDEN COST TRACKER | H2: TODAY
B3: Your gift budget, and what the holidays will still cost you in January. | H3: =Settings!$C$11
B5: HOLIDAY BUDGET | D5: SPENT ON GIFTS | F5: LEFT IN BUDGET | H5: GIFTS SORTED
B6: =Settings!$C$5 | D6: =SUM('Gift List'!$F$6:$F$55) | F6: =Settings!$C$5-SUM('Gift List'!$F$6:$F$55) | H6: =COUNTIF('Gift List'!$H$6:$H$55,"Bought")+COUNTIF('Gift List'!$H$6:$H$55,"Wrapped")+COUNTIF('Gift List'!$H$6:$H$55,"Given")&" of "&COUNTA('Gift List'!$B$6:$B$55)
B7: change it in Settings | D7: =IF(Settings!$C$5>0,TEXT(SUM('Gift List'!$F$6:$F$55)/Settings!$C$5,"0%")&" of your budget","") | F7: =IF(Settings!$C$5-SUM('Gift List'!$F$6:$F$55)<0,"over budget","still to spend") | H7: =COUNTIF('Gift List'!$H$6:$H$55,"Idea")&" still ideas · "&COUNTIF('Gift List'!$H$6:$H$55,"Given")&" given"
B9: ="DUE IN "&UPPER(TEXT(EDATE(Settings!$C$7,1),"mmmm")) | D9: ="DUE IN "&UPPER(TEXT(EDATE(Settings!$C$7,2),"mmmm")) | F9: HIGHEST REAL APR | H9: FREE TRIALS ENDING SOON
B10: ='Chart Data'!$C$6 | D10: ='Chart Data'!$C$7 | F10: =IF(COUNT('Holiday Payments'!$M$6:$M$25)=0,"",MAX('Holiday Payments'!$M$6:$M$25)) | H10: =COUNTIF('Free Trials'!$L$6:$L$25,"Cancel soon?")
B11: =TEXT('Chart Data'!$D$6,"0%")&" of monthly take-home · from holiday plans" | D11: =TEXT('Chart Data'!$D$7,"0%")&" of monthly take-home · from holiday plans" | F11: =IF(COUNT('Holiday Payments'!$M$6:$M$25)=0,"add a plan to see it",'Chart Data'!$B$22&" · extra cost "&TEXT(SUM('Holiday Payments'!$L$6:$L$25),"$#,##0")) | H11: =IF(COUNT('Free Trials'!$M$6:$M$25)=0,"no open free trials","first cancel-by: "&TEXT(Settings!$C$11+INT(SMALL('Free Trials'!$M$6:$M$25,1)),"mmm d"))
B13: HOLIDAY PAYMENTS · MONTH BY MONTH | F13: HOLIDAY PAYMENTS BY MONTH
B14: MONTH | C14: DUE | D14: SHARE OF INCOME | E14: RUNNING TOTAL
B15: ='Chart Data'!B5 | C15: ='Chart Data'!C5 | D15: ='Chart Data'!D5 | E15: =SUM('Chart Data'!$C$5:C5)
B16: ='Chart Data'!B6 | C16: ='Chart Data'!C6 | D16: ='Chart Data'!D6 | E16: =SUM('Chart Data'!$C$5:C6)
B17: ='Chart Data'!B7 | C17: ='Chart Data'!C7 | D17: ='Chart Data'!D7 | E17: =SUM('Chart Data'!$C$5:C7)
B18: ='Chart Data'!B8 | C18: ='Chart Data'!C8 | D18: ='Chart Data'!D8 | E18: =SUM('Chart Data'!$C$5:C8)
B19: ='Chart Data'!B9 | C19: ='Chart Data'!C9 | D19: ='Chart Data'!D9 | E19: =SUM('Chart Data'!$C$5:C9)
B21: FREE TRIALS · CANCEL BEFORE YOU'RE CHARGED
B22: FREE TRIAL | C22: THEN COSTS | D22: CANCEL BY | E22: DAYS LEFT
B23: =IFERROR(INDEX('Free Trials'!$B$6:$B$25,MATCH(SMALL('Free Trials'!$M$6:$M$25,1),'Free Trials'!$M$6:$M$25,0)),"") | C23: =IFERROR(INDEX('Free Trials'!$E$6:$E$25,MATCH(SMALL('Free Trials'!$M$6:$M$25,1),'Free Trials'!$M$6:$M$25,0)),"") | D23: =IFERROR(INDEX('Free Trials'!$H$6:$H$25,MATCH(SMALL('Free Trials'!$M$6:$M$25,1),'Free Trials'!$M$6:$M$25,0)),"") | E23: =IFERROR(INDEX('Free Trials'!$I$6:$I$25,MATCH(SMALL('Free Trials'!$M$6:$M$25,1),'Free Trials'!$M$6:$M$25,0)),"")
B24: =IFERROR(INDEX('Free Trials'!$B$6:$B$25,MATCH(SMALL('Free Trials'!$M$6:$M$25,2),'Free Trials'!$M$6:$M$25,0)),"") | C24: =IFERROR(INDEX('Free Trials'!$E$6:$E$25,MATCH(SMALL('Free Trials'!$M$6:$M$25,2),'Free Trials'!$M$6:$M$25,0)),"") | D24: =IFERROR(INDEX('Free Trials'!$H$6:$H$25,MATCH(SMALL('Free Trials'!$M$6:$M$25,2),'Free Trials'!$M$6:$M$25,0)),"") | E24: =IFERROR(INDEX('Free Trials'!$I$6:$I$25,MATCH(SMALL('Free Trials'!$M$6:$M$25,2),'Free Trials'!$M$6:$M$25,0)),"")
B25: =IFERROR(INDEX('Free Trials'!$B$6:$B$25,MATCH(SMALL('Free Trials'!$M$6:$M$25,3),'Free Trials'!$M$6:$M$25,0)),"") | C25: =IFERROR(INDEX('Free Trials'!$E$6:$E$25,MATCH(SMALL('Free Trials'!$M$6:$M$25,3),'Free Trials'!$M$6:$M$25,0)),"") | D25: =IFERROR(INDEX('Free Trials'!$H$6:$H$25,MATCH(SMALL('Free Trials'!$M$6:$M$25,3),'Free Trials'!$M$6:$M$25,0)),"") | E25: =IFERROR(INDEX('Free Trials'!$I$6:$I$25,MATCH(SMALL('Free Trials'!$M$6:$M$25,3),'Free Trials'!$M$6:$M$25,0)),"")
B26: =IFERROR(INDEX('Free Trials'!$B$6:$B$25,MATCH(SMALL('Free Trials'!$M$6:$M$25,4),'Free Trials'!$M$6:$M$25,0)),"") | C26: =IFERROR(INDEX('Free Trials'!$E$6:$E$25,MATCH(SMALL('Free Trials'!$M$6:$M$25,4),'Free Trials'!$M$6:$M$25,0)),"") | D26: =IFERROR(INDEX('Free Trials'!$H$6:$H$25,MATCH(SMALL('Free Trials'!$M$6:$M$25,4),'Free Trials'!$M$6:$M$25,0)),"") | E26: =IFERROR(INDEX('Free Trials'!$I$6:$I$25,MATCH(SMALL('Free Trials'!$M$6:$M$25,4),'Free Trials'!$M$6:$M$25,0)),"")
B28: PAYMENT PLANS · HIGHEST REAL APR FIRST
B29: PLAN | C29: REAL APR | D29: FLAG | E29: STILL TO PAY | F29: HOW YOU PAID FOR GIFTS
B30: ='Chart Data'!B22 | C30: ='Chart Data'!C22 | D30: ='Chart Data'!D22 | E30: ='Chart Data'!E22
B31: ='Chart Data'!B23 | C31: ='Chart Data'!C23 | D31: ='Chart Data'!D23 | E31: ='Chart Data'!E23
B32: ='Chart Data'!B24 | C32: ='Chart Data'!C24 | D32: ='Chart Data'!D24 | E32: ='Chart Data'!E24
B33: ='Chart Data'!B25 | C33: ='Chart Data'!C25 | D33: ='Chart Data'!D25 | E33: ='Chart Data'!E25
B34: ='Chart Data'!B26 | C34: ='Chart Data'!C26 | D34: ='Chart Data'!D26 | E34: ='Chart Data'!E26
B35: ='Chart Data'!B27 | C35: ='Chart Data'!C27 | D35: ='Chart Data'!D27 | E35: ='Chart Data'!E27
B37: STILL TO BUY
B38: RECIPIENT | C38: GIFT | D38: BUDGET | E38: RELATIONSHIP
B39: ='Chart Data'!B30 | C39: ='Chart Data'!C30 | D39: ='Chart Data'!D30 | E39: ='Chart Data'!E30
B40: ='Chart Data'!B31 | C40: ='Chart Data'!C31 | D40: ='Chart Data'!D31 | E40: ='Chart Data'!E31
B41: ='Chart Data'!B32 | C41: ='Chart Data'!C32 | D41: ='Chart Data'!D32 | E41: ='Chart Data'!E32
B42: ='Chart Data'!B33 | C42: ='Chart Data'!C33 | D42: ='Chart Data'!D33 | E42: ='Chart Data'!E33
B43: ='Chart Data'!B34 | C43: ='Chart Data'!C34 | D43: ='Chart Data'!D34 | E43: ='Chart Data'!E34
B45: WHAT THE FLAGS MEAN
B46: HIGH | C46: ="Real APR at or above "&TEXT(Settings!$C$8,"0%")&". The monthly price hides a real cost."
B47: CHECK | C47: ="Real APR at or above "&TEXT(Settings!$C$9,"0%")&". Worth a second look."
B48: OK | C48: ="Little or no extra cost. Still a bill to plan for."
...

Sheet How to Use
B2: How to use
B3: Ten minutes to set up.
B5: 1. Settings: enter your holiday budget, monthly take-home income and the first month you want to plan (usually December).
B6: 2. Gift List: one row per person. Gold-header columns are yours; berry-header columns calculate themselves.
B7: • Set Paid with. Gifts on Pay-in-4, Monthly BNPL or Store financing are marked 'On a plan'.
B8: 3. Holiday Payments: one row per payment plan (gifts, travel, anything bought on a plan this season).
B9: • Enter the price, the payment, how many payments, how often and the first payment date.
B10: • First payment taken at checkout (most pay-in-4)? Set '1st paid at checkout?' to Yes.
B11: • You get the real APR, the extra cost, and what each plan charges in each month.
B12: 4. Free Trials: one row per trial you start (Black Friday deals often come with one). Tick Cancelled? once you've cancelled.
B13: • Deal Check: before you buy a sale item, enter the sale price and the usual price (before the sale), tax, shipping and
B14: the plan if you'd pay on one. The verdict tells you if it's a real deal, a small one, or not a deal at all.
... B20: Estimates only. Not financial advice. Real APR is an estimate from your payment schedule and does not include fees charged separately.

Sheet Settings
B2: Settings
B3: Gold-header cells are yours to edit.
B4: SETTING | C4: VALUE | D4: WHAT IT DOES
B5: Holiday budget | C5: 1500 | D5: Everything you plan to spend on gifts this season.
B6: Monthly take-home income | C6: 4200 | D6: Income after tax, per month. Used for the share-of-income figures.
B7: First month to plan | C7: 46357 | D7: The month-by-month bill starts here and runs 5 months.
B8: High-cost APR (berry flag) | C8: 0.2 | D8: Any plan at or above this real APR is flagged HIGH.
B9: Check APR (gold flag) | C9: 0.1 | D9: At or above this real APR is flagged CHECK.
B10: Warn me this many days ahead | C10: 7 | D10: Free trials ending within this many days are highlighted.
B11: Today's date | C11: =TODAY() | D11: Updates automatically. Every date calculation uses it.
B13: RELATIONSHIP | C13: PAID WITH | D13: GIFT STATUS | E13: PLAN TYPE | F13: PAYS EVERY | G13: BILLING
B14: Family | C14: Cash / debit | D14: Idea | E14: Pay-in-4 | F14: 2 weeks | G14: Weekly | H14: Rename or add items here and the drop-downs follow.
B15: Partner | C15: Credit card | D15: Bought | E15: Monthly BNPL | F15: Month | G15: Monthly | H15: Keep the Paid with names Pay-in-4, Monthly BNPL and Store financing:
B16: Kids | C16: Pay-in-4 | D16: Wrapped | E16: Store financing | G16: Yearly | H16: the Gift List uses them to mark gifts that are on a payment plan.
B17: Friend | C17: Monthly BNPL | D17: Given | E17: Credit card plan
B18: Coworker | C18: Store financing | E18: Other
B19: Other | C19: Gift card
C20: Other

Sheet Gift List
B2: Gift List | H2: GOLD headers: you fill in · BERRY headers: calculated for you
B3: =COUNTA('Gift List'!$B$6:$B$55)&" gifts · spent "&TEXT(SUM('Gift List'!$F$6:$F$55),"$#,##0")&" of "&TEXT(Settings!$C$5,"$#,##0")&" · "&IF(Settings!$C$5-SUM('Gift List'!$F$6:$F$55)>=0,TEXT(Settings!$C$5-SUM('Gift List'!$F$6:$F$55),"$#,##0")&" left",TEXT(SUM('Gift List'!$F$6:$F$55)-Settings!$C$5,"$#,##0")&" over budget")&" · "&COUNTIF('Gift List'!$K$6:$K$55,"On a plan")&" on a payment plan"
B5: RECIPIENT | C5: RELATIONSHIP | D5: GIFT | E5: BUDGET | F5: ACTUAL COST | G5: PAID WITH | H5: STATUS | I5: WHERE / NOTES | J5: OVER / UNDER | K5: PAYMENT PLAN | L5: key
B6: Mom | C6: Family | D6: Cashmere scarf | E6: 80 | F6: 74 | G6: Credit card | H6: Bought | J6: =IF(AND(ISNUMBER($E6),ISNUMBER($F6)),$E6-$F6,"") | K6: =IF(OR($G6="Pay-in-4",$G6="Monthly BNPL",$G6="Store financing"),"On a plan","") | L6: =IF(AND($H6="Idea",ISNUMBER($E6)),$E6+ROW()/100000,"")
B7: Dad | C7: Family | D7: Smart watch | E7: 250 | F7: 279 | G7: Pay-in-4 | H7: Bought | I7: Black Friday deal | J7: =IF(AND(ISNUMBER($E7),ISNUMBER($F7)),$E7-$F7,"") | K7: =IF(OR($G7="Pay-in-4",$G7="Monthly BNPL",$G7="Store financing"),"On a plan","") | L7: =IF(AND($H7="Idea",ISNUMBER($E7)),$E7+ROW()/100000,"")
B8: Alex | C8: Partner | D8: 4K TV | E8: 600 | F8: 649 | G8: Store financing | H8: Bought | I8: 12 monthly payments | J8: =IF(AND(ISNUMBER($E8),ISNUMBER($F8)),$E8-$F8,"") | K8: =IF(OR($G8="Pay-in-4",$G8="Monthly BNPL",$G8="Store financing"),"On a plan","") | L8: =IF(AND($H8="Idea",ISNUMBER($E8)),$E8+ROW()/100000,"")
B9: Sam | C9: Kids | D9: Game console | E9: 450 | F9: 499 | G9: Monthly BNPL | H9: Wrapped | J9: =IF(AND(ISNUMBER($E9),ISNUMBER($F9)),$E9-$F9,"") | K9: =IF(OR($G9="Pay-in-4",$G9="Monthly BNPL",$G9="Store financing"),"On a plan","") | L9: =IF(AND($H9="Idea",ISNUMBER($E9)),$E9+ROW()/100000,"")
B10: Jordan | C10: Friend | D10: Concert tickets | E10: 120 | F10: 140 | G10: Credit card | H10: Bought | J10: =IF(AND(ISNUMBER($E10),ISNUMBER($F10)),$E10-$F10,"") | K10: =IF(OR($G10="Pay-in-4",$G10="Monthly BNPL",$G10="Store financing"),"On a plan","") | L10: =IF(AND($H10="Idea",ISNUMBER($E10)),$E10+ROW()/100000,"")
B11: Grandma | C11: Family | D11: Photo book | E11: 40 | F11: 38 | G11: Cash / debit | H11: Wrapped | J11: =IF(AND(ISNUMBER($E11),ISNUMBER($F11)),$E11-$F11,"") | K11: =IF(OR($G11="Pay-in-4",$G11="Monthly BNPL",$G11="Store financing"),"On a plan","") | L11: =IF(AND($H11="Idea",ISNUMBER($E11)),$E11+ROW()/100000,"")
B12: Office gift swap | C12: Coworker | D12: Candle set | E12: 25 | F12: 25 | G12: Cash / debit | H12: Given | I12: $25 limit | J12: =IF(AND(ISNUMBER($E12),ISNUMBER($F12)),$E12-$F12,"") | K12: =IF(OR($G12="Pay-in-4",$G12="Monthly BNPL",$G12="Store financing"),"On a plan","") | L12: =IF(AND($H12="Idea",ISNUMBER($E12)),$E12+ROW()/100000,"")
B13: Teacher | C13: Other | D13: Coffee gift card | E13: 30 | F13: 30 | G13: Gift card | H13: Bought | J13: =IF(AND(ISNUMBER($E13),ISNUMBER($F13)),$E13-$F13,"") | K13: =IF(OR($G13="Pay-in-4",$G13="Monthly BNPL",$G13="Store financing"),"On a plan","") | L13: =IF(AND($H13="Idea",ISNUMBER($E13)),$E13+ROW()/100000,"")
B14: Sister | C14: Family | D14: Skincare set | E14: 60 | H14: Idea | J14: =IF(AND(ISNUMBER($E14),ISNUMBER($F14)),$E14-$F14,"") | K14: =IF(OR($G14="Pay-in-4",$G14="Monthly BNPL",$G14="Store financing"),"On a plan","") | L14: =IF(AND($H14="Idea",ISNUMBER($E14)),$E14+ROW()/100000,"")
B15: Nephew | C15: Kids | D15: Building block set | E15: 60 | H15: Idea | J15: =IF(AND(ISNUMBER($E15),ISNUMBER($F15)),$E15-$F15,"") | K15: =IF(OR($G15="Pay-in-4",$G15="Monthly BNPL",$G15="Store financing"),"On a plan","") | L15: =IF(AND($H15="Idea",ISNUMBER($E15)),$E15+ROW()/100000,"")
J16: =IF(AND(ISNUMBER($E16),ISNUMBER($F16)),$E16-$F16,"") | K16: =IF(OR($G16="Pay-in-4",$G16="Monthly BNPL",$G16="Store financing"),"On a plan","") | L16: =IF(AND($H16="Idea",ISNUMBER($E16)),$E16+ROW()/100000,"")
J17: =IF(AND(ISNUMBER($E17),ISNUMBER($F17)),$E17-$F17,"") | K17: =IF(OR($G17="Pay-in-4",$G17="Monthly BNPL",$G17="Store financing"),"On a plan","") | L17: =IF(AND($H17="Idea",ISNUMBER($E17)),$E17+ROW()/100000,"")
J18: =IF(AND(ISNUMBER($E18),ISNUMBER($F18)),$E18-$F18,"") | K18: =IF(OR($G18="Pay-in-4",$G18="Monthly BNPL",$G18="Store financing"),"On a plan","") | L18: =IF(AND($H18="Idea",ISNUMBER($E18)),$E18+ROW()/100000,"")
J19: =IF(AND(ISNUMBER($E19),ISNUMBER($F19)),$E19-$F19,"") | K19: =IF(OR($G19="Pay-in-4",$G19="Monthly BNPL",$G19="Store financing"),"On a plan","") | L19: =IF(AND($H19="Idea",ISNUMBER($E19)),$E19+ROW()/100000,"")
J20: =IF(AND(ISNUMBER($E20),ISNUMBER($F20)),$E20-$F20,"") | K20: =IF(OR($G20="Pay-in-4",$G20="Monthly BNPL",$G20="Store financing"),"On a plan","") | L20: =IF(AND($H20="Idea",ISNUMBER($E20)),$E20+ROW()/100000,"")
J21: =IF(AND(ISNUMBER($E21),ISNUMBER($F21)),$E21-$F21,"") | K21: =IF(OR($G21="Pay-in-4",$G21="Monthly BNPL",$G21="Store financing"),"On a plan","") | L21: =IF(AND($H21="Idea",ISNUMBER($E21)),$E21+ROW()/100000,"")
J22: =IF(AND(ISNUMBER($E22),ISNUMBER($F22)),$E22-$F22,"") | K22: =IF(OR($G22="Pay-in-4",$G22="Monthly BNPL",$G22="Store financing"),"On a plan","") | L22: =IF(AND($H22="Idea",ISNUMBER($E22)),$E22+ROW()/100000,"")
J23: =IF(AND(ISNUMBER($E23),ISNUMBER($F23)),$E23-$F23,"") | K23: =IF(OR($G23="Pay-in-4",$G23="Monthly BNPL",$G23="Store financing"),"On a plan","") | L23: =IF(AND($H23="Idea",ISNUMBER($E23)),$E23+ROW()/100000,"")
J24: =IF(AND(ISNUMBER($E24),ISNUMBER($F24)),$E24-$F24,"") | K24: =IF(OR($G24="Pay-in-4",$G24="Monthly BNPL",$G24="Store financing"),"On a plan","") | L24: =IF(AND($H24="Idea",ISNUMBER($E24)),$E24+ROW()/100000,"")
J25: =IF(AND(ISNUMBER($E25),ISNUMBER($F25)),$E25-$F25,"") | K25: =IF(OR($G25="Pay-in-4",$G25="Monthly BNPL",$G25="Store financing"),"On a plan","") | L25: =IF(AND($H25="Idea",ISNUMBER($E25)),$E25+ROW()/100000,"")
J26: =IF(AND(ISNUMBER($E26),ISNUMBER($F26)),$E26-$F26,"") | K26: =IF(OR($G26="Pay-in-4",$G26="Monthly BNPL",$G26="Store financing"),"On a plan","") | L26: =IF(AND($H26="Idea",ISNUMBER($E26)),$E26+ROW()/100000,"")
J27: =IF(AND(ISNUMBER($E27),ISNUMBER($F27)),$E27-$F27,"") | K27: =IF(OR($G27="Pay-in-4",$G27="Monthly BNPL",$G27="Store financing"),"On a plan","") | L27: =IF(AND($H27="Idea",ISNUMBER($E27)),$E27+ROW()/100000,"")
... J55: =IF(AND(ISNUMBER($E55),ISNUMBER($F55)),$E55-$F55,"") | K55: =IF(OR($G55="Pay-in-4",$G55="Monthly BNPL",$G55="Store financing"),"On a plan","") | L55: =IF(AND($H55="Idea",ISNUMBER($E55)),$E55+ROW()/100000,"")

Sheet Holiday Payments
B2: Holiday Payments | N2: GOLD headers: you fill in · BERRY headers: calculated for you
B3: =COUNT('Holiday Payments'!$K$6:$K$25)&" plans · "&TEXT(SUM('Holiday Payments'!$P$6:$P$25),"$#,##0")&" still to pay · extra cost "&TEXT(SUM('Holiday Payments'!$L$6:$L$25),"$#,##0")&" · last payment "&IF(COUNT('Holiday Payments'!$N$6:$N$25)=0,"-",TEXT(MAX('Holiday Payments'!$N$6:$N$25),"mmm d, yyyy"))
B5: ITEM | C5: PLAN TYPE | D5: PRICE | E5: PAYMENT | F5: NUMBER OF PAYMENTS | G5: PAYS EVERY | H5: FIRST PAYMENT | I5: 1ST PAID AT CHECKOUT? | J5: STATED APR (IF KNOWN) | K5: TOTAL YOU'LL PAY | L5: EXTRA COST | M5: REAL APR | N5: LAST PAYMENT | O5: PAYMENTS LEFT | P5: STILL TO PAY | Q5: FLAG | R5: =UPPER(TEXT(EDATE(Settings!$C$7,0),"mmm yyyy")) | S5: =UPPER(TEXT(EDATE(Settings!$C$7,1),"mmm yyyy")) | T5: =UPPER(TEXT(EDATE(Settings!$C$7,2),"mmm yyyy")) | U5: =UPPER(TEXT(EDATE(Settings!$C$7,3),"mmm yyyy")) | V5: =UPPER(TEXT(EDATE(Settings!$C$7,4),"mmm yyyy")) | W5: key
B6: Smart watch | C6: Pay-in-4 | D6: 279 | E6: 69.75 | F6: 4 | G6: 2 weeks | H6: 46353 | I6: Yes | K6: =IF(AND($B6<>"",N($E6)>0,N($F6)>0),$E6*$F6,"") | L6: =IF(AND(ISNUMBER($K6),ISNUMBER($D6)),MAX(0,$K6-$D6),"") | M6: =IF(NOT(AND($B6<>"",N($E6)>0,N($F6)>0)),"",IF(ISNUMBER($J6),$J6,IF(NOT(ISNUMBER($D6)),"",IF($K6<=$D6+0.005,0,IFERROR(RATE($F6,-$E6,$D6,0,IF($I6="Yes",1,0))*IF($G6="2 weeks",26,12),""))))) | N6: =IF(NOT(AND(AND($B6<>"",N($E6)>0,N($F6)>0),ISNUMBER($H6))),"",IF($G6="2 weeks",$H6+14*($F6-1),EDATE($H6,$F6-1))) | O6: =IF(NOT(AND(AND($B6<>"",N($E6)>0,N($F6)>0),ISNUMBER($H6))),"",$F6-IF(Settings!$C$11<=$H6,0,MIN($F6,IF($G6="2 weeks",INT((Settings!$C$11-$H6-1)/14)+1,DATEDIF($H6,Settings!$C$11,"M")+IF(EDATE($H6,DATEDIF($H6,Settings!$C$11,"M"))<Settings!$C$11,1,0))))) | P6: =IF(ISNUMBER($O6),$O6*$E6,"") | Q6: =IF(NOT(ISNUMBER($M6)),"",IF($M6>=Settings!$C$8,"HIGH",IF($M6>=Settings!$C$9,"CHECK","OK"))) | R6: =IF(NOT(AND(AND($B6<>"",N($E6)>0,N($F6)>0),ISNUMBER($H6))),"",$E6*IF($G6="2 weeks",MAX(0,MIN($F6-1,INT((EOMONTH(Settings!$C$7,0)-$H6)/14))-MAX(0,-INT(-(EDATE(Settings!$C$7,0)-$H6)/14))+1),IF(AND(((YEAR(EDATE(Settings!$C$7,0))*12+MONTH(EDATE(Settings!$C$7,0)))-(YEAR($H6)*12+MONTH($H6)))>=0,((YEAR(EDATE(Settings!$C$7,0))*12+MONTH(EDATE(Settings!$C$7,0)))-(YEAR($H6)*12+MONTH($H6)))<$F6),1,0))) | S6: =IF(NOT(AND(AND($B6<>"",N($E6)>0,N($F6)>0),ISNUMBER($H6))),"",$E6*IF($G6="2 weeks",MAX(0,MIN($F6-1,INT((EOMONTH(Settings!$C$7,1)-$H6)/14))-MAX(0,-INT(-(EDATE(Settings!$C$7,1)-$H6)/14))+1),IF(AND(((YEAR(EDATE(Settings!$C$7,1))*12+MONTH(EDATE(Settings!$C$7,1)))-(YEAR($H6)*12+MONTH($H6)))>=0,((YEAR(EDATE(Settings!$C$7,1))*12+MONTH(EDATE(Settings!$C$7,1)))-(YEAR($H6)*12+MONTH($H6)))<$F6),1,0))) | T6: =IF(NOT(AND(AND($B6<>"",N($E6)>0,N($F6)>0),ISNUMBER($H6))),"",$E6*IF($G6="2 weeks",MAX(0,MIN($F6-1,INT((EOMONTH(Settings!$C$7,2)-$H6)/14))-MAX(0,-INT(-(EDATE(Settings!$C$7,2)-$H6)/14))+1),IF(AND(((YEAR(EDATE(Settings!$C$7,2))*12+MONTH(EDATE(Settings!$C$7,2)))-(YEAR($H6)*12+MONTH($H6)))>=0,((YEAR(EDATE(Settings!$C$7,2))*12+MONTH(EDATE(Settings!$C$7,2)))-(YEAR($H6)*12+MONTH($H6)))<$F6),1,0))) | U6: =IF(NOT(AND(AND($B6<>"",N($E6)>0,N($F6)>0),ISNUMBER($H6))),"",$E6*IF($G6="2 weeks",MAX(0,MIN($F6-1,INT((EOMONTH(Settings!$C$7,3)-$H6)/14))-MAX(0,-INT(-(EDATE(Settings!$C$7,3)-$H6)/14))+1),IF(AND(((YEAR(EDATE(Settings!$C$7,3))*12+MONTH(EDATE(Settings!$C$7,3)))-(YEAR($H6)*12+MONTH($H6)))>=0,((YEAR(EDATE(Settings!$C$7,3))*12+MONTH(EDATE(Settings!$C$7,3)))-(YEAR($H6)*12+MONTH($H6)))<$F6),1,0))) | V6: =IF(NOT(AND(AND($B6<>"",N($E6)>0,N($F6)>0),ISNUMBER($H6))),"",$E6*IF($G6="2 weeks",MAX(0,MIN($F6-1,INT((EOMONTH(Settings!$C$7,4)-$H6)/14))-MAX(0,-INT(-(EDATE(Settings!$C$7,4)-$H6)/14))+1),IF(AND(((YEAR(EDATE(Settings!$C$7,4))*12+MONTH(EDATE(Settings!$C$7,4)))-(YEAR($H6)*12+MONTH($H6)))>=0,((YEAR(EDATE(Settings!$C$7,4))*12+MONTH(EDATE(Settings!$C$7,4)))-(YEAR($H6)*12+MONTH($H6)))<$F6),1,0))) | W6: =IF(ISNUMBER($M6),$M6+ROW()/10000000,"")
B7: Flights home | C7: Pay-in-4 | D7: 420 | E7: 105 | F7: 4 | G7: 2 weeks | H7: 46371 | I7: Yes | K7: =IF(AND($B7<>"",N($E7)>0,N($F7)>0),$E7*$F7,"") | L7: =IF(AND(ISNUMBER($K7),ISNUMBER($D7)),MAX(0,$K7-$D7),"") | M7: =IF(NOT(AND($B7<>"",N($E7)>0,N($F7)>0)),"",IF(ISNUMBER($J7),$J7,IF(NOT(ISNUMBER($D7)),"",IF($K7<=$D7+0.005,0,IFERROR(RATE($F7,-$E7,$D7,0,IF($I7="Yes",1,0))*IF($G7="2 weeks",26,12),""))))) | N7: =IF(NOT(AND(AND($B7<>"",N($E7)>0,N($F7)>0),ISNUMBER($H7))),"",IF($G7="2 weeks",$H7+14*($F7-1),EDATE($H7,$F7-1))) | O7: =IF(NOT(AND(AND($B7<>"",N($E7)>0,N($F7)>0),ISNUMBER($H7))),"",$F7-IF(Settings!$C$11<=$H7,0,MIN($F7,IF($G7="2 weeks",INT((Settings!$C$11-$H7-1)/14)+1,DATEDIF($H7,Settings!$C$11,"M")+IF(EDATE($H7,DATEDIF($H7,Settings!$C$11,"M"))<Settings!$C$11,1,0))))) | P7: =IF(ISNUMBER($O7),$O7*$E7,"") | Q7: =IF(NOT(ISNUMBER($M7)),"",IF($M7>=Settings!$C$8,"HIGH",IF($M7>=Settings!$C$9,"CHECK","OK"))) | R7: =IF(NOT(AND(AND($B7<>"",N($E7)>0,N($F7)>0),ISNUMBER($H7))),"",$E7*IF($G7="2 weeks",MAX(0,MIN($F7-1,INT((EOMONTH(Settings!$C$7,0)-$H7)/14))-MAX(0,-INT(-(EDATE(Settings!$C$7,0)-$H7)/14))+1),IF(AND(((YEAR(EDATE(Settings!$C$7,0))*12+MONTH(EDATE(Settings!$C$7,0)))-(YEAR($H7)*12+MONTH($H7)))>=0,((YEAR(EDATE(Settings!$C$7,0))*12+MONTH(EDATE(Settings!$C$7,0)))-(YEAR($H7)*12+MONTH($H7)))<$F7),1,0))) | S7: =IF(NOT(AND(AND($B7<>"",N($E7)>0,N($F7)>0),ISNUMBER($H7))),"",$E7*IF($G7="2 weeks",MAX(0,MIN($F7-1,INT((EOMONTH(Settings!$C$7,1)-$H7)/14))-MAX(0,-INT(-(EDATE(Settings!$C$7,1)-$H7)/14))+1),IF(AND(((YEAR(EDATE(Settings!$C$7,1))*12+MONTH(EDATE(Settings!$C$7,1)))-(YEAR($H7)*12+MONTH($H7)))>=0,((YEAR(EDATE(Settings!$C$7,1))*12+MONTH(EDATE(Settings!$C$7,1)))-(YEAR($H7)*12+MONTH($H7)))<$F7),1,0))) | T7: =IF(NOT(AND(AND($B7<>"",N($E7)>0,N($F7)>0),ISNUMBER($H7))),"",$E7*IF($G7="2 weeks",MAX(0,MIN($F7-1,INT((EOMONTH(Settings!$C$7,2)-$H7)/14))-MAX(0,-INT(-(EDATE(Settings!$C$7,2)-$H7)/14))+1),IF(AND(((YEAR(EDATE(Settings!$C$7,2))*12+MONTH(EDATE(Settings!$C$7,2)))-(YEAR($H7)*12+MONTH($H7)))>=0,((YEAR(EDATE(Settings!$C$7,2))*12+MONTH(EDATE(Settings!$C$7,2)))-(YEAR($H7)*12+MONTH($H7)))<$F7),1,0))) | U7: =IF(NOT(AND(AND($B7<>"",N($E7)>0,N($F7)>0),ISNUMBER($H7))),"",$E7*IF($G7="2 weeks",MAX(0,MIN($F7-1,INT((EOMONTH(Settings!$C$7,3)-$H7)/14))-MAX(0,-INT(-(EDATE(Settings!$C$7,3)-$H7)/14))+1),IF(AND(((YEAR(EDATE(Settings!$C$7,3))*12+MONTH(EDATE(Settings!$C$7,3)))-(YEAR($H7)*12+MONTH($H7)))>=0,((YEAR(EDATE(Settings!$C$7,3))*12+MONTH(EDATE(Settings!$C$7,3)))-(YEAR($H7)*12+MONTH($H7)))<$F7),1,0))) | V7: =IF(NOT(AND(AND($B7<>"",N($E7)>0,N($F7)>0),ISNUMBER($H7))),"",$E7*IF($G7="2 weeks",MAX(0,MIN($F7-1,INT((EOMONTH(Settings!$C$7,4)-$H7)/14))-MAX(0,-INT(-(EDATE(Settings!$C$7,4)-$H7)/14))+1),IF(AND(((YEAR(EDATE(Settings!$C$7,4))*12+MONTH(EDATE(Settings!$C$7,4)))-(YEAR($H7)*12+MONTH($H7)))>=0,((YEAR(EDATE(Settings!$C$7,4))*12+MONTH(EDATE(Settings!$C$7,4)))-(YEAR($H7)*12+MONTH($H7)))<$F7),1,0))) | W7: =IF(ISNUMBER($M7),$M7+ROW()/10000000,"")
B8: 4K TV | C8: Store financing | D8: 649 | E8: 59 | F8: 12 | G8: Month | H8: 46383 | I8: No | K8: =IF(AND($B8<>"",N($E8)>0,N($F8)>0),$E8*$F8,"") | L8: =IF(AND(ISNUMBER($K8),ISNUMBER($D8)),MAX(0,$K8-$D8),"") | M8: =IF(NOT(AND($B8<>"",N($E8)>0,N($F8)>0)),"",IF(ISNUMBER($J8),$J8,IF(NOT(ISNUMBER($D8)),"",IF($K8<=$D8+0.005,0,IFERROR(RATE($F8,-$E8,$D8,0,IF($I8="Yes",1,0))*IF($G8="2 weeks",26,12),""))))) | N8: =IF(NOT(AND(AND($B8<>"",N($E8)>0,N($F8)>0),ISNUMBER($H8))),"",IF($G8="2 weeks",$H8+14*($F8-1),EDATE($H8,$F8-1))) | O8: =IF(NOT(AND(AND($B8<>"",N($E8)>0,N($F8)>0),ISNUMBER($H8))),"",$F8-IF(Settings!$C$11<=$H8,0,MIN($F8,IF($G8="2 weeks",INT((Settings!$C$11-$H8-1)/14)+1,DATEDIF($H8,Settings!$C$11,"M")+IF(EDATE($H8,DATEDIF($H8,Settings!$C$11,"M"))<Settings!$C$11,1,0))))) | P8: =IF(ISNUMBER($O8),$O8*$E8,"") | Q8: =IF(NOT(ISNUMBER($M8)),"",IF($M8>=Settings!$C$8,"HIGH",IF($M8>=Settings!$C$9,"CHECK","OK"))) | R8: =IF(NOT(AND(AND($B8<>"",N($E8)>0,N($F8)>0),ISNUMBER($H8))),"",$E8*IF($G8="2 weeks",MAX(0,MIN($F8-1,INT((EOMONTH(Settings!$C$7,0)-$H8)/14))-MAX(0,-INT(-(EDATE(Settings!$C$7,0)-$H8)/14))+1),IF(AND(((YEAR(EDATE(Settings!$C$7,0))*12+MONTH(EDATE(Settings!$C$7,0)))-(YEAR($H8)*12+MONTH($H8)))>=0,((YEAR(EDATE(Settings!$C$7,0))*12+MONTH(EDATE(Settings!$C$7,0)))-(YEAR($H8)*12+MONTH($H8)))<$F8),1,0))) | S8: =IF(NOT(AND(AND($B8<>"",N($E8)>0,N($F8)>0),ISNUMBER($H8))),"",$E8*IF($G8="2 weeks",MAX(0,MIN($F8-1,INT((EOMONTH(Settings!$C$7,1)-$H8)/14))-MAX(0,-INT(-(EDATE(Settings!$C$7,1)-$H8)/14))+1),IF(AND(((YEAR(EDATE(Settings!$C$7,1))*12+MONTH(EDATE(Settings!$C$7,1)))-(YEAR($H8)*12+MONTH($H8)))>=0,((YEAR(EDATE(Settings!$C$7,1))*12+MONTH(EDATE(Settings!$C$7,1)))-(YEAR($H8)*12+MONTH($H8)))<$F8),1,0))) | T8: =IF(NOT(AND(AND($B8<>"",N($E8)>0,N($F8)>0),ISNUMBER($H8))),"",$E8*IF($G8="2 weeks",MAX(0,MIN($F8-1,INT((EOMONTH(Settings!$C$7,2)-$H8)/14))-MAX(0,-INT(-(EDATE(Settings!$C$7,2)-$H8)/14))+1),IF(AND(((YEAR(EDATE(Settings!$C$7,2))*12+MONTH(EDATE(Settings!$C$7,2)))-(YEAR($H8)*12+MONTH($H8)))>=0,((YEAR(EDATE(Settings!$C$7,2))*12+MONTH(EDATE(Settings!$C$7,2)))-(YEAR($H8)*12+MONTH($H8)))<$F8),1,0))) | U8: =IF(NOT(AND(AND($B8<>"",N($E8)>0,N($F8)>0),ISNUMBER($H8))),"",$E8*IF($G8="2 weeks",MAX(0,MIN($F8-1,INT((EOMONTH(Settings!$C$7,3)-$H8)/14))-MAX(0,-INT(-(EDATE(Settings!$C$7,3)-$H8)/14))+1),IF(AND(((YEAR(EDATE(Settings!$C$7,3))*12+MONTH(EDATE(Settings!$C$7,3)))-(YEAR($H8)*12+MONTH($H8)))>=0,((YEAR(EDATE(Settings!$C$7,3))*12+MONTH(EDATE(Settings!$C$7,3)))-(YEAR($H8)*12+MONTH($H8)))<$F8),1,0))) | V8: =IF(NOT(AND(AND($B8<>"",N($E8)>0,N($F8)>0),ISNUMBER($H8))),"",$E8*IF($G8="2 weeks",MAX(0,MIN($F8-1,INT((EOMONTH(Settings!$C$7,4)-$H8)/14))-MAX(0,-INT(-(EDATE(Settings!$C$7,4)-$H8)/14))+1),IF(AND(((YEAR(EDATE(Settings!$C$7,4))*12+MONTH(EDATE(Settings!$C$7,4)))-(YEAR($H8)*12+MONTH($H8)))>=0,((YEAR(EDATE(Settings!$C$7,4))*12+MONTH(EDATE(Settings!$C$7,4)))-(YEAR($H8)*12+MONTH($H8)))<$F8),1,0))) | W8: =IF(ISNUMBER($M8),$M8+ROW()/10000000,"")
B9: Game console | C9: Monthly BNPL | D9: 499 | E9: 89.5 | F9: 6 | G9: Month | H9: 46383 | I9: No | K9: =IF(AND($B9<>"",N($E9)>0,N($F9)>0),$E9*$F9,"") | L9: =IF(AND(ISNUMBER($K9),ISNUMBER($D9)),MAX(0,$K9-$D9),"") | M9: =IF(NOT(AND($B9<>"",N($E9)>0,N($F9)>0)),"",IF(ISNUMBER($J9),$J9,IF(NOT(ISNUMBER($D9)),"",IF($K9<=$D9+0.005,0,IFERROR(RATE($F9,-$E9,$D9,0,IF($I9="Yes",1,0))*IF($G9="2 weeks",26,12),""))))) | N9: =IF(NOT(AND(AND($B9<>"",N($E9)>0,N($F9)>0),ISNUMBER($H9))),"",IF($G9="2 weeks",$H9+14*($F9-1),EDATE($H9,$F9-1))) | O9: =IF(NOT(AND(AND($B9<>"",N($E9)>0,N($F9)>0),ISNUMBER($H9))),"",$F9-IF(Settings!$C$11<=$H9,0,MIN($F9,IF($G9="2 weeks",INT((Settings!$C$11-$H9-1)/14)+1,DATEDIF($H9,Settings!$C$11,"M")+IF(EDATE($H9,DATEDIF($H9,Settings!$C$11,"M"))<Settings!$C$11,1,0))))) | P9: =IF(ISNUMBER($O9),$O9*$E9,"") | Q9: =IF(NOT(ISNUMBER($M9)),"",IF($M9>=Settings!$C$8,"HIGH",IF($M9>=Settings!$C$9,"CHECK","OK"))) | R9: =IF(NOT(AND(AND($B9<>"",N($E9)>0,N($F9)>0),ISNUMBER($H9))),"",$E9*IF($G9="2 weeks",MAX(0,MIN($F9-1,INT((EOMONTH(Settings!$C$7,0)-$H9)/14))-MAX(0,-INT(-(EDATE(Settings!$C$7,0)-$H9)/14))+1),IF(AND(((YEAR(EDATE(Settings!$C$7,0))*12+MONTH(EDATE(Settings!$C$7,0)))-(YEAR($H9)*12+MONTH($H9)))>=0,((YEAR(EDATE(Settings!$C$7,0))*12+MONTH(EDATE(Settings!$C$7,0)))-(YEAR($H9)*12+MONTH($H9)))<$F9),1,0))) | S9: =IF(NOT(AND(AND($B9<>"",N($E9)>0,N($F9)>0),ISNUMBER($H9))),"",$E9*IF($G9="2 weeks",MAX(0,MIN($F9-1,INT((EOMONTH(Settings!$C$7,1)-$H9)/14))-MAX(0,-INT(-(EDATE(Settings!$C$7,1)-$H9)/14))+1),IF(AND(((YEAR(EDATE(Settings!$C$7,1))*12+MONTH(EDATE(Settings!$C$7,1)))-(YEAR($H9)*12+MONTH($H9)))>=0,((YEAR(EDATE(Settings!$C$7,1))*12+MONTH(EDATE(Settings!$C$7,1)))-(YEAR($H9)*12+MONTH($H9)))<$F9),1,0))) | T9: =IF(NOT(AND(AND($B9<>"",N($E9)>0,N($F9)>0),ISNUMBER($H9))),"",$E9*IF($G9="2 weeks",MAX(0,MIN($F9-1,INT((EOMONTH(Settings!$C$7,2)-$H9)/14))-MAX(0,-INT(-(EDATE(Settings!$C$7,2)-$H9)/14))+1),IF(AND(((YEAR(EDATE(Settings!$C$7,2))*12+MONTH(EDATE(Settings!$C$7,2)))-(YEAR($H9)*12+MONTH($H9)))>=0,((YEAR(EDATE(Settings!$C$7,2))*12+MONTH(EDATE(Settings!$C$7,2)))-(YEAR($H9)*12+MONTH($H9)))<$F9),1,0))) | U9: =IF(NOT(AND(AND($B9<>"",N($E9)>0,N($F9)>0),ISNUMBER($H9))),"",$E9*IF($G9="2 weeks",MAX(0,MIN($F9-1,INT((EOMONTH(Settings!$C$7,3)-$H9)/14))-MAX(0,-INT(-(EDATE(Settings!$C$7,3)-$H9)/14))+1),IF(AND(((YEAR(EDATE(Settings!$C$7,3))*12+MONTH(EDATE(Settings!$C$7,3)))-(YEAR($H9)*12+MONTH($H9)))>=0,((YEAR(EDATE(Settings!$C$7,3))*12+MONTH(EDATE(Settings!$C$7,3)))-(YEAR($H9)*12+MONTH($H9)))<$F9),1,0))) | V9: =IF(NOT(AND(AND($B9<>"",N($E9)>0,N($F9)>0),ISNUMBER($H9))),"",$E9*IF($G9="2 weeks",MAX(0,MIN($F9-1,INT((EOMONTH(Settings!$C$7,4)-$H9)/14))-MAX(0,-INT(-(EDATE(Settings!$C$7,4)-$H9)/14))+1),IF(AND(((YEAR(EDATE(Settings!$C$7,4))*12+MONTH(EDATE(Settings!$C$7,4)))-(YEAR($H9)*12+MONTH($H9)))>=0,((YEAR(EDATE(Settings!$C$7,4))*12+MONTH(EDATE(Settings!$C$7,4)))-(YEAR($H9)*12+MONTH($H9)))<$F9),1,0))) | W9: =IF(ISNUMBER($M9),$M9+ROW()/10000000,"")
K10: =IF(AND($B10<>"",N($E10)>0,N($F10)>0),$E10*$F10,"") | L10: =IF(AND(ISNUMBER($K10),ISNUMBER($D10)),MAX(0,$K10-$D10),"") | M10: =IF(NOT(AND($B10<>"",N($E10)>0,N($F10)>0)),"",IF(ISNUMBER($J10),$J10,IF(NOT(ISNUMBER($D10)),"",IF($K10<=$D10+0.005,0,IFERROR(RATE($F10,-$E10,$D10,0,IF($I10="Yes",1,0))*IF($G10="2 weeks",26,12),""))))) | N10: =IF(NOT(AND(AND($B10<>"",N($E10)>0,N($F10)>0),ISNUMBER($H10))),"",IF($G10="2 weeks",$H10+14*($F10-1),EDATE($H10,$F10-1))) | O10: =IF(NOT(AND(AND($B10<>"",N($E10)>0,N($F10)>0),ISNUMBER($H10))),"",$F10-IF(Settings!$C$11<=$H10,0,MIN($F10,IF($G10="2 weeks",INT((Settings!$C$11-$H10-1)/14)+1,DATEDIF($H10,Settings!$C$11,"M")+IF(EDATE($H10,DATEDIF($H10,Settings!$C$11,"M"))<Settings!$C$11,1,0))))) | P10: =IF(ISNUMBER($O10),$O10*$E10,"") | Q10: =IF(NOT(ISNUMBER($M10)),"",IF($M10>=Settings!$C$8,"HIGH",IF($M10>=Settings!$C$9,"CHECK","OK"))) | R10: =IF(NOT(AND(AND($B10<>"",N($E10)>0,N($F10)>0),ISNUMBER($H10))),"",$E10*IF($G10="2 weeks",MAX(0,MIN($F10-1,INT((EOMONTH(Settings!$C$7,0)-$H10)/14))-MAX(0,-INT(-(EDATE(Settings!$C$7,0)-$H10)/14))+1),IF(AND(((YEAR(EDATE(Settings!$C$7,0))*12+MONTH(EDATE(Settings!$C$7,0)))-(YEAR($H10)*12+MONTH($H10)))>=0,((YEAR(EDATE(Settings!$C$7,0))*12+MONTH(EDATE(Settings!$C$7,0)))-(YEAR($H10)*12+MONTH($H10)))<$F10),1,0))) | S10: =IF(NOT(AND(AND($B10<>"",N($E10)>0,N($F10)>0),ISNUMBER($H10))),"",$E10*IF($G10="2 weeks",MAX(0,MIN($F10-1,INT((EOMONTH(Settings!$C$7,1)-$H10)/14))-MAX(0,-INT(-(EDATE(Settings!$C$7,1)-$H10)/14))+1),IF(AND(((YEAR(EDATE(Settings!$C$7,1))*12+MONTH(EDATE(Settings!$C$7,1)))-(YEAR($H10)*12+MONTH($H10)))>=0,((YEAR(EDATE(Settings!$C$7,1))*12+MONTH(EDATE(Settings!$C$7,1)))-(YEAR($H10)*12+MONTH($H10)))<$F10),1,0))) | T10: =IF(NOT(AND(AND($B10<>"",N($E10)>0,N($F10)>0),ISNUMBER($H10))),"",$E10*IF($G10="2 weeks",MAX(0,MIN($F10-1,INT((EOMONTH(Settings!$C$7,2)-$H10)/14))-MAX(0,-INT(-(EDATE(Settings!$C$7,2)-$H10)/14))+1),IF(AND(((YEAR(EDATE(Settings!$C$7,2))*12+MONTH(EDATE(Settings!$C$7,2)))-(YEAR($H10)*12+MONTH($H10)))>=0,((YEAR(EDATE(Settings!$C$7,2))*12+MONTH(EDATE(Settings!$C$7,2)))-(YEAR($H10)*12+MONTH($H10)))<$F10),1,0))) | U10: =IF(NOT(AND(AND($B10<>"",N($E10)>0,N($F10)>0),ISNUMBER($H10))),"",$E10*IF($G10="2 weeks",MAX(0,MIN($F10-1,INT((EOMONTH(Settings!$C$7,3)-$H10)/14))-MAX(0,-INT(-(EDATE(Settings!$C$7,3)-$H10)/14))+1),IF(AND(((YEAR(EDATE(Settings!$C$7,3))*12+MONTH(EDATE(Settings!$C$7,3)))-(YEAR($H10)*12+MONTH($H10)))>=0,((YEAR(EDATE(Settings!$C$7,3))*12+MONTH(EDATE(Settings!$C$7,3)))-(YEAR($H10)*12+MONTH($H10)))<$F10),1,0))) | V10: =IF(NOT(AND(AND($B10<>"",N($E10)>0,N($F10)>0),ISNUMBER($H10))),"",$E10*IF($G10="2 weeks",MAX(0,MIN($F10-1,INT((EOMONTH(Settings!$C$7,4)-$H10)/14))-MAX(0,-INT(-(EDATE(Settings!$C$7,4)-$H10)/14))+1),IF(AND(((YEAR(EDATE(Settings!$C$7,4))*12+MONTH(EDATE(Settings!$C$7,4)))-(YEAR($H10)*12+MONTH($H10)))>=0,((YEAR(EDATE(Settings!$C$7,4))*12+MONTH(EDATE(Settings!$C$7,4)))-(YEAR($H10)*12+MONTH($H10)))<$F10),1,0))) | W10: =IF(ISNUMBER($M10),$M10+ROW()/10000000,"")
K11: =IF(AND($B11<>"",N($E11)>0,N($F11)>0),$E11*$F11,"") | L11: =IF(AND(ISNUMBER($K11),ISNUMBER($D11)),MAX(0,$K11-$D11),"") | M11: =IF(NOT(AND($B11<>"",N($E11)>0,N($F11)>0)),"",IF(ISNUMBER($J11),$J11,IF(NOT(ISNUMBER($D11)),"",IF($K11<=$D11+0.005,0,IFERROR(RATE($F11,-$E11,$D11,0,IF($I11="Yes",1,0))*IF($G11="2 weeks",26,12),""))))) | N11: =IF(NOT(AND(AND($B11<>"",N($E11)>0,N($F11)>0),ISNUMBER($H11))),"",IF($G11="2 weeks",$H11+14*($F11-1),EDATE($H11,$F11-1))) | O11: =IF(NOT(AND(AND($B11<>"",N($E11)>0,N($F11)>0),ISNUMBER($H11))),"",$F11-IF(Settings!$C$11<=$H11,0,MIN($F11,IF($G11="2 weeks",INT((Settings!$C$11-$H11-1)/14)+1,DATEDIF($H11,Settings!$C$11,"M")+IF(EDATE($H11,DATEDIF($H11,Settings!$C$11,"M"))<Settings!$C$11,1,0))))) | P11: =IF(ISNUMBER($O11),$O11*$E11,"") | Q11: =IF(NOT(ISNUMBER($M11)),"",IF($M11>=Settings!$C$8,"HIGH",IF($M11>=Settings!$C$9,"CHECK","OK"))) | R11: =IF(NOT(AND(AND($B11<>"",N($E11)>0,N($F11)>0),ISNUMBER($H11))),"",$E11*IF($G11="2 weeks",MAX(0,MIN($F11-1,INT((EOMONTH(Settings!$C$7,0)-$H11)/14))-MAX(0,-INT(-(EDATE(Settings!$C$7,0)-$H11)/14))+1),IF(AND(((YEAR(EDATE(Settings!$C$7,0))*12+MONTH(EDATE(Settings!$C$7,0)))-(YEAR($H11)*12+MONTH($H11)))>=0,((YEAR(EDATE(Settings!$C$7,0))*12+MONTH(EDATE(Settings!$C$7,0)))-(YEAR($H11)*12+MONTH($H11)))<$F11),1,0))) | S11: =IF(NOT(AND(AND($B11<>"",N($E11)>0,N($F11)>0),ISNUMBER($H11))),"",$E11*IF($G11="2 weeks",MAX(0,MIN($F11-1,INT((EOMONTH(Settings!$C$7,1)-$H11)/14))-MAX(0,-INT(-(EDATE(Settings!$C$7,1)-$H11)/14))+1),IF(AND(((YEAR(EDATE(Settings!$C$7,1))*12+MONTH(EDATE(Settings!$C$7,1)))-(YEAR($H11)*12+MONTH($H11)))>=0,((YEAR(EDATE(Settings!$C$7,1))*12+MONTH(EDATE(Settings!$C$7,1)))-(YEAR($H11)*12+MONTH($H11)))<$F11),1,0))) | T11: =IF(NOT(AND(AND($B11<>"",N($E11)>0,N($F11)>0),ISNUMBER($H11))),"",$E11*IF($G11="2 weeks",MAX(0,MIN($F11-1,INT((EOMONTH(Settings!$C$7,2)-$H11)/14))-MAX(0,-INT(-(EDATE(Settings!$C$7,2)-$H11)/14))+1),IF(AND(((YEAR(EDATE(Settings!$C$7,2))*12+MONTH(EDATE(Settings!$C$7,2)))-(YEAR($H11)*12+MONTH($H11)))>=0,((YEAR(EDATE(Settings!$C$7,2))*12+MONTH(EDATE(Settings!$C$7,2)))-(YEAR($H11)*12+MONTH($H11)))<$F11),1,0))) | U11: =IF(NOT(AND(AND($B11<>"",N($E11)>0,N($F11)>0),ISNUMBER($H11))),"",$E11*IF($G11="2 weeks",MAX(0,MIN($F11-1,INT((EOMONTH(Settings!$C$7,3)-$H11)/14))-MAX(0,-INT(-(EDATE(Settings!$C$7,3)-$H11)/14))+1),IF(AND(((YEAR(EDATE(Settings!$C$7,3))*12+MONTH(EDATE(Settings!$C$7,3)))-(YEAR($H11)*12+MONTH($H11)))>=0,((YEAR(EDATE(Settings!$C$7,3))*12+MONTH(EDATE(Settings!$C$7,3)))-(YEAR($H11)*12+MONTH($H11)))<$F11),1,0))) | V11: =IF(NOT(AND(AND($B11<>"",N($E11)>0,N($F11)>0),ISNUMBER($H11))),"",$E11*IF($G11="2 weeks",MAX(0,MIN($F11-1,INT((EOMONTH(Settings!$C$7,4)-$H11)/14))-MAX(0,-INT(-(EDATE(Settings!$C$7,4)-$H11)/14))+1),IF(AND(((YEAR(EDATE(Settings!$C$7,4))*12+MONTH(EDATE(Settings!$C$7,4)))-(YEAR($H11)*12+MONTH($H11)))>=0,((YEAR(EDATE(Settings!$C$7,4))*12+MONTH(EDATE(Settings!$C$7,4)))-(YEAR($H11)*12+MONTH($H11)))<$F11),1,0))) | W11: =IF(ISNUMBER($M11),$M11+ROW()/10000000,"")
K12: =IF(AND($B12<>"",N($E12)>0,N($F12)>0),$E12*$F12,"") | L12: =IF(AND(ISNUMBER($K12),ISNUMBER($D12)),MAX(0,$K12-$D12),"") | M12: =IF(NOT(AND($B12<>"",N($E12)>0,N($F12)>0)),"",IF(ISNUMBER($J12),$J12,IF(NOT(ISNUMBER($D12)),"",IF($K12<=$D12+0.005,0,IFERROR(RATE($F12,-$E12,$D12,0,IF($I12="Yes",1,0))*IF($G12="2 weeks",26,12),""))))) | N12: =IF(NOT(AND(AND($B12<>"",N($E12)>0,N($F12)>0),ISNUMBER($H12))),"",IF($G12="2 weeks",$H12+14*($F12-1),EDATE($H12,$F12-1))) | O12: =IF(NOT(AND(AND($B12<>"",N($E12)>0,N($F12)>0),ISNUMBER($H12))),"",$F12-IF(Settings!$C$11<=$H12,0,MIN($F12,IF($G12="2 weeks",INT((Settings!$C$11-$H12-1)/14)+1,DATEDIF($H12,Settings!$C$11,"M")+IF(EDATE($H12,DATEDIF($H12,Settings!$C$11,"M"))<Settings!$C$11,1,0))))) | P12: =IF(ISNUMBER($O12),$O12*$E12,"") | Q12: =IF(NOT(ISNUMBER($M12)),"",IF($M12>=Settings!$C$8,"HIGH",IF($M12>=Settings!$C$9,"CHECK","OK"))) | R12: =IF(NOT(AND(AND($B12<>"",N($E12)>0,N($F12)>0),ISNUMBER($H12))),"",$E12*IF($G12="2 weeks",MAX(0,MIN($F12-1,INT((EOMONTH(Settings!$C$7,0)-$H12)/14))-MAX(0,-INT(-(EDATE(Settings!$C$7,0)-$H12)/14))+1),IF(AND(((YEAR(EDATE(Settings!$C$7,0))*12+MONTH(EDATE(Settings!$C$7,0)))-(YEAR($H12)*12+MONTH($H12)))>=0,((YEAR(EDATE(Settings!$C$7,0))*12+MONTH(EDATE(Settings!$C$7,0)))-(YEAR($H12)*12+MONTH($H12)))<$F12),1,0))) | S12: =IF(NOT(AND(AND($B12<>"",N($E12)>0,N($F12)>0),ISNUMBER($H12))),"",$E12*IF($G12="2 weeks",MAX(0,MIN($F12-1,INT((EOMONTH(Settings!$C$7,1)-$H12)/14))-MAX(0,-INT(-(EDATE(Settings!$C$7,1)-$H12)/14))+1),IF(AND(((YEAR(EDATE(Settings!$C$7,1))*12+MONTH(EDATE(Settings!$C$7,1)))-(YEAR($H12)*12+MONTH($H12)))>=0,((YEAR(EDATE(Settings!$C$7,1))*12+MONTH(EDATE(Settings!$C$7,1)))-(YEAR($H12)*12+MONTH($H12)))<$F12),1,0))) | T12: =IF(NOT(AND(AND($B12<>"",N($E12)>0,N($F12)>0),ISNUMBER($H12))),"",$E12*IF($G12="2 weeks",MAX(0,MIN($F12-1,INT((EOMONTH(Settings!$C$7,2)-$H12)/14))-MAX(0,-INT(-(EDATE(Settings!$C$7,2)-$H12)/14))+1),IF(AND(((YEAR(EDATE(Settings!$C$7,2))*12+MONTH(EDATE(Settings!$C$7,2)))-(YEAR($H12)*12+MONTH($H12)))>=0,((YEAR(EDATE(Settings!$C$7,2))*12+MONTH(EDATE(Settings!$C$7,2)))-(YEAR($H12)*12+MONTH($H12)))<$F12),1,0))) | U12: =IF(NOT(AND(AND($B12<>"",N($E12)>0,N($F12)>0),ISNUMBER($H12))),"",$E12*IF($G12="2 weeks",MAX(0,MIN($F12-1,INT((EOMONTH(Settings!$C$7,3)-$H12)/14))-MAX(0,-INT(-(EDATE(Settings!$C$7,3)-$H12)/14))+1),IF(AND(((YEAR(EDATE(Settings!$C$7,3))*12+MONTH(EDATE(Settings!$C$7,3)))-(YEAR($H12)*12+MONTH($H12)))>=0,((YEAR(EDATE(Settings!$C$7,3))*12+MONTH(EDATE(Settings!$C$7,3)))-(YEAR($H12)*12+MONTH($H12)))<$F12),1,0))) | V12: =IF(NOT(AND(AND($B12<>"",N($E12)>0,N($F12)>0),ISNUMBER($H12))),"",$E12*IF($G12="2 weeks",MAX(0,MIN($F12-1,INT((EOMONTH(Settings!$C$7,4)-$H12)/14))-MAX(0,-INT(-(EDATE(Settings!$C$7,4)-$H12)/14))+1),IF(AND(((YEAR(EDATE(Settings!$C$7,4))*12+MONTH(EDATE(Settings!$C$7,4)))-(YEAR($H12)*12+MONTH($H12)))>=0,((YEAR(EDATE(Settings!$C$7,4))*12+MONTH(EDATE(Settings!$C$7,4)))-(YEAR($H12)*12+MONTH($H12)))<$F12),1,0))) | W12: =IF(ISNUMBER($M12),$M12+ROW()/10000000,"")
K13: =IF(AND($B13<>"",N($E13)>0,N($F13)>0),$E13*$F13,"") | L13: =IF(AND(ISNUMBER($K13),ISNUMBER($D13)),MAX(0,$K13-$D13),"") | M13: =IF(NOT(AND($B13<>"",N($E13)>0,N($F13)>0)),"",IF(ISNUMBER($J13),$J13,IF(NOT(ISNUMBER($D13)),"",IF($K13<=$D13+0.005,0,IFERROR(RATE($F13,-$E13,$D13,0,IF($I13="Yes",1,0))*IF($G13="2 weeks",26,12),""))))) | N13: =IF(NOT(AND(AND($B13<>"",N($E13)>0,N($F13)>0),ISNUMBER($H13))),"",IF($G13="2 weeks",$H13+14*($F13-1),EDATE($H13,$F13-1))) | O13: =IF(NOT(AND(AND($B13<>"",N($E13)>0,N($F13)>0),ISNUMBER($H13))),"",$F13-IF(Settings!$C$11<=$H13,0,MIN($F13,IF($G13="2 weeks",INT((Settings!$C$11-$H13-1)/14)+1,DATEDIF($H13,Settings!$C$11,"M")+IF(EDATE($H13,DATEDIF($H13,Settings!$C$11,"M"))<Settings!$C$11,1,0))))) | P13: =IF(ISNUMBER($O13),$O13*$E13,"") | Q13: =IF(NOT(ISNUMBER($M13)),"",IF($M13>=Settings!$C$8,"HIGH",IF($M13>=Settings!$C$9,"CHECK","OK"))) | R13: =IF(NOT(AND(AND($B13<>"",N($E13)>0,N($F13)>0),ISNUMBER($H13))),"",$E13*IF($G13="2 weeks",MAX(0,MIN($F13-1,INT((EOMONTH(Settings!$C$7,0)-$H13)/14))-MAX(0,-INT(-(EDATE(Settings!$C$7,0)-$H13)/14))+1),IF(AND(((YEAR(EDATE(Settings!$C$7,0))*12+MONTH(EDATE(Settings!$C$7,0)))-(YEAR($H13)*12+MONTH($H13)))>=0,((YEAR(EDATE(Settings!$C$7,0))*12+MONTH(EDATE(Settings!$C$7,0)))-(YEAR($H13)*12+MONTH($H13)))<$F13),1,0))) | S13: =IF(NOT(AND(AND($B13<>"",N($E13)>0,N($F13)>0),ISNUMBER($H13))),"",$E13*IF($G13="2 weeks",MAX(0,MIN($F13-1,INT((EOMONTH(Settings!$C$7,1)-$H13)/14))-MAX(0,-INT(-(EDATE(Settings!$C$7,1)-$H13)/14))+1),IF(AND(((YEAR(EDATE(Settings!$C$7,1))*12+MONTH(EDATE(Settings!$C$7,1)))-(YEAR($H13)*12+MONTH($H13)))>=0,((YEAR(EDATE(Settings!$C$7,1))*12+MONTH(EDATE(Settings!$C$7,1)))-(YEAR($H13)*12+MONTH($H13)))<$F13),1,0))) | T13: =IF(NOT(AND(AND($B13<>"",N($E13)>0,N($F13)>0),ISNUMBER($H13))),"",$E13*IF($G13="2 weeks",MAX(0,MIN($F13-1,INT((EOMONTH(Settings!$C$7,2)-$H13)/14))-MAX(0,-INT(-(EDATE(Settings!$C$7,2)-$H13)/14))+1),IF(AND(((YEAR(EDATE(Settings!$C$7,2))*12+MONTH(EDATE(Settings!$C$7,2)))-(YEAR($H13)*12+MONTH($H13)))>=0,((YEAR(EDATE(Settings!$C$7,2))*12+MONTH(EDATE(Settings!$C$7,2)))-(YEAR($H13)*12+MONTH($H13)))<$F13),1,0))) | U13: =IF(NOT(AND(AND($B13<>"",N($E13)>0,N($F13)>0),ISNUMBER($H13))),"",$E13*IF($G13="2 weeks",MAX(0,MIN($F13-1,INT((EOMONTH(Settings!$C$7,3)-$H13)/14))-MAX(0,-INT(-(EDATE(Settings!$C$7,3)-$H13)/14))+1),IF(AND(((YEAR(EDATE(Settings!$C$7,3))*12+MONTH(EDATE(Settings!$C$7,3)))-(YEAR($H13)*12+MONTH($H13)))>=0,((YEAR(EDATE(Settings!$C$7,3))*12+MONTH(EDATE(Settings!$C$7,3)))-(YEAR($H13)*12+MONTH($H13)))<$F13),1,0))) | V13: =IF(NOT(AND(AND($B13<>"",N($E13)>0,N($F13)>0),ISNUMBER($H13))),"",$E13*IF($G13="2 weeks",MAX(0,MIN($F13-1,INT((EOMONTH(Settings!$C$7,4)-$H13)/14))-MAX(0,-INT(-(EDATE(Settings!$C$7,4)-$H13)/14))+1),IF(AND(((YEAR(EDATE(Settings!$C$7,4))*12+MONTH(EDATE(Settings!$C$7,4)))-(YEAR($H13)*12+MONTH($H13)))>=0,((YEAR(EDATE(Settings!$C$7,4))*12+MONTH(EDATE(Settings!$C$7,4)))-(YEAR($H13)*12+MONTH($H13)))<$F13),1,0))) | W13: =IF(ISNUMBER($M13),$M13+ROW()/10000000,"")
K14: =IF(AND($B14<>"",N($E14)>0,N($F14)>0),$E14*$F14,"") | L14: =IF(AND(ISNUMBER($K14),ISNUMBER($D14)),MAX(0,$K14-$D14),"") | M14: =IF(NOT(AND($B14<>"",N($E14)>0,N($F14)>0)),"",IF(ISNUMBER($J14),$J14,IF(NOT(ISNUMBER($D14)),"",IF($K14<=$D14+0.005,0,IFERROR(RATE($F14,-$E14,$D14,0,IF($I14="Yes",1,0))*IF($G14="2 weeks",26,12),""))))) | N14: =IF(NOT(AND(AND($B14<>"",N($E14)>0,N($F14)>0),ISNUMBER($H14))),"",IF($G14="2 weeks",$H14+14*($F14-1),EDATE($H14,$F14-1))) | O14: =IF(NOT(AND(AND($B14<>"",N($E14)>0,N($F14)>0),ISNUMBER($H14))),"",$F14-IF(Settings!$C$11<=$H14,0,MIN($F14,IF($G14="2 weeks",INT((Settings!$C$11-$H14-1)/14)+1,DATEDIF($H14,Settings!$C$11,"M")+IF(EDATE($H14,DATEDIF($H14,Settings!$C$11,"M"))<Settings!$C$11,1,0))))) | P14: =IF(ISNUMBER($O14),$O14*$E14,"") | Q14: =IF(NOT(ISNUMBER($M14)),"",IF($M14>=Settings!$C$8,"HIGH",IF($M14>=Settings!$C$9,"CHECK","OK"))) | R14: =IF(NOT(AND(AND($B14<>"",N($E14)>0,N($F14)>0),ISNUMBER($H14))),"",$E14*IF($G14="2 weeks",MAX(0,MIN($F14-1,INT((EOMONTH(Settings!$C$7,0)-$H14)/14))-MAX(0,-INT(-(EDATE(Settings!$C$7,0)-$H14)/14))+1),IF(AND(((YEAR(EDATE(Settings!$C$7,0))*12+MONTH(EDATE(Settings!$C$7,0)))-(YEAR($H14)*12+MONTH($H14)))>=0,((YEAR(EDATE(Settings!$C$7,0))*12+MONTH(EDATE(Settings!$C$7,0)))-(YEAR($H14)*12+MONTH($H14)))<$F14),1,0))) | S14: =IF(NOT(AND(AND($B14<>"",N($E14)>0,N($F14)>0),ISNUMBER($H14))),"",$E14*IF($G14="2 weeks",MAX(0,MIN($F14-1,INT((EOMONTH(Settings!$C$7,1)-$H14)/14))-MAX(0,-INT(-(EDATE(Settings!$C$7,1)-$H14)/14))+1),IF(AND(((YEAR(EDATE(Settings!$C$7,1))*12+MONTH(EDATE(Settings!$C$7,1)))-(YEAR($H14)*12+MONTH($H14)))>=0,((YEAR(EDATE(Settings!$C$7,1))*12+MONTH(EDATE(Settings!$C$7,1)))-(YEAR($H14)*12+MONTH($H14)))<$F14),1,0))) | T14: =IF(NOT(AND(AND($B14<>"",N($E14)>0,N($F14)>0),ISNUMBER($H14))),"",$E14*IF($G14="2 weeks",MAX(0,MIN($F14-1,INT((EOMONTH(Settings!$C$7,2)-$H14)/14))-MAX(0,-INT(-(EDATE(Settings!$C$7,2)-$H14)/14))+1),IF(AND(((YEAR(EDATE(Settings!$C$7,2))*12+MONTH(EDATE(Settings!$C$7,2)))-(YEAR($H14)*12+MONTH($H14)))>=0,((YEAR(EDATE(Settings!$C$7,2))*12+MONTH(EDATE(Settings!$C$7,2)))-(YEAR($H14)*12+MONTH($H14)))<$F14),1,0))) | U14: =IF(NOT(AND(AND($B14<>"",N($E14)>0,N($F14)>0),ISNUMBER($H14))),"",$E14*IF($G14="2 weeks",MAX(0,MIN($F14-1,INT((EOMONTH(Settings!$C$7,3)-$H14)/14))-MAX(0,-INT(-(EDATE(Settings!$C$7,3)-$H14)/14))+1),IF(AND(((YEAR(EDATE(Settings!$C$7,3))*12+MONTH(EDATE(Settings!$C$7,3)))-(YEAR($H14)*12+MONTH($H14)))>=0,((YEAR(EDATE(Settings!$C$7,3))*12+MONTH(EDATE(Settings!$C$7,3)))-(YEAR($H14)*12+MONTH($H14)))<$F14),1,0))) | V14: =IF(NOT(AND(AND($B14<>"",N($E14)>0,N($F14)>0),ISNUMBER($H14))),"",$E14*IF($G14="2 weeks",MAX(0,MIN($F14-1,INT((EOMONTH(Settings!$C$7,4)-$H14)/14))-MAX(0,-INT(-(EDATE(Settings!$C$7,4)-$H14)/14))+1),IF(AND(((YEAR(EDATE(Settings!$C$7,4))*12+MONTH(EDATE(Settings!$C$7,4)))-(YEAR($H14)*12+MONTH($H14)))>=0,((YEAR(EDATE(Settings!$C$7,4))*12+MONTH(EDATE(Settings!$C$7,4)))-(YEAR($H14)*12+MONTH($H14)))<$F14),1,0))) | W14: =IF(ISNUMBER($M14),$M14+ROW()/10000000,"")
K15: =IF(AND($B15<>"",N($E15)>0,N($F15)>0),$E15*$F15,"") | L15: =IF(AND(ISNUMBER($K15),ISNUMBER($D15)),MAX(0,$K15-$D15),"") | M15: =IF(NOT(AND($B15<>"",N($E15)>0,N($F15)>0)),"",IF(ISNUMBER($J15),$J15,IF(NOT(ISNUMBER($D15)),"",IF($K15<=$D15+0.005,0,IFERROR(RATE($F15,-$E15,$D15,0,IF($I15="Yes",1,0))*IF($G15="2 weeks",26,12),""))))) | N15: =IF(NOT(AND(AND($B15<>"",N($E15)>0,N($F15)>0),ISNUMBER($H15))),"",IF($G15="2 weeks",$H15+14*($F15-1),EDATE($H15,$F15-1))) | O15: =IF(NOT(AND(AND($B15<>"",N($E15)>0,N($F15)>0),ISNUMBER($H15))),"",$F15-IF(Settings!$C$11<=$H15,0,MIN($F15,IF($G15="2 weeks",INT((Settings!$C$11-$H15-1)/14)+1,DATEDIF($H15,Settings!$C$11,"M")+IF(EDATE($H15,DATEDIF($H15,Settings!$C$11,"M"))<Settings!$C$11,1,0))))) | P15: =IF(ISNUMBER($O15),$O15*$E15,"") | Q15: =IF(NOT(ISNUMBER($M15)),"",IF($M15>=Settings!$C$8,"HIGH",IF($M15>=Settings!$C$9,"CHECK","OK"))) | R15: =IF(NOT(AND(AND($B15<>"",N($E15)>0,N($F15)>0),ISNUMBER($H15))),"",$E15*IF($G15="2 weeks",MAX(0,MIN($F15-1,INT((EOMONTH(Settings!$C$7,0)-$H15)/14))-MAX(0,-INT(-(EDATE(Settings!$C$7,0)-$H15)/14))+1),IF(AND(((YEAR(EDATE(Settings!$C$7,0))*12+MONTH(EDATE(Settings!$C$7,0)))-(YEAR($H15)*12+MONTH($H15)))>=0,((YEAR(EDATE(Settings!$C$7,0))*12+MONTH(EDATE(Settings!$C$7,0)))-(YEAR($H15)*12+MONTH($H15)))<$F15),1,0))) | S15: =IF(NOT(AND(AND($B15<>"",N($E15)>0,N($F15)>0),ISNUMBER($H15))),"",$E15*IF($G15="2 weeks",MAX(0,MIN($F15-1,INT((EOMONTH(Settings!$C$7,1)-$H15)/14))-MAX(0,-INT(-(EDATE(Settings!$C$7,1)-$H15)/14))+1),IF(AND(((YEAR(EDATE(Settings!$C$7,1))*12+MONTH(EDATE(Settings!$C$7,1)))-(YEAR($H15)*12+MONTH($H15)))>=0,((YEAR(EDATE(Settings!$C$7,1))*12+MONTH(EDATE(Settings!$C$7,1)))-(YEAR($H15)*12+MONTH($H15)))<$F15),1,0))) | T15: =IF(NOT(AND(AND($B15<>"",N($E15)>0,N($F15)>0),ISNUMBER($H15))),"",$E15*IF($G15="2 weeks",MAX(0,MIN($F15-1,INT((EOMONTH(Settings!$C$7,2)-$H15)/14))-MAX(0,-INT(-(EDATE(Settings!$C$7,2)-$H15)/14))+1),IF(AND(((YEAR(EDATE(Settings!$C$7,2))*12+MONTH(EDATE(Settings!$C$7,2)))-(YEAR($H15)*12+MONTH($H15)))>=0,((YEAR(EDATE(Settings!$C$7,2))*12+MONTH(EDATE(Settings!$C$7,2)))-(YEAR($H15)*12+MONTH($H15)))<$F15),1,0))) | U15: =IF(NOT(AND(AND($B15<>"",N($E15)>0,N($F15)>0),ISNUMBER($H15))),"",$E15*IF($G15="2 weeks",MAX(0,MIN($F15-1,INT((EOMONTH(Settings!$C$7,3)-$H15)/14))-MAX(0,-INT(-(EDATE(Settings!$C$7,3)-$H15)/14))+1),IF(AND(((YEAR(EDATE(Settings!$C$7,3))*12+MONTH(EDATE(Settings!$C$7,3)))-(YEAR($H15)*12+MONTH($H15)))>=0,((YEAR(EDATE(Settings!$C$7,3))*12+MONTH(EDATE(Settings!$C$7,3)))-(YEAR($H15)*12+MONTH($H15)))<$F15),1,0))) | V15: =IF(NOT(AND(AND($B15<>"",N($E15)>0,N($F15)>0),ISNUMBER($H15))),"",$E15*IF($G15="2 weeks",MAX(0,MIN($F15-1,INT((EOMONTH(Settings!$C$7,4)-$H15)/14))-MAX(0,-INT(-(EDATE(Settings!$C$7,4)-$H15)/14))+1),IF(AND(((YEAR(EDATE(Settings!$C$7,4))*12+MONTH(EDATE(Settings!$C$7,4)))-(YEAR($H15)*12+MONTH($H15)))>=0,((YEAR(EDATE(Settings!$C$7,4))*12+MONTH(EDATE(Settings!$C$7,4)))-(YEAR($H15)*12+MONTH($H15)))<$F15),1,0))) | W15: =IF(ISNUMBER($M15),$M15+ROW()/10000000,"")
K16: =IF(AND($B16<>"",N($E16)>0,N($F16)>0),$E16*$F16,"") | L16: =IF(AND(ISNUMBER($K16),ISNUMBER($D16)),MAX(0,$K16-$D16),"") | M16: =IF(NOT(AND($B16<>"",N($E16)>0,N($F16)>0)),"",IF(ISNUMBER($J16),$J16,IF(NOT(ISNUMBER($D16)),"",IF($K16<=$D16+0.005,0,IFERROR(RATE($F16,-$E16,$D16,0,IF($I16="Yes",1,0))*IF($G16="2 weeks",26,12),""))))) | N16: =IF(NOT(AND(AND($B16<>"",N($E16)>0,N($F16)>0),ISNUMBER($H16))),"",IF($G16="2 weeks",$H16+14*($F16-1),EDATE($H16,$F16-1))) | O16: =IF(NOT(AND(AND($B16<>"",N($E16)>0,N($F16)>0),ISNUMBER($H16))),"",$F16-IF(Settings!$C$11<=$H16,0,MIN($F16,IF($G16="2 weeks",INT((Settings!$C$11-$H16-1)/14)+1,DATEDIF($H16,Settings!$C$11,"M")+IF(EDATE($H16,DATEDIF($H16,Settings!$C$11,"M"))<Settings!$C$11,1,0))))) | P16: =IF(ISNUMBER($O16),$O16*$E16,"") | Q16: =IF(NOT(ISNUMBER($M16)),"",IF($M16>=Settings!$C$8,"HIGH",IF($M16>=Settings!$C$9,"CHECK","OK"))) | R16: =IF(NOT(AND(AND($B16<>"",N($E16)>0,N($F16)>0),ISNUMBER($H16))),"",$E16*IF($G16="2 weeks",MAX(0,MIN($F16-1,INT((EOMONTH(Settings!$C$7,0)-$H16)/14))-MAX(0,-INT(-(EDATE(Settings!$C$7,0)-$H16)/14))+1),IF(AND(((YEAR(EDATE(Settings!$C$7,0))*12+MONTH(EDATE(Settings!$C$7,0)))-(YEAR($H16)*12+MONTH($H16)))>=0,((YEAR(EDATE(Settings!$C$7,0))*12+MONTH(EDATE(Settings!$C$7,0)))-(YEAR($H16)*12+MONTH($H16)))<$F16),1,0))) | S16: =IF(NOT(AND(AND($B16<>"",N($E16)>0,N($F16)>0),ISNUMBER($H16))),"",$E16*IF($G16="2 weeks",MAX(0,MIN($F16-1,INT((EOMONTH(Settings!$C$7,1)-$H16)/14))-MAX(0,-INT(-(EDATE(Settings!$C$7,1)-$H16)/14))+1),IF(AND(((YEAR(EDATE(Settings!$C$7,1))*12+MONTH(EDATE(Settings!$C$7,1)))-(YEAR($H16)*12+MONTH($H16)))>=0,((YEAR(EDATE(Settings!$C$7,1))*12+MONTH(EDATE(Settings!$C$7,1)))-(YEAR($H16)*12+MONTH($H16)))<$F16),1,0))) | T16: =IF(NOT(AND(AND($B16<>"",N($E16)>0,N($F16)>0),ISNUMBER($H16))),"",$E16*IF($G16="2 weeks",MAX(0,MIN($F16-1,INT((EOMONTH(Settings!$C$7,2)-$H16)/14))-MAX(0,-INT(-(EDATE(Settings!$C$7,2)-$H16)/14))+1),IF(AND(((YEAR(EDATE(Settings!$C$7,2))*12+MONTH(EDATE(Settings!$C$7,2)))-(YEAR($H16)*12+MONTH($H16)))>=0,((YEAR(EDATE(Settings!$C$7,2))*12+MONTH(EDATE(Settings!$C$7,2)))-(YEAR($H16)*12+MONTH($H16)))<$F16),1,0))) | U16: =IF(NOT(AND(AND($B16<>"",N($E16)>0,N($F16)>0),ISNUMBER($H16))),"",$E16*IF($G16="2 weeks",MAX(0,MIN($F16-1,INT((EOMONTH(Settings!$C$7,3)-$H16)/14))-MAX(0,-INT(-(EDATE(Settings!$C$7,3)-$H16)/14))+1),IF(AND(((YEAR(EDATE(Settings!$C$7,3))*12+MONTH(EDATE(Settings!$C$7,3)))-(YEAR($H16)*12+MONTH($H16)))>=0,((YEAR(EDATE(Settings!$C$7,3))*12+MONTH(EDATE(Settings!$C$7,3)))-(YEAR($H16)*12+MONTH($H16)))<$F16),1,0))) | V16: =IF(NOT(AND(AND($B16<>"",N($E16)>0,N($F16)>0),ISNUMBER($H16))),"",$E16*IF($G16="2 weeks",MAX(0,MIN($F16-1,INT((EOMONTH(Settings!$C$7,4)-$H16)/14))-MAX(0,-INT(-(EDATE(Settings!$C$7,4)-$H16)/14))+1),IF(AND(((YEAR(EDATE(Settings!$C$7,4))*12+MONTH(EDATE(Settings!$C$7,4)))-(YEAR($H16)*12+MONTH($H16)))>=0,((YEAR(EDATE(Settings!$C$7,4))*12+MONTH(EDATE(Settings!$C$7,4)))-(YEAR($H16)*12+MONTH($H16)))<$F16),1,0))) | W16: =IF(ISNUMBER($M16),$M16+ROW()/10000000,"")
K17: =IF(AND($B17<>"",N($E17)>0,N($F17)>0),$E17*$F17,"") | L17: =IF(AND(ISNUMBER($K17),ISNUMBER($D17)),MAX(0,$K17-$D17),"") | M17: =IF(NOT(AND($B17<>"",N($E17)>0,N($F17)>0)),"",IF(ISNUMBER($J17),$J17,IF(NOT(ISNUMBER($D17)),"",IF($K17<=$D17+0.005,0,IFERROR(RATE($F17,-$E17,$D17,0,IF($I17="Yes",1,0))*IF($G17="2 weeks",26,12),""))))) | N17: =IF(NOT(AND(AND($B17<>"",N($E17)>0,N($F17)>0),ISNUMBER($H17))),"",IF($G17="2 weeks",$H17+14*($F17-1),EDATE($H17,$F17-1))) | O17: =IF(NOT(AND(AND($B17<>"",N($E17)>0,N($F17)>0),ISNUMBER($H17))),"",$F17-IF(Settings!$C$11<=$H17,0,MIN($F17,IF($G17="2 weeks",INT((Settings!$C$11-$H17-1)/14)+1,DATEDIF($H17,Settings!$C$11,"M")+IF(EDATE($H17,DATEDIF($H17,Settings!$C$11,"M"))<Settings!$C$11,1,0))))) | P17: =IF(ISNUMBER($O17),$O17*$E17,"") | Q17: =IF(NOT(ISNUMBER($M17)),"",IF($M17>=Settings!$C$8,"HIGH",IF($M17>=Settings!$C$9,"CHECK","OK"))) | R17: =IF(NOT(AND(AND($B17<>"",N($E17)>0,N($F17)>0),ISNUMBER($H17))),"",$E17*IF($G17="2 weeks",MAX(0,MIN($F17-1,INT((EOMONTH(Settings!$C$7,0)-$H17)/14))-MAX(0,-INT(-(EDATE(Settings!$C$7,0)-$H17)/14))+1),IF(AND(((YEAR(EDATE(Settings!$C$7,0))*12+MONTH(EDATE(Settings!$C$7,0)))-(YEAR($H17)*12+MONTH($H17)))>=0,((YEAR(EDATE(Settings!$C$7,0))*12+MONTH(EDATE(Settings!$C$7,0)))-(YEAR($H17)*12+MONTH($H17)))<$F17),1,0))) | S17: =IF(NOT(AND(AND($B17<>"",N($E17)>0,N($F17)>0),ISNUMBER($H17))),"",$E17*IF($G17="2 weeks",MAX(0,MIN($F17-1,INT((EOMONTH(Settings!$C$7,1)-$H17)/14))-MAX(0,-INT(-(EDATE(Settings!$C$7,1)-$H17)/14))+1),IF(AND(((YEAR(EDATE(Settings!$C$7,1))*12+MONTH(EDATE(Settings!$C$7,1)))-(YEAR($H17)*12+MONTH($H17)))>=0,((YEAR(EDATE(Settings!$C$7,1))*12+MONTH(EDATE(Settings!$C$7,1)))-(YEAR($H17)*12+MONTH($H17)))<$F17),1,0))) | T17: =IF(NOT(AND(AND($B17<>"",N($E17)>0,N($F17)>0),ISNUMBER($H17))),"",$E17*IF($G17="2 weeks",MAX(0,MIN($F17-1,INT((EOMONTH(Settings!$C$7,2)-$H17)/14))-MAX(0,-INT(-(EDATE(Settings!$C$7,2)-$H17)/14))+1),IF(AND(((YEAR(EDATE(Settings!$C$7,2))*12+MONTH(EDATE(Settings!$C$7,2)))-(YEAR($H17)*12+MONTH($H17)))>=0,((YEAR(EDATE(Settings!$C$7,2))*12+MONTH(EDATE(Settings!$C$7,2)))-(YEAR($H17)*12+MONTH($H17)))<$F17),1,0))) | U17: =IF(NOT(AND(AND($B17<>"",N($E17)>0,N($F17)>0),ISNUMBER($H17))),"",$E17*IF($G17="2 weeks",MAX(0,MIN($F17-1,INT((EOMONTH(Settings!$C$7,3)-$H17)/14))-MAX(0,-INT(-(EDATE(Settings!$C$7,3)-$H17)/14))+1),IF(AND(((YEAR(EDATE(Settings!$C$7,3))*12+MONTH(EDATE(Settings!$C$7,3)))-(YEAR($H17)*12+MONTH($H17)))>=0,((YEAR(EDATE(Settings!$C$7,3))*12+MONTH(EDATE(Settings!$C$7,3)))-(YEAR($H17)*12+MONTH($H17)))<$F17),1,0))) | V17: =IF(NOT(AND(AND($B17<>"",N($E17)>0,N($F17)>0),ISNUMBER($H17))),"",$E17*IF($G17="2 weeks",MAX(0,MIN($F17-1,INT((EOMONTH(Settings!$C$7,4)-$H17)/14))-MAX(0,-INT(-(EDATE(Settings!$C$7,4)-$H17)/14))+1),IF(AND(((YEAR(EDATE(Settings!$C$7,4))*12+MONTH(EDATE(Settings!$C$7,4)))-(YEAR($H17)*12+MONTH($H17)))>=0,((YEAR(EDATE(Settings!$C$7,4))*12+MONTH(EDATE(Settings!$C$7,4)))-(YEAR($H17)*12+MONTH($H17)))<$F17),1,0))) | W17: =IF(ISNUMBER($M17),$M17+ROW()/10000000,"")
K18: =IF(AND($B18<>"",N($E18)>0,N($F18)>0),$E18*$F18,"") | L18: =IF(AND(ISNUMBER($K18),ISNUMBER($D18)),MAX(0,$K18-$D18),"") | M18: =IF(NOT(AND($B18<>"",N($E18)>0,N($F18)>0)),"",IF(ISNUMBER($J18),$J18,IF(NOT(ISNUMBER($D18)),"",IF($K18<=$D18+0.005,0,IFERROR(RATE($F18,-$E18,$D18,0,IF($I18="Yes",1,0))*IF($G18="2 weeks",26,12),""))))) | N18: =IF(NOT(AND(AND($B18<>"",N($E18)>0,N($F18)>0),ISNUMBER($H18))),"",IF($G18="2 weeks",$H18+14*($F18-1),EDATE($H18,$F18-1))) | O18: =IF(NOT(AND(AND($B18<>"",N($E18)>0,N($F18)>0),ISNUMBER($H18))),"",$F18-IF(Settings!$C$11<=$H18,0,MIN($F18,IF($G18="2 weeks",INT((Settings!$C$11-$H18-1)/14)+1,DATEDIF($H18,Settings!$C$11,"M")+IF(EDATE($H18,DATEDIF($H18,Settings!$C$11,"M"))<Settings!$C$11,1,0))))) | P18: =IF(ISNUMBER($O18),$O18*$E18,"") | Q18: =IF(NOT(ISNUMBER($M18)),"",IF($M18>=Settings!$C$8,"HIGH",IF($M18>=Settings!$C$9,"CHECK","OK"))) | R18: =IF(NOT(AND(AND($B18<>"",N($E18)>0,N($F18)>0),ISNUMBER($H18))),"",$E18*IF($G18="2 weeks",MAX(0,MIN($F18-1,INT((EOMONTH(Settings!$C$7,0)-$H18)/14))-MAX(0,-INT(-(EDATE(Settings!$C$7,0)-$H18)/14))+1),IF(AND(((YEAR(EDATE(Settings!$C$7,0))*12+MONTH(EDATE(Settings!$C$7,0)))-(YEAR($H18)*12+MONTH($H18)))>=0,((YEAR(EDATE(Settings!$C$7,0))*12+MONTH(EDATE(Settings!$C$7,0)))-(YEAR($H18)*12+MONTH($H18)))<$F18),1,0))) | S18: =IF(NOT(AND(AND($B18<>"",N($E18)>0,N($F18)>0),ISNUMBER($H18))),"",$E18*IF($G18="2 weeks",MAX(0,MIN($F18-1,INT((EOMONTH(Settings!$C$7,1)-$H18)/14))-MAX(0,-INT(-(EDATE(Settings!$C$7,1)-$H18)/14))+1),IF(AND(((YEAR(EDATE(Settings!$C$7,1))*12+MONTH(EDATE(Settings!$C$7,1)))-(YEAR($H18)*12+MONTH($H18)))>=0,((YEAR(EDATE(Settings!$C$7,1))*12+MONTH(EDATE(Settings!$C$7,1)))-(YEAR($H18)*12+MONTH($H18)))<$F18),1,0))) | T18: =IF(NOT(AND(AND($B18<>"",N($E18)>0,N($F18)>0),ISNUMBER($H18))),"",$E18*IF($G18="2 weeks",MAX(0,MIN($F18-1,INT((EOMONTH(Settings!$C$7,2)-$H18)/14))-MAX(0,-INT(-(EDATE(Settings!$C$7,2)-$H18)/14))+1),IF(AND(((YEAR(EDATE(Settings!$C$7,2))*12+MONTH(EDATE(Settings!$C$7,2)))-(YEAR($H18)*12+MONTH($H18)))>=0,((YEAR(EDATE(Settings!$C$7,2))*12+MONTH(EDATE(Settings!$C$7,2)))-(YEAR($H18)*12+MONTH($H18)))<$F18),1,0))) | U18: =IF(NOT(AND(AND($B18<>"",N($E18)>0,N($F18)>0),ISNUMBER($H18))),"",$E18*IF($G18="2 weeks",MAX(0,MIN($F18-1,INT((EOMONTH(Settings!$C$7,3)-$H18)/14))-MAX(0,-INT(-(EDATE(Settings!$C$7,3)-$H18)/14))+1),IF(AND(((YEAR(EDATE(Settings!$C$7,3))*12+MONTH(EDATE(Settings!$C$7,3)))-(YEAR($H18)*12+MONTH($H18)))>=0,((YEAR(EDATE(Settings!$C$7,3))*12+MONTH(EDATE(Settings!$C$7,3)))-(YEAR($H18)*12+MONTH($H18)))<$F18),1,0))) | V18: =IF(NOT(AND(AND($B18<>"",N($E18)>0,N($F18)>0),ISNUMBER($H18))),"",$E18*IF($G18="2 weeks",MAX(0,MIN($F18-1,INT((EOMONTH(Settings!$C$7,4)-$H18)/14))-MAX(0,-INT(-(EDATE(Settings!$C$7,4)-$H18)/14))+1),IF(AND(((YEAR(EDATE(Settings!$C$7,4))*12+MONTH(EDATE(Settings!$C$7,4)))-(YEAR($H18)*12+MONTH($H18)))>=0,((YEAR(EDATE(Settings!$C$7,4))*12+MONTH(EDATE(Settings!$C$7,4)))-(YEAR($H18)*12+MONTH($H18)))<$F18),1,0))) | W18: =IF(ISNUMBER($M18),$M18+ROW()/10000000,"")
K19: =IF(AND($B19<>"",N($E19)>0,N($F19)>0),$E19*$F19,"") | L19: =IF(AND(ISNUMBER($K19),ISNUMBER($D19)),MAX(0,$K19-$D19),"") | M19: =IF(NOT(AND($B19<>"",N($E19)>0,N($F19)>0)),"",IF(ISNUMBER($J19),$J19,IF(NOT(ISNUMBER($D19)),"",IF($K19<=$D19+0.005,0,IFERROR(RATE($F19,-$E19,$D19,0,IF($I19="Yes",1,0))*IF($G19="2 weeks",26,12),""))))) | N19: =IF(NOT(AND(AND($B19<>"",N($E19)>0,N($F19)>0),ISNUMBER($H19))),"",IF($G19="2 weeks",$H19+14*($F19-1),EDATE($H19,$F19-1))) | O19: =IF(NOT(AND(AND($B19<>"",N($E19)>0,N($F19)>0),ISNUMBER($H19))),"",$F19-IF(Settings!$C$11<=$H19,0,MIN($F19,IF($G19="2 weeks",INT((Settings!$C$11-$H19-1)/14)+1,DATEDIF($H19,Settings!$C$11,"M")+IF(EDATE($H19,DATEDIF($H19,Settings!$C$11,"M"))<Settings!$C$11,1,0))))) | P19: =IF(ISNUMBER($O19),$O19*$E19,"") | Q19: =IF(NOT(ISNUMBER($M19)),"",IF($M19>=Settings!$C$8,"HIGH",IF($M19>=Settings!$C$9,"CHECK","OK"))) | R19: =IF(NOT(AND(AND($B19<>"",N($E19)>0,N($F19)>0),ISNUMBER($H19))),"",$E19*IF($G19="2 weeks",MAX(0,MIN($F19-1,INT((EOMONTH(Settings!$C$7,0)-$H19)/14))-MAX(0,-INT(-(EDATE(Settings!$C$7,0)-$H19)/14))+1),IF(AND(((YEAR(EDATE(Settings!$C$7,0))*12+MONTH(EDATE(Settings!$C$7,0)))-(YEAR($H19)*12+MONTH($H19)))>=0,((YEAR(EDATE(Settings!$C$7,0))*12+MONTH(EDATE(Settings!$C$7,0)))-(YEAR($H19)*12+MONTH($H19)))<$F19),1,0))) | S19: =IF(NOT(AND(AND($B19<>"",N($E19)>0,N($F19)>0),ISNUMBER($H19))),"",$E19*IF($G19="2 weeks",MAX(0,MIN($F19-1,INT((EOMONTH(Settings!$C$7,1)-$H19)/14))-MAX(0,-INT(-(EDATE(Settings!$C$7,1)-$H19)/14))+1),IF(AND(((YEAR(EDATE(Settings!$C$7,1))*12+MONTH(EDATE(Settings!$C$7,1)))-(YEAR($H19)*12+MONTH($H19)))>=0,((YEAR(EDATE(Settings!$C$7,1))*12+MONTH(EDATE(Settings!$C$7,1)))-(YEAR($H19)*12+MONTH($H19)))<$F19),1,0))) | T19: =IF(NOT(AND(AND($B19<>"",N($E19)>0,N($F19)>0),ISNUMBER($H19))),"",$E19*IF($G19="2 weeks",MAX(0,MIN($F19-1,INT((EOMONTH(Settings!$C$7,2)-$H19)/14))-MAX(0,-INT(-(EDATE(Settings!$C$7,2)-$H19)/14))+1),IF(AND(((YEAR(EDATE(Settings!$C$7,2))*12+MONTH(EDATE(Settings!$C$7,2)))-(YEAR($H19)*12+MONTH($H19)))>=0,((YEAR(EDATE(Settings!$C$7,2))*12+MONTH(EDATE(Settings!$C$7,2)))-(YEAR($H19)*12+MONTH($H19)))<$F19),1,0))) | U19: =IF(NOT(AND(AND($B19<>"",N($E19)>0,N($F19)>0),ISNUMBER($H19))),"",$E19*IF($G19="2 weeks",MAX(0,MIN($F19-1,INT((EOMONTH(Settings!$C$7,3)-$H19)/14))-MAX(0,-INT(-(EDATE(Settings!$C$7,3)-$H19)/14))+1),IF(AND(((YEAR(EDATE(Settings!$C$7,3))*12+MONTH(EDATE(Settings!$C$7,3)))-(YEAR($H19)*12+MONTH($H19)))>=0,((YEAR(EDATE(Settings!$C$7,3))*12+MONTH(EDATE(Settings!$C$7,3)))-(YEAR($H19)*12+MONTH($H19)))<$F19),1,0))) | V19: =IF(NOT(AND(AND($B19<>"",N($E19)>0,N($F19)>0),ISNUMBER($H19))),"",$E19*IF($G19="2 weeks",MAX(0,MIN($F19-1,INT((EOMONTH(Settings!$C$7,4)-$H19)/14))-MAX(0,-INT(-(EDATE(Settings!$C$7,4)-$H19)/14))+1),IF(AND(((YEAR(EDATE(Settings!$C$7,4))*12+MONTH(EDATE(Settings!$C$7,4)))-(YEAR($H19)*12+MONTH($H19)))>=0,((YEAR(EDATE(Settings!$C$7,4))*12+MONTH(EDATE(Settings!$C$7,4)))-(YEAR($H19)*12+MONTH($H19)))<$F19),1,0))) | W19: =IF(ISNUMBER($M19),$M19+ROW()/10000000,"")
